Workbook

Sheet INFO
B5: ZINTEGROWANY SYSTEM ROLNICZEJ INFORMACJI RYNKOWEJ
B10: Rynek
B11: owoców i warzyw
B14: NR 18/2026
M16: 07 maja 2026 r.
D19: zsrir.minrol.gov.pl

Sheet SPIS
B2: SPIS TREŚCI
C6: ZMIANY CEN HURTOWYCH
C7: CENY HURTOWE WARZYW
C8: CENY HURTOWE OWOCÓW
C9: CENY OWOCÓW ORGANIZACJI PRODUCENTÓW
C10: CENY OWOCÓW DO PRZETWORSTWA
C11: CENY WARZYW DO PRZETWORSTWA
C12: CENY DETALICZNE OWOCÓW
C13: CENY DETALICZNE WARZYW
C14: WYKRESY - OWOCE DETAL
C15: WYKRESY - WARZYWA DETAL
C16: IERGZ - CENY WARZYW
C17: IRGZ- CENY W ZAKŁADACH PRZETWÓRCZYCH I SPÓLDZIELNIACH
... C20: HANDEL ZAGRANICZNY

Sheet ZMIANY HURT
B2: ZMIANY ŚREDNICH CEN HURTOWYCH DLA WYBRANEGO ASORTYMENTU OWOCÓW I WARZYW
O4: =POMOC!B5
D5: Cena zł/jedn | H5: Zmiany ceny (%)
B6: Produkt | C6: Jedn. | D6: 46149 | F6: 46142 | H6: w stosunku do poprzedniego notowania*) | J6: 2 tyg. | L6: 3 tyg. | N6: 4 tyg.
D7: Min | E7: Max | F7: Min | G7: Max | H7: Min | I7: Max | J7: Min | K7: Max | L7: Min | M7: Max | N7: Min | O7: Max
B8: 1 | C8: 2 | D8: 3 | E8: 4 | F8: 5 | G8: 6 | H8: 7 | I8: 8 | J8: 9 | K8: 10 | L8: 11 | M8: 12 | N8: 13 | O8: 14
B9: Warzywa krajowe
B10: Boczniaki | C10: kg | D10: 19.833333 | E10: 22.666667 | F10: 21.75 | G10: 25
B11: Buraki ćwikłowe | C11: kg | D11: 1.06 | E11: 1.54 | F11: 1.25 | G11: 1.8
B12: Buraki młode | C12: pęczek | D12: 3.5 | E12: 5 | F12: 3.5 | G12: 5
B13: Cebula biała | C13: kg | D13: 1.14 | E13: 1.44 | F13: 1.275 | G13: 1.575
B14: Kalafiory | C14: szt. | D14: 9.3333333 | E14: 10.666667 | F14: 0 | G14: 0 | H14: -4.3478261 | I14: -3.478741 | J14: -2.6548673 | K14: -8.1031824 | L14: 0 | M14: -6.3571429 | N14: -10.204082 | O14: -12.116642
B15: Kapusta biała | C15: kg | D15: 0.93 | E15: 1.24 | F15: 1.2125 | G15: 1.45
B16: Kapusta młoda | C16: szt. | D16: 5.1666667 | E16: 5.75 | F16: 6 | G16: 6.25 | H16: -15.217391 | I16: -6.8927387 | J16: -23.529412 | K16: -15.092437 | L16: 2.6315789 | M16: -15.8 | N16: -25.949367 | O16: -22.673469
B17: Marchew | C17: kg | D17: 2.12 | E17: 2.74 | F17: 2.175 | G17: 2.9125
B18: Ogórki gruntowe | C18: kg | D18: 5.9 | E18: 7.2 | F18: 6.875 | G18: 8.25
B19: Ogórki krótkie | C19: kg | D19: 0 | E19: 0 | F19: 0 | G19: 0
B20: Ogórki szklarniowe | C20: kg | D20: 3.63 | E20: 4.39 | F20: 4.5 | G20: 5.65 | H20: 0 | I20: 0 | J20: 0 | K20: 0 | L20: 0 | M20: 0 | N20: 0 | O20: 0
B21: Pietruszka | C21: kg | D21: 3.14 | E21: 4.36 | F21: 3.875 | G21: 4.7
B22: Pomidory | C22: kg | D22: 8.932 | E22: 10.6 | F22: 11.5425 | G22: 13.5
B23: Pomidory malinowe | C23: kg | D23: 8.3 | E23: 10.632 | F23: 10.96 | G23: 13.4175
B24: Pory | C24: szt. | D24: 1.9333333 | E24: 2.6666667 | F24: 2.3333333 | G24: 3
B25: Sałata | C25: szt. | D25: 2.75 | E25: 3.418 | F25: 2.89 | G25: 3.6166667 | H25: -4.4880785 | I25: -3.9042821 | J25: 9.7207304 | K25: 9.6264368 | L25: -14.875 | M25: -23.7 | N25: -0.58394161 | O25: -13.442995
B26: Selery | C26: kg | D26: 1.98 | E26: 2.48 | F26: 2.55 | G26: 3.025
B27: Ziemniaki | C27: kg | D27: 0.712 | E27: 0.994 | F27: 0.9075 | G27: 1.2925
B28: Ziemniaki młode | C28: kg | D28: 12.223333 | E28: 13.89 | F28: 13.5 | G28: 18.5 | H28: -20.093458 | I28: -11.111111 | J28: -26.080692 | K28: -11.111111 | N28: -6.3868613 | O28: -5.8823529
B29: Owoce krajowe
B30: Gruszki | C30: kg | D30: 4.2 | E30: 6 | F30: 5.125 | G30: 6.5 | H30: -18.04878 | I30: -7.6923077 | J30: -20.754717 | K30: -4.7619048 | L30: -1.1764706 | M30: 0 | N30: -13.846154 | O30: 2.1276596
B31: Truskawki | C31: kg | D31: 29.25 | E31: 35 | F31: 35.333333 | G31: 37.333333 | H31: -17.216981 | I31: -6.25 | J31: -15.625 | K31: -2.7777778 | L31: -8.59375 | M31: -2.7777778 | N31: -12.686567 | O31: -2.7777778
B32: Jabłka:
B33: Boskoop | C33: kg | D33: 2.5 | E33: 3.25 | F33: 2.5 | G33: 3.25 | H33: 0 | I33: 0 | J33: 0 | K33: 0 | N33: 0 | O33: 0
B34: Cortland | C34: kg | D34: 3.1366667 | E34: 4.2633333 | F34: 3.1366667 | G34: 4.3933333 | H34: 0 | I34: -2.9590288 | J34: 3.8631347 | K34: -0.73729142 | L34: 10.6408 | M34: -5.2592593 | N34: 3.8631347 | O34: 1.206726
B35: Gala | C35: kg | D35: 2.8866667 | E35: 3.22 | F35: 2.8866667 | G35: 3.22 | H35: 0 | I35: 0 | J35: 0 | K35: 0 | L35: 15.466667 | M35: -8 | N35: 0 | O35: -2.5227043
B36: Golden | C36: kg | D36: 3.1933333 | E36: 3.61 | F36: 3.1933333 | G36: 3.61 | H36: 0 | I36: 0 | J36: 0 | K36: 0 | L36: 27.733333 | M36: -3.7333333 | N36: 0 | O36: 0
B37: Jonagold | C37: kg | D37: 2.54 | E37: 3.04 | F37: 2.54 | G37: 3.04 | H37: 0 | I37: 0 | J37: 0 | K37: 0 | L37: 27 | M37: 1.3333333 | N37: 0 | O37: 0
B38: Jonagored | C38: kg | D38: 3.33 | E38: 4 | F38: 3.33 | G38: 4 | H38: 0 | I38: 0 | J38: 0 | K38: 0 | N38: 0 | O38: 0
B39: Ligol | C39: kg | D39: 2.8033333 | E39: 3.36 | F39: 2.8033333 | G39: 3.36 | H39: 0 | I39: 0 | J39: 7.7169388 | K39: 0.22371365 | L39: 40.166667 | M39: 12 | N39: 7.7169388 | O39: 0.22371365
B40: Lobo | C40: kg | D40: 3.0866667 | E40: 4.06 | F40: 3.0866667 | G40: 4.06 | H40: 0 | I40: 0 | J40: 9.6506809 | K40: 6.9828722 | L40: 8.3040936 | M40: 1.5 | N40: 9.6506809 | O40: 6.9828722
B41: Szara Reneta | C41: kg | D41: 3.165 | E41: 3.925 | F41: 3.61 | G41: 4.2833333 | H41: -12.32687 | I41: -8.3657588 | J41: -1.3250195 | K41: -2.9666255 | L41: -2.6153846 | M41: -1.875 | N41: 13.985594 | O41: 5.3220036
B42: Szampion | C42: kg | D42: 2.8033333 | E42: 3.5266667 | F42: 2.8033333 | G42: 3.5266667 | H42: 0 | I42: 0 | J42: 11.243386 | K42: 3.8782523 | L42: 52.770209 | M42: 8.5128205 | N42: 11.243386 | O42: 3.8782523
...

Sheet HURT WARZ
B2: ŚREDNIE CENY WARZYW NA RYNKACH HURTOWYCH
E5: Bronisze | G5: Kalisz | I5: Kraków | K5: Poznań | M5: Wrocław
B6: Data notowania | E6: 46147 | G6: 46146 | I6: 46146 | K6: 46146 | M6: 46146
B7: Owoce | E7: Min | F7: Max | G7: Min | H7: Max | I7: Min | J7: Max | K7: Min | L7: Max | M7: Min | N7: Max
B8: KRAJOWE
B9: Buraki ćwikłowe | D9: kg | E9: 0.7 | F9: 1.4 | G9: 0.8 | H9: 1 | I9: 0.8 | J9: 1 | K9: 2 | L9: 2.8 | M9: 1 | N9: 1.5
B10: Buraki młode | D10: pęczek | E10: 3.5 | F10: 5
B11: Cebula biała | D11: kg | E11: 1 | F11: 1.3 | G11: 0.8 | H11: 1 | I11: 0.8 | J11: 1.2 | K11: 1.8 | L11: 2 | M11: 1.3 | N11: 1.7
B12: Kalafiory | D12: szt. | G12: 8 | H12: 8 | I12: 11 | J12: 12 | M12: 9 | N12: 12
B13: Kapusta biała | D13: kg | E13: 0.85 | F13: 1.1 | G13: 0.5 | H13: 0.5 | I13: 0.8 | J13: 0.9 | K13: 1.7 | L13: 2.2 | M13: 0.8 | N13: 1.5
B14: Kapusta młoda | D14: szt. | E14: 6 | F14: 7 | G14: 5 | H14: 5 | K14: 4.5 | L14: 5.25
B15: Marchew | D15: kg | E15: 2.5 | F15: 3.5 | G15: 2.8 | H15: 3.5 | I15: 1.8 | J15: 2.5 | K15: 2.5 | L15: 2.8 | M15: 1 | N15: 1.4
B16: Ogórki gruntowe | D16: kg | E16: 5.5 | F16: 7 | G16: 4 | H16: 6 | I16: 6 | J16: 6.5 | K16: 8 | L16: 9 | M16: 6 | N16: 7.5
B17: Ogórki szklarniowe | D17: kg | E17: 2.65 | F17: 4.85 | G17: 3 | H17: 3 | I17: 3 | J17: 3 | K17: 6 | L17: 6.6 | M17: 3.5 | N17: 4.5
B18: Pietruszka | D18: kg | E18: 3 | F18: 4 | G18: 2.5 | H18: 4 | I18: 2.2 | J18: 3 | K18: 6 | L18: 6.8 | M18: 2 | N18: 4
B19: Pomidory | D19: kg | E19: 9 | F19: 13 | G19: 8.33 | H19: 9.17 | I19: 9 | J19: 10 | K19: 10.33 | L19: 10.83 | M19: 8 | N19: 10
B20: Pomidory malinowe | D20: kg | E20: 8 | F20: 14 | G20: 7.5 | H20: 8.33 | I20: 9 | J20: 10 | K20: 10 | L20: 10.83 | M20: 7 | N20: 10
B21: Pory | D21: szt. | G21: 1.5 | H21: 1.5 | K21: 2.5 | L21: 3.5 | M21: 1.8 | N21: 3
B22: Rzodkiewka | D22: pęczek | E22: 1 | F22: 2 | I22: 1.6 | J22: 2 | K22: 2 | L22: 2 | M22: 1.8 | N22: 2.5
B23: Sałata | D23: szt. | E23: 2 | F23: 3 | G23: 2.5 | H23: 2.92 | I23: 2.5 | J23: 3 | K23: 3.75 | L23: 4.17 | M23: 3 | N23: 4
B24: Selery | D24: kg | E24: 1.3 | F24: 1.6 | G24: 1 | H24: 1.5 | I24: 1.2 | J24: 1.6 | K24: 4.4 | L24: 5 | M24: 2 | N24: 2.7
B25: Ziemniaki | D25: kg | E25: 0.5 | F25: 1.2 | G25: 1 | H25: 1 | I25: 0.33 | J25: 0.5 | K25: 1.13 | L25: 1.47 | M25: 0.6 | N25: 0.8
B26: Ziemniaki młode | D26: kg | E26: 12 | F26: 17 | G26: 18 | H26: 18 | K26: 6.67 | L26: 6.67
B27: Boczniaki | D27: kg | E27: 13.5 | F27: 20 | K27: 30 | L27: 30 | M27: 16 | N27: 18
B28: Pieczarki | D28: kg | E28: 9 | F28: 12 | G28: 10 | H28: 10 | I28: 9.5 | J28: 11 | K28: 11 | L28: 13 | M28: 8.5 | N28: 10.5
B29: IMPORTOWANE
B30: Czosnek | D30: kg | E30: 7 | F30: 8 | G30: 14 | H30: 14 | I30: 20 | J30: 25
B31: Kalafiory | D31: szt. | E31: 11 | F31: 14 | G31: 10 | H31: 12 | K31: 12 | L31: 13.33
B32: Kapusta młoda | D32: szt. | E32: 4.5 | F32: 7 | K32: 5.25 | L32: 5.63
B33: Papryka czerwona | D33: kg | E33: 12 | F33: 14 | G33: 10 | H33: 10 | I33: 9.8 | J33: 11 | K33: 10 | L33: 12 | M33: 13 | N33: 17
B34: Papryka zielona | D34: kg | E34: 10 | F34: 14 | G34: 10 | H34: 10 | K34: 10 | L34: 12 | M34: 13 | N34: 17
B35: Papryka żółta | D35: kg | E35: 12 | F35: 14 | G35: 12 | H35: 12 | I35: 11 | J35: 12 | K35: 10 | L35: 12 | M35: 13 | N35: 17
B36: Rzodkiewka | D36: pęczek | G36: 1.2 | H36: 1.5 | K36: 1.5 | L36: 2
B37: Sałata | D37: szt. | E37: 4 | F37: 4.5 | K37: 2.81 | L37: 3.13
B38: Ziemniaki młode | D38: kg | E38: 1.8 | F38: 4 | K38: 3.33 | L38: 4

Sheet OWOCE ORGANIZACJE PROD.
B2: ŚREDNIE CENY ZAKUPU JABŁEK I GRUSZEK PŁACONE PRZEZ ORGANIZACJE PRODUCENTÓW - najważniejsze odmiany
B3: (zł/100 kg)
N4: =POMOC!B5
B5: TOWAR | C5: 03.05.2026 | E5: 26.04.2026 | F5: 04.05.2025 | G5: Zmiana % w stosunku do poprzedniego okresu | H5: Zmiana % w stosunku do okresu sprzed roku
B6: Jabłka (razem) | C6: 144.07 | E6: 136.35 | F6: 178.84 | G6: 5.66 | H6: -19.44
B7: Boskoop | C7: --- | E7: nld | F7: --- | G7: * | H7: *
B8: Gala | C8: nld | E8: nld | F8: nld | G8: * | H8: *
B9: Gloster | C9: --- | E9: --- | F9: nld | G9: * | H9: *
B10: Golden delicious | C10: nld | E10: nld | F10: 170.44 | G10: * | H10: *
B11: Idared | C11: 123.86 | E11: nld | F11: 180.34 | G11: * | H11: -31.32
B12: Jonagold/Jonagored | C12: 145.56 | E12: nld | F12: 192.06 | G12: * | H12: -24.21
B13: Ligol | C13: nld | E13: 140.06 | F13: 176.24 | G13: * | H13: *
B14: Szampion | C14: nld | E14: nld | F14: 166.71 | G14: * | H14: *
B15: Gruszki (razem) | C15: nld | E15: nld | F15: nld | G15: * | H15: *
B17: ŚREDNIE CENY SPRZEDAŻY JABŁEK I GRUSZEK PŁACONE PRZEZ ORGANIZACJE PRODUCENTÓW - główne odmiany
B18: (zł/100 kg)
B20: TOWAR | C20: 03.05.2026 | E20: 26.04.2026 | F20: 04.05.2025 | G20: Zmiana ceny (%) w stosunku do poprzedniego okresu | H20: Zmiana ceny (%) w stosunku do okresu sprzed roku
B21: Jabłka (razem) | C21: 231.03 | E21: 263.59 | F21: 310.86 | G21: -12.35 | H21: -25.68
B22: Boskoop | C22: nld | E22: nld | F22: --- | G22: * | H22: *
B23: Gala | C23: nld | E23: nld | F23: 367.69 | G23: * | H23: *
B24: Gloster | C24: --- | E24: --- | F24: nld | G24: * | H24: *
B25: Golden delicious | C25: 213.06 | E25: nld | F25: 269.24 | G25: * | H25: -20.87
B26: Idared | C26: nld | E26: nld | F26: 292.59 | G26: * | H26: *
B27: Jonagold/Jonagored | C27: 229.32 | E27: nld | F27: 305.62 | G27: * | H27: -24.97
B28: Ligol | C28: nld | E28: 262.67 | F28: 336.21 | G28: * | H28: *
B29: Szampion | C29: nld | E29: 241.77 | F29: 310.19 | G29: * | H29: *
B30: Gruszki (razem) | C30: nld | E30: nld | F30: nld | G30: * | H30: *
B32: Odmiany, dla których zbierane są dane:
B33: Boskoop, Cortland, Elstar, Gala, Gloster, Golden delicious, Idared, Jonagold/Jonagored, Ligol, Lobo, Red delicious, Shampion

Sheet OWOCE PRZETWÓRSTWO
B2: ŚREDNIE CENY ZAKUPU OWOCÓW PŁACONE PRZEZ PODMIOTY ZAJMUJĄCE SIĘ PRZETWÓRSTWEM
B3: (zł/100 kg)
L4: =POMOC!B5
B5: TOWAR | C5: 03.05.2026 | D5: 46138 | E5: Zmiana ceny (%) w stosunku do okresu sprzed roku
B6: Jabłka /ogółem | C6: 64.08 | D6: 66.05 | E6: =(C6-D6)/D6*100
B7: Jabłka / na sok zagęszczony | C7: 64.45 | D7: 61.16 | E7: =(C7-D7)/D7*100
B8: Jabłka / na sok NFC | C8: 72.3 | D8: nld | E8: *
B9: Jabłka / na dżemy, przeciery, marmolada | C9: 66.91 | D9: 68.78 | E9: =(C9-D9)/D9*100

Sheet WARZYWA PRZETWÓRSTWO
B2: ŚREDNIE CENY ZAKUPU WARZYW PŁACONE PRZEZ PODMIOTY ZAJMUJĄCE SIĘ PRZETWÓRSTWEM
B3: (zł/100 kg)
J4: =POMOC!B5
B5: TOWAR | C5: 03.05.2026 | D5: 46138 | E5: Zmiana ceny (%) w stosunku do poprzedniego okresu
B6: Buraki ćwikłowe | C6: 45.62 | D6: 53.91 | E6: =(C6-D6)/D6*100
B7: Cebula biała obierana | C7: 132.03 | D7: 129.96 | E7: =(C7-D7)/D7*100
B8: Kapusta biała | C8: 85.25 | D8: nld | E8: *
B9: Marchew | C9: nld | D9: nld | E9: *

Sheet ZAKUP OWOCE DETAL
B2: ŚREDNIE CENY ZAKUPU OWOCÓ PŁACONE PRZEZ PODMIOTY HANDLU DETALICZNEGO
B3: (zł/100 kg)
L4: =POMOC!B5
B5: OWOCE krajowe - luzem
B6: TOWAR | C6: 03.05.2026 | D6: 26.04.2026 | E6: 04.05.2025 | F6: Zmiana ceny (%) w stosunku do poprzedniego okresu | G6: Zmiana ceny (%) w stosunku do okresu sprzed roku
B7: Jabłka (razem) | C7: 287.24 | D7: 286.03 | E7: 354.53 | F7: =IFERROR((C7-D7)/D7*100,"-") | G7: =IFERROR((C7-E7)/E7*100,"-")
B8: Gala | C8: 363.67 | D8: 366.34 | E8: 406.16 | F8: =IFERROR((C8-D8)/D8*100,"-") | G8: =IFERROR((C8-E8)/E8*100,"-")
B9: Golden delicious | C9: 331.7 | D9: 326.24 | E9: 349.18 | F9: =IFERROR((C9-D9)/D9*100,"-") | G9: =IFERROR((C9-E9)/E9*100,"-")
B10: Idared | C10: 305.45 | D10: 253.46 | E10: 303.01 | F10: =IFERROR((C10-D10)/D10*100,"-") | G10: =IFERROR((C10-E10)/E10*100,"-")
B11: Jonagold/Jonagored | C11: 262.58 | D11: 261.93 | E11: 335.33 | F11: =IFERROR((C11-D11)/D11*100,"-") | G11: =IFERROR((C11-E11)/E11*100,"-")
B12: Ligol | C12: 316.84 | D12: 313.19 | E12: 370.98 | F12: =IFERROR((C12-D12)/D12*100,"-") | G12: =IFERROR((C12-E12)/E12*100,"-")
B13: Szampion | C13: 295.72 | D13: 278.93 | E13: 346.87 | F13: =IFERROR((C13-D13)/D13*100,"-") | G13: =IFERROR((C13-E13)/E13*100,"-")
B15: OWOCE z importu - luzem
B16: TOWAR | C16: 03.05.2026 | D16: 26.04.2026 | E16: 04.05.2025 | F16: Zmiana ceny (%) w stosunku do poprzedniego okresu | G16: Zmiana ceny (%) w stosunku do okresu sprzed roku
B17: Jabłka-Granny Smith | C17: nld | D17: nld | E17: nld | F17: * | G17: *
B18: Pomarańcze | C18: 402.22 | D18: 424.65 | E18: 473.46 | F18: =IFERROR((C18-D18)/D18*100,"-") | G18: =IFERROR((C18-E18)/E18*100,"-")
B19: Brzoskwinie | C19: nld | D19: nld | E19: 1573.39 | F19: * | G19: *
B20: Nektaryny | C20: nld | D20: nld | E20: nld | F20: * | G20: *

Sheet ZAKUP WARZ DETAL
B2: ŚREDNIE CENY ZAKUPU WARZYW PŁACONE PRZEZ PODMIOTY HANDLU DETALICZNEGO
B3: (zł/100 kg)
L4: =POMOC!B5
B5: WARZYWA krajowe - luzem
B6: TOWAR | C6: 03.05.2026 | D6: 26.04.2026 | E6: 04.05.2025 | F6: Zmiana % w stosunku do poprzedniego okresu | G6: Zmiana % w stosunku do okresu sprzed roku
B7: Marchew | C7: 318.04 | D7: 274.96 | E7: 256.2 | F7: =IFERROR((C7-D7)/D7*100,"-") | G7: =IFERROR((C7-E7)/E7*100,"-")
B8: Ogórki szklarniowe | C8: 465.93 | D8: 665.77 | E8: * | F8: =IFERROR((C8-D8)/D8*100,"-") | G8: *
B9: Papryka czerwona | C9: 1068.72 | D9: 1215.1 | E9: * | F9: =IFERROR((C9-D9)/D9*100,"-") | G9: *
B10: Pomidory okrągłe | C10: 945.18 | D10: 1325.75 | E10: 950.45 | F10: =IFERROR((C10-D10)/D10*100,"-") | G10: =IFERROR((C10-E10)/E10*100,"-")
B11: Ziemniaki | C11: 107.57 | D11: 106.8 | E11: 205.17 | F11: =IFERROR((C11-D11)/D11*100,"-") | G11: =IFERROR((C11-E11)/E11*100,"-")
B13: WARZYWA z importu - luzem
B14: TOWAR | C14: 03.05.2026 | D14: 26.04.2026 | E14: 04.05.2025 | F14: Zmiana ceny (%) w stosunku do poprzedniego okresu | G14: Zmiana ceny (%) w stosunku do okresu sprzed roku
B15: Marchew | C15: 357.42 | D15: 341.25 | E15: 293.74 | F15: =IFERROR((C15-D15)/D15*100,"-") | G15: =IFERROR((C15-E15)/E15*100,"-")
B16: Papryka czerwona | C16: 856.7 | D16: 956.61 | F16: =(C16-D16)/D16*100 | G16: *
B17: Pomidory okrągłe | C17: 849.29 | D17: 1008.02 | E17: 593.19 | F17: =(C17-D17)/D17*100 | G17: =IFERROR((C17-E17)/E17*100,"-")
B18: Pomidory na gałązkach | C18: 825.41 | D18: 1098.44 | E18: 607.59 | F18: =(C18-D18)/D18*100 | G18: =IFERROR((C18-E18)/E18*100,"-")
B19: Pomidory typu "cherry" | C19: 1294.28 | D19: 1707.72 | E19: 1604.41 | F19: =(C19-D19)/D19*100 | G19: =IFERROR((C19-E19)/E19*100,"-")
B20: Ziemniaki | C20: 428.98 | D20: 456.39 | E20: 407.13 | F20: =(C20-D20)/D20*100 | G20: =IFERROR((C20-E20)/E20*100,"-")
B22: WARZYWA krajowe - opakowania do 2 kg
B23: TOWAR | C23: 03.05.2026 | D23: 26.04.2026 | E23: 04.05.2025 | F23: Zmiana ceny (%) w stosunku do poprzedniego okresu | G23: Zmiana ceny (%) w stosunku do okresu sprzed roku
B24: Marchew | C24: 460.81 | D24: 422.15 | E24: 382.63 | F24: =(C24-D24)/D24*100 | G24: =IFERROR((C24-E24)/E24*100,"-")
B25: Pomidory okrągłe | C25: 1055.71 | D25: 1430.89 | E25: 946.97 | F25: =(C25-D25)/D25*100 | G25: =IFERROR((C25-E25)/E25*100,"-")
B26: Pomidory typu "cherry" | C26: 1500.12 | D26: 1527.11 | E26: 1336.28 | F26: =(C26-D26)/D26*100 | G26: =IFERROR((C26-E26)/E26*100,"-")
B27: Ziemniaki | C27: 179.93 | D27: 175.19 | E27: 300.58 | F27: =(C27-D27)/D27*100 | G27: =IFERROR((C27-E27)/E27*100,"-")
B29: WARZYWA z importu - do 2 kg
B30: TOWAR | C30: 03.05.2026 | D30: 26.04.2026 | E30: 04.05.2025 | F30: Zmiana % w stosunku do poprzedniego okresu | G30: Zmiana % w stosunku do okresu sprzed roku
B31: Marchew | C31: 710.09 | D31: 531.81 | E31: 704.48 | F31: =(C31-D31)/D31*100 | G31: =IFERROR((C31-E31)/E31*100,"-")
B32: Pomidory okrągłe | C32: 1004.75 | D32: 1318.58 | E32: nld | F32: =(C32-D32)/D32*100 | G32: =IFERROR((C32-E32)/E32*100,"-")
B33: Pomidory na gałązkach | C33: nld | D33: nld | E33: nld | F33: * | G33: =IFERROR((C33-E33)/E33*100,"-")
B34: Pomidory typu "cherry" | C34: 1597.25 | D34: 2167.11 | E34: 1629.7 | F34: =(C34-D34)/D34*100 | G34: =IFERROR((C34-E34)/E34*100,"-")

Sheet DETAL OWOCE WYKRES 
B2: Średnie ceny zakupu jabłek (luzem) płacone przez podmioty handlu detalicznego
M4: =POMOC!B5
B63: 03.05.2026 | C63: 46138
A64: Gala | B64: 3.6367 | C64: 3.6634
A65: Golden delicious | B65: 3.317 | C65: 3.2624
A66: Idared | B66: 3.0545 | C66: 2.5346
A67: Jonagold/jonagored | B67: 2.6258 | C67: 2.6193
A68: Ligol | B68: 3.1684 | C68: 3.1319
A69: Szampion | B69: 2.9572 | C69: 2.7893

Sheet DETAL WARZ WYKRES
B2: Średnie ceny zakupu warzyw (luzem) płacone przez podmioty handlu detalicznego
M4: =POMOC!B5
B60: 03.05.2026 | C60: 46138
A61: Marchew | B61: 3.1804 | C61: 2.7496
A62: Pomidory okrągłe | B62: 9.4518 | C62: 13.2576
A63: Ziemniaki | B63: 1.0757 | C63: 1.068

Sheet IERGZ_warzywa
A5: Ogrodniczy Informator Cenowy | L5: Warszawa
L6: 4 V
L7: 2026 r.
B8: Instytut Ekonomiki Rolnictwa i Gospodarki Żywnościowej Państwowy Instytut Badawczy
B9: 00-950 Warszawa, ul.Świętokrzyska 20, P.O. Box 984
B10: tel. (22) 505 44 32, e-mail: Tomasz.Smolenski@ierigz.waw.pl
B11: Ceny skupu netto warzyw i owoców w spółdzielniach ogrodniczych zbierane 4 V 2026 r.
B12: Województwo | C12: Buraki ćwikłowe | D12: Cebula | E12: Kapusta biała | F12: Kapusta włoska | G12: Kapusta pekińska | H12: Brukselka | I12: Kiszona kapusta
B13: kujawsko-pomorskie | C13: 0,52-0,60 | D13: 0,54-0,57 | E13: 0,45-0,65 | F13: 1,68-1,89 | G13: 2,69-3,25 | H13: 3,35-4,56
B14: lubelskie | C14: 0,51-0,58 | D14: 0,61-0,68 | E14: 0,51-0,58 | F14: 1,59-1,87 | I14: 6,35-6,89
B15: lubelskie | C15: 0,52-0,55 | D15: 0,54-0,57 | E15: 0,48-0,58 | G15: 2,55-2,87 | H15: 3,78-4,51
B16: łódzkie | C16: 0,48-0,57 | D16: 0,54-0,66 | E16: 0,57-0,63 | F16: 1,56-1,99 | I16: 6,78-7,45
B17: łódzkie | C17: 0,50-0,64 | D17: 0,51-0,58 | I17: 6,35-6,98
B18: małopol. | C18: 0,47-0,56 | D18: 0,55-0,66 | E18: 0,48-0,59 | F18: 1,78-2,70 | I18: 6,65-7,36
B19: małopol. | C19: 0,50-0,55 | D19: 0,56-0,62 | I19: 5,94-6,89
B20: małopol. | C20: 0,51-0,56 | D20: 0,52-0,60 | E20: 0,46-0,57 | H20: 3,65-3,89 | I20: 5,98-6,77
B21: małopol. | C21: 0,50-0,62 | D21: 0,53-0,57 | F21: 1,88-2,40 | G21: 2,50-2,98
B22: mazowiec. | C22: 0,48-0,54 | D22: 0,58-0,63 | E22: 0,51-0,59 | F22: 1,88-2,45 | G22: 2,78-3,22 | H22: 3,45-3,87 | I22: 7,23-7,90
B23: podkarp. | C23: 0,54-0,66 | D23: 0,47-0,56 | I23: 6,58-7,69
B24: podkarp. | C24: 0,55-0,65 | D24: 0,48-0,55 | H24: 3,66-4,36
C25: 0,48-0,66 | D25: 0,47-0,68 | E25: 0,45-0,65 | F25: 1,56-2,70 | G25: 2,50-3,25 | H25: 3,35-4,68 | I25: 5,94-7,90
B26: dwa tygodnie temu | C26: 0,49-0,67 | D26: 0,48-0,69 | E26: 0,45-0,64 | F26: 1,66-2,66 | G26: 2,45-3,10 | H26: 3,51-4,70 | I26: 5,98-7,98
B27: rok temu | C27: 0,69-0,87 | D27: 0,89-1,10 | E27: 0,69-0,98 | F27: 1,88-2,74 | G27: 2,75-3,65 | H27: 3,45-4,98 | I27: 6,45-8,33
B29: Województwo | C29: Marchew (myta) | D29: Pieczarki | E29: Pietruszka | F29: Pory | G29: Czosnek/a | H29: Rzodkiewka/b | I29: Selery
B30: kujawsko-pomorskie | C30: 0,56-0,87 | D30: 5,65-5,98 | E30: 1,94-2,68 | F30: 2,56-2,66 | G30: 0,65-0,78 | H30: 1,56-1,89 | I30: 0,75-0,92
B31: lubelskie | C31: 0,64-0,77 | D31: 6,45-7,89 | E31: 2,56-2,78 | F31: 2,77-2,98 | G31: 0,84-0,90 | I31: 0,85-0,99
B32: małopol. | C32: 0,56-0,65 | D32: 7,56-8,66 | E32: 2,25-2,69 | F32: 2,69-3,15 | H32: 1,78-1,99 | I32: 0,84-0,96
B33: małopol. | C33: 0,64-0,73 | D33: 7,23-8,63 | E33: 2,45-2,98 | F33: 2,48-2,89 | G33: 0,75-0,96 | I33: 0,82-0,91
B34: mazowiec. | C34: 0,71-0,88 | D34: 7,68-8,36 | E34: 2,10-2,45 | F34: 2,88-3,12 | G34: 0,89-0,93 | H34: 1,98-2,10 | I34: 0,88-0,97
B35: mazowiec. | C35: 0,75-0,79 | D35: 7,25-8,45 | E35: 2,35-2,88 | F35: 2,65-3,10 | G35: 0,76-0,88 | H35: 1,68-1,98 | I35: 0,78-0,88
B36: podkarp. | C36: 0,88-0,93 | D36: 5,69-6,89 | E36: 2,45-2,95 | F36: 2,55-2,87 | I36: 0,70-0,88
B37: podkarp. | C37: 0,88-0,90 | D37: 6,32-6,86 | E37: 2,34-2,87 | F37: 2,65-2,98 | G37: 0,79-1,10 | H37: 1,45-1,66 | I37: 0,64-0,78
B38: Cena średnia | C38: 0,56-0,93 | D38: 5,65-8,66 | E38: 1,94-2,95 | F38: 2,48-3,15 | G38: 0,65-1,10 | H38: 1,45-2,10 | I38: 0,64-0,99
B39: dwa tygodnie temu | C39: 0,64-0,99 | D39: 4,89-8,45 | E39: 1,89-2,99 | F39: 2,45-3,25 | G39: 0,75-0,98 | H39: 1,35-1,98 | I39: 0,66-0,97
B40: rok temu | C40: 0,89-1,25 | D40: 6,98-9,23 | E40: 1,89-3,15 | F40: 2,68-3,45 | G40: 0,87-1,25 | H40: 1,56-1,98 | I40: 0,78-1,25
B41: a/sztuka,b/peczek

Sheet Zaklady 
A1: Ogrodniczy Informator Cenowy
A4: Instytut Ekonomiki Rolnictwa i Gospodarki Żywnościowej - Państwowy Instytut Badawczy
A5: Zakład Ekonomiki Gospodarstw Rolnych i Ogrodniczych
A6: 00-950 Warszawa, ul.Świętokrzyska 20, P.O. Box 984
A7: Ceny skupu netto w zakładach przetwórczych i chłodniach zbierane 4 V 2026 r. (zł/kg)
J8: Jabłka | N8: Cebula | O8: Buraki | Y8: Pory | Z8: Kapusta | AA8: Marchew | AB8: Jabłka
J9: przemysłowe | N9: obrana | O9: ćwikłowe | Z9: biała | AA9: na plastry | AB9: przemyslowe
A10: kujawsko-pomor.
A11: kujawsko-pomor. | N11: 1,15lz-1,20lz
A12: kujawsko-pomor.
A13: kujawsko-pomor. | N13: 1,15lz-1,20lz | O13: 0,60lz-0,63lz | Y13: 1,20lz | Z13: 0,50-0,60lz | AA13: 0,60lz-0,65lz
A14: lubelskie | J14: 0,32-0,36lz | AB14: 0,60lz-0,70lz
A15: lubelskie | O15: 0,55-0,60lz
A16: lubelskie | N16: 1,18lz-1,20lz | AA16: 0,60lz/k | AB16: 0,60lz-0,90lz-1,20lz
A17: lubelskie | Y17: 1,12lz-1,17lz | Z17: 0,55-0,60lz-0,65lz | AB17: 0,65lz-0,75lz
A18: lubelskie
A19: lubuskie | Z19: 0,65lz
A20: łódzkie | AA20: 0,60lz-0,65lz | AB20: 0,60lz-0,70lz
A21: łódzkie | Y21: 1,10lz-1,20lz
A22: małopolskie | J22: 0,31-0,35lz | N22: 1,10-1,25lz-1,30lz | O22: 0,50-0,65lz
A23: mazowieckie | AB23: 0,65lz-0,90lz-1,15lz-1,20lz
A24: mazowieckie | J24: 0,32-0,35lz
A25: podkarpackie
A26: podkarpackie
A27: podlaskie | J27: 0,36lz
A28: podlaskie
A29: śląskie
A30: świętokrzyskie | Z30: 0,55lz-0,60lz
A31: wielkopolskie | N31: 1,00-1,25lz
A32: wielkopolskie | N32: 1,10lz-1,27lz
A33: zachodnio-pomor.
A35: średnio | J35: 0,32-0,36lz | N35: 1,00-1,10-1,10lz-1,30lz | O35: 0,50-0,55-0,60lz-0,65lz | Y35: 1,10lz-1,20lz | Z35: 0,50-0,55-0,60lz-0,65lz | AA35: 0,60lz-0,65lz | AB35: 0,60lz-0,75lz/na sok-0,90lz-1,20lz/do obierania
A37: tydzień temu | J37: 0,32-0,36lz | N37: 1,00lz-1,27lz | O37: 0,56-0,60lz-0,65lz | Y37: 1,10lz-1,20lz | Z37: 0,55-0,60lz-0,65lz | AA37: 0,55-0,60lz-0,70lz | AB37: 0,60lz-0,75lz/na sok-0,90lz-1,20lz/do obierania
A39: rok temu | J39: 0,27-0,33lz | N39: 1,54lz-1,75lz | O39: 0,70lz-0,85lz | Y39: 1,40-1,40lz-1,60lz | Z39: 0,90lz-1,20lz | AA39: 0,95lz-1,15lz | AB39: 1,00lz-1,25lz, 1,40lz-1,60lz/do obierania
A72: lz/ cena loco zakład, k/kontraktacja,kl.I/klasa I, kl.II/klasa II,extra/klasa ekstra,m/"mokry" przemysł,s/ "suchy" przemysł,W/Węgierka

Sheet IERGZ_Zaklady  
A5: Ogrodniczy Informator Cenowy
A8: Instytut Ekonomiki Rolnictwa i Gospodarki Żywnościowej - Państwowy Instytut Badawczy
A9: Zakład Ekonomiki Gospodarstw Rolnych i Ogrodniczych
A10: 00-950 Warszawa, ul.Świętokrzyska 20, P.O. Box 984
A12: Ceny skupu netto w zakładach przetwórczych i chłodniach zbierane 4 V 2026 r. (zł/kg)
J13: Jabłka | N13: Cebula | O13: Buraki | W13: Pory | X13: Kapusta | Y13: Marchew | Z13: Jabłka
J14: przemysłowe | N14: obrana | O14: ćwikłowe | X14: biała | Y14: na plastry | Z14: przemyslowe
A15: kujawsko-pomor.
A16: kujawsko-pomor. | N16: 1,15lz-1,20lz
A17: kujawsko-pomor.
A18: kujawsko-pomor. | N18: 1,15lz-1,20lz | O18: 0,60lz-0,63lz | W18: 1,20lz | X18: 0,50-0,60lz | Y18: 0,60lz-0,65lz
A19: lubelskie | J19: 0,32-0,36lz | Z19: 0,60lz-0,70lz
A20: lubelskie | O20: 0,55-0,60lz
A21: lubelskie | N21: 1,18lz-1,20lz | Y21: 0,60lz/k | Z21: 0,60lz-0,90lz-1,20lz
A22: lubelskie | W22: 1,12lz-1,17lz | X22: 0,55-0,60lz-0,65lz | Z22: 0,65lz-0,75lz
A23: lubelskie
A24: lubuskie | X24: 0,65lz
A25: łódzkie | Y25: 0,60lz-0,65lz | Z25: 0,60lz-0,70lz
A26: łódzkie | W26: 1,10lz-1,20lz
A27: małopolskie | J27: 0,31-0,35lz | N27: 1,10-1,25lz-1,30lz | O27: 0,50-0,65lz
A28: mazowieckie | Z28: 0,65lz-0,90lz-1,15lz-1,20lz
A29: mazowieckie | J29: 0,32-0,35lz
A30: podkarpackie
A31: podkarpackie
A32: podlaskie | J32: 0,36lz
A33: podlaskie
A34: śląskie
A35: świętokrzyskie | X35: 0,55lz-0,60lz
A36: wielkopolskie | N36: 1,00-1,25lz
A37: wielkopolskie | N37: 1,10lz-1,27lz
A38: zachodnio-pomor.
A40: średnio | J40: 0,32-0,36lz | N40: 1,00-1,10-1,10lz-1,30lz | O40: 0,50-0,55-0,60lz-0,65lz | W40: 1,10lz-1,20lz | X40: 0,50-0,55-0,60lz-0,65lz | Y40: 0,60lz-0,65lz | Z40: 0,60lz-0,75lz/na sok-0,90lz-1,20lz/do obierania
A42: tydzień temu | J42: 0,32-0,36lz | N42: 1,00lz-1,27lz | O42: 0,56-0,60lz-0,65lz | W42: 1,10lz-1,20lz | X42: 0,55-0,60lz-0,65lz | Y42: 0,55-0,60lz-0,70lz | Z42: 0,60lz-0,75lz/na sok-0,90lz-1,20lz/do obierania
A44: rok temu | J44: 0,27-0,33lz | N44: 1,54lz-1,75lz | O44: 0,70lz-0,85lz | W44: 1,40-1,40lz-1,60lz | X44: 0,90lz-1,20lz | Y44: 0,95lz-1,15lz | Z44: 1,00lz-1,25lz, 1,40lz-1,60lz/do obierania

Sheet IERGZ_owoce
B5: Województwo | C5: Jabłka deserowe | D5: Jabłka przemysłowe | E5: Gruszki
B6: kujawsko-pomorskie | C6: 1,60-2,20
B7: lubelskie | C7: 1,64-2,40 | D7: 0,55-0,65
B8: łódzkie | C8: 1,57-2,35 | E8: 3,25-3,68
B9: łódzkie | C9: 1,55-2,35 | D9: 0,60-0,67 | E9: 3,45-3,70
B10: łódzkie
B11: małopolskie | C11: 1,69-1,87 | E11: 3,40-3,80
B12: małopolskie | C12: 1,70-2,64 | D12: 0,63-0,67
B13: małopolskie | C13: 1,65-2,67 | D13: 0,60-0,68 | E13: 3,55-3,68
B14: małopolskie
B15: małopolskie | D15: 0,62-0,67
B16: mazowiec. | C16: 1,85-2,40 | E16: 3,43-3,68
B17: podkarp. | C17: 1,65-2,35 | D17: 0,60-0,68
B18: podkarp. | E18: 3,50-3,90
B19: Cena średnia | C19: 1,55-2,67 | D19: 0,55-0,68 | E19: 3,25-3,90
B20: dwa tygodnie temu | C20: 1,66-2,70 | D20: 0,60-0,70 | E20: 3,35-4,21
B21: rok temu | C21: 1,79-2,98 | D21: 0,75-0,98 | E21: 3,70-4,35
B22: s/"suchy" przemysł, */jabłka w kal. 65+ i do średniej nie wliczana jest odmiana Antonówka

Sheet ow_KRIR
C1: Tygodniowy Serwis Cenowy
B2: 18 tydzień | C2: dla producentów owoców i warzyw
B3: 27.04. - 03.05.2026 r | C3: Krajowa Rada Izb Rolniczych
C4: Parzniew ul. Przyszłości 5, 05-804 Pruszków
C5: tel. 881-939-421, www.krir.pl, sekretariat@krir.pl
B6: Serwis znajduje się obecnie w fazie rozwoju i dotyczy wybranych produktów w niektórych województwach.
B8: Województwo/Towar | C8: Mazowieckie | F8: Świętokrzyskie | I8: Wielkopolskie
C9: 27.04. - 03.05.2026r. cena w zł/kg (szt*) | D9: 20.04. - 26.04.2026r. cena w zł/kg (szt*) | E9: tygodniowa zmiana ceny w % | F9: 27.04. - 03.05.2026r. cena w zł/kg (szt*) | G9: 20.04. - 26.04.2026r. cena w zł/kg (szt*) | H9: tygodniowa zmiana ceny w % | I9: 27.04. - 03.05.2026r. cena w zł/kg (szt*) | J9: 20.04. - 26.04.2026r. cena w zł/kg (szt*) | K9: tygodniowa zmiana ceny w %
B10: Jabłka (op.5-20 kg) Golden delicious (70/80mm) | C10: 2.65 | D10: 2.65 | E10: =((C10-D10)/D10)*100 | F10: 1.45 | G10: 1.45 | H10: =((F10-G10)/G10)*100 | I10: -- | J10: -- | K10: --
B11: Jabłka (op.5-20 kg) Jonagold+Jonagored (70/80mm) | E11: -- | F11: -- | G11: -- | H11: -- | I11: -- | J11: -- | K11: --
B12: Jabłka (op.5-20 kg) Idared (70/80mm) | C12: 2 | D12: 2 | E12: =((C12-D12)/D12)*100 | F12: 1.35 | G12: 1.35 | H12: =((F12-G12)/G12)*100 | I12: -- | J12: -- | K12: --
B13: Jabłka (op.5-20 kg) Shampion (70/80mm) | E13: -- | F13: 1.45 | G13: 1.55 | H13: =((F13-G13)/G13)*100 | I13: -- | J13: -- | K13: --
B14: Jabłka (op.5-20 kg) Boskoop (70/80mm) | C14: 3.3 | D14: 3.3 | E14: -- | F14: 2.15 | G14: 2.15 | H14: =((F14-G14)/G14)*100 | I14: -- | J14: -- | K14: --
B15: Jabłka (op.5-20 kg) Gala (65/70mm) | C15: 2 | D15: 2 | E15: -- | F15: -- | G15: -- | H15: -- | I15: -- | J15: -- | K15: --
B16: Gruszki (op.5-20 kg) Lukasówka (65/70 mm) | C16: 5 | D16: 5 | E16: =((C16-D16)/D16)*100 | F16: 4.75 | G16: 4.75 | H16: =((F16-G16)/G16)*100 | I16: -- | J16: -- | K16: --
B17: Cebula żółta 40-80 mm; op.5-25 kg | C17: -- | D17: -- | E17: -- | F17: -- | G17: -- | H17: -- | I17: -- | J17: -- | K17: --
B18: Cebula biała 40-80 mm op.5-25 kg | C18: 1.06 | D18: 1.06 | E18: =((C18-D18)/D18)*100 | F18: 1 | G18: 1 | H18: =((F18-G18)/G18)*100 | I18: 0.6 | J18: 1 | K18: =((I18-J18)/J18)*100
B19: Marchew wszystkie odmiany pakowane luzem | C19: 1.97 | D19: 1.97 | E19: =((C19-D19)/D19)*100 | F19: 1.05 | G19: 1.1 | H19: =((F19-G19)/G19)*100 | I19: 1.5 | J19: 2.5 | K19: =((I19-J19)/J19)*100
B20: Pietruszka korzeń op. 10 kg | C20: -- | D20: -- | E20: -- | F20: 2.5 | G20: 2.5 | H20: =((F20-G20)/G20)*100 | I20: 1.9522222 | J20: 3 | K20: =((I20-J20)/J20)*100
B21: Pomidory, typ okrągły; op. 5-6-kg | C21: -- | D21: -- | E21: -- | F21: -- | G21: 10.8 | H21: -- | I21: 6.2477009 | J21: 14.6 | K21: =((I21-J21)/J21)*100
B22: Ogórki, typ gładkie; op. 5-6 kg | C22: -- | D22: -- | E22: -- | F22: 4.2 | G22: 3.1 | H22: =((F22-G22)/G22)*100 | I22: 14 | J22: 14 | K22: =((I22-J22)/J22)*100
B23: Seler | C23: -- | D23: -- | E23: -- | F23: 1.8 | G23: 1.8 | H23: =((F23-G23)/G23)*100 | I23: 1 | J23: 1 | K23: =((I23-J23)/J23)*100
B24: Sałata masłowa za główkę | C24: -- | D24: -- | E24: -- | F24: 2.4 | G24: 2.6 | H24: =((F24-G24)/G24)*100 | I24: -- | J24: -- | K24: --
B25: Szparagi biało/fioletowe >16mm | C25: -- | D25: -- | E25: -- | F25: -- | G25: -- | H25: -- | I25: -- | J25: -- | K25: --
B26: Burak ćwikłowy op. 10-15 kg | C26: -- | D26: -- | E26: -- | F26: 0.85 | G26: 0.85 | H26: =((F26-G26)/G26)*100 | I26: -- | J26: 0.9 | K26: --
B27: Kalafiory 12-20 cm | C27: -- | D27: -- | E27: -- | F27: 12 | G27: 12 | H27: =((F27-G27)/G27)*100 | I27: -- | K27: --
B28: Kapusta biała zł/kg | C28: -- | D28: -- | E28: -- | F28: 0.65 | G28: 0.65 | H28: =((F28-G28)/G28)*100 | I28: -- | J28: 0.5 | K28: --
B29: Rzodkiewka za pęczek 1 szt | C29: -- | D29: -- | E29: -- | F29: 1.9 | G29: 1.95 | H29: =((F29-G29)/G29)*100 | K29: --
B30: Ziemniaki (op. 15 kg) | C30: -- | D30: -- | E30: -- | F30: 0.45 | G30: 0.48 | H30: =((F30-G30)/G30)*100 | I30: -- | J30: -- | K30: --
B31: Pieczarki 30-65 mm | C31: -- | D31: -- | E31: -- | F31: 11.15 | G31: 11.15 | H31: =((F31-G31)/G31)*100 | I31: 8.4054871 | J31: 8.8775637 | K31: =((I31-J31)/J31)*100

Sheet HANDEL ZAGRANICZNY_I_XII_2025
D1: EKSPORT/WYWÓZ | H1: IMPORT/PRZYWÓZ | L1: SALDO
B2: CN | C2: Nazwa towaru | D2: Wartość [tys. EUR] | F2: Wolumen [tony] | H2: Wartość [tys. EUR] | J2: Wolumen [tony] | L2: Wartość [tys. EUR]
D3: I-XII 2024r. | E3: I-XII 2025r.* | F3: I-XII 2024r. | G3: I-XII 2025r.* | H3: I-XII 2024r. | I3: I-XII 2025r.* | J3: I-XII 2024r. | K3: I-XII 2025r.* | L3: I-XII 2024r. | M3: I-XII 2025r.*
B4: 0701 | C4: Ziemniaki, świeże lub chłodzone | D4: 46460.788 | E4: 47534.142 | F4: 119743.26 | G4: 160663.39 | H4: 63341.138 | I4: 68038.956 | J4: 157064.05 | K4: 179710.18 | L4: -16880.35 | M4: -20504.814
B5: 0702 | C5: Pomidory świeże lub chłodzone | D5: 118770.49 | E5: 127718.81 | F5: 78265.073 | G5: 80423.129 | H5: 420922.98 | I5: 440881.68 | J5: 246260.81 | K5: 237223.77 | L5: -302152.49 | M5: -313162.87
B6: 0703 | C6: Cebula, szalotka, czosnek, pory oraz inne warzywa | D6: 129088.63 | E6: 114533.35 | F6: 170182.02 | G6: 161761.06 | H6: 102974.43 | I6: 90718.876 | J6: 228146.95 | K6: 178305.02 | L6: 26114.198 | M6: 23814.477
B7: 0704 | C7: Kapusta, kalafiory, kalarepa, kapusta włoska, | D7: 78418.27 | E7: 72408.866 | F7: 103773.7 | G7: 93572.299 | H7: 91457.973 | I7: 96192.435 | J7: 85863.155 | K7: 87124.957 | L7: -13039.703 | M7: -23783.569
B8: 0705 | C8: Sałata (Lactuca sativa) i cykoria (Cichorium spp.), | D8: 32269.805 | E8: 32275.545 | F8: 26063.481 | G8: 24667.471 | H8: 97087.925 | I8: 103169.86 | J8: 73073.851 | K8: 79840.871 | L8: -64818.12 | M8: -70894.314
B9: 0706 | C9: Marchew, rzepa, buraki sałatkowe, salsefia, selery, | D9: 42404.232 | E9: 40859.998 | F9: 64597.357 | G9: 83701.753 | H9: 78545.05 | I9: 77346.817 | J9: 96386.332 | K9: 108823.43 | L9: -36140.818 | M9: -36486.819
B10: 0707 | C10: Ogórki i korniszony świeże | D10: 25426.211 | E10: 28415.476 | F10: 19346.303 | G10: 20608.521 | H10: 121899.39 | I10: 141998.66 | J10: 106985.88 | K10: 109228.17 | L10: -96473.177 | M10: -113583.19
B11: 0708 | C11: Warzywa strączkowe, nawet łuskane, świeże | D11: 15052.011 | E11: 13872.72 | F11: 27324.965 | G11: 32373.875 | H11: 4006.423 | I11: 4059.883 | J11: 4157.331 | K11: 3804.698 | L11: 11045.588 | M11: 9812.837
B12: 0709 | C12: Inne warzywa świeże lub chłodzone | D12: 681523.48 | E12: 670939.82 | F12: 323321.09 | G12: 310841.7 | H12: 345498.76 | I12: 384711.16 | J12: 168142.9 | K12: 182179.82 | L12: 336024.72 | M12: 286228.66
B13: 0710 | C13: Warzywa niegotowane lub gotowane na parze, zamrożone | D13: 432572.37 | E13: 415272.98 | F13: 407308.91 | G13: 396677.51 | H13: 78589.331 | I13: 92194.668 | J13: 68252.737 | K13: 78001.767 | L13: 353983.04 | M13: 323078.31
B14: 0711 | C14: Warzywa zakonserwowane tymczasowo | D14: 16368.888 | E14: 16323.561 | F14: 8776.655 | G14: 8581.733 | H14: 36676.991 | I14: 42908.572 | J14: 18377.683 | K14: 23606.869 | L14: -20308.103 | M14: -26585.011
B15: 0712 | C15: Warzywa suszone, całe, cięte w kawałki | D15: 110353.24 | E15: 110838.96 | F15: 45331.324 | G15: 33558.361 | H15: 71873.124 | I15: 66246.777 | J15: 22262.13 | K15: 21623.151 | L15: 38480.121 | M15: 44592.179
... B27: 0810 | C27: Pozostałe owoce, świeże | D27: 292567.88 | E27: 281130.08 | F27: 70540.003 | G27: 65970.394 | H27: 423150.1 | I27: 516564.96 | J27: 109894.76 | K27: 124926.08 | L27: -130582.21 | M27: -235434.88

Sheet HANDEL ZAGRANICZNY_I _II_2026
D5: EKSPORT/WYWÓZ | H5: IMPORT/PRZYWÓZ | L5: SALDO
B6: CN | C6: Nazwa towaru | D6: Wartość [tys. EUR] | F6: Wolumen [tony] | H6: Wartość [tys. EUR] | J6: Wolumen [tony] | L6: Wartość [tys. EUR]
D7: I-II 2025r.* | E7: I-II 2026r.* | F7: I-II 2025r.* | G7: I-II 2026r.* | H7: I-II 2025r.* | I7: I-II 2026r.* | J7: I-II 2025r.* | K7: I-II 2026r.* | L7: I-II 2025r.* | M7: I-II 2026r.*
B8: RAZEM (poz. HS - 0101 do 2403) | D8: 9137168.8 | E8: 8975386.4 | H8: 6391246.9 | I8: 6228661.4 | L8: 2745921.8 | M8: 2746725
B9: 0101 | C9: Konie żywe | D9: 2168.434 | E9: 2355.474 | F9: 687.066 | G9: 702.048 | H9: 947.103 | I9: 39.005 | J9: 16.309 | K9: 6.78 | L9: 1221.331 | M9: 2316.469
B10: 0102 | C10: Bydło żywe | D10: 4970.304 | E10: 3107.643 | F10: 1227.627 | G10: 636.153 | H10: 37111.526 | I10: 48789.892 | J10: 12712.87 | K10: 11093.652 | L10: -32141.222 | M10: -45682.249
B11: 0103 | C11: Trzoda chlewna żywa | D11: 396.382 | E11: 873.732 | F11: 231.43 | G11: 514.745 | H11: 107798.94 | I11: 95540.035 | J11: 46282.3 | K11: 52769.733 | L11: -107402.56 | M11: -94666.303
B12: 0104 | C12: Owce i kozy żywe | D12: 0 | E12: 0 | F12: 0 | G12: 0 | H12: 2.616 | I12: 23.534 | J12: 0.693 | K12: 7.682 | L12: -2.616 | M12: -23.534
B13: 0105 | C13: Drób domowy żywy | D13: 11065.506 | E13: 9751.567 | F13: 3408.966 | G13: 1257.86 | H13: 52530.589 | I13: 52152.514 | J13: 29791.661 | K13: 24215.579 | L13: -41465.083 | M13: -42400.947
B14: 0106 | C14: Pozostałe zwierzęta żywe | D14: 1241.482 | E14: 1364.316 | F14: 98.909 | G14: 89.768 | H14: 2565.806 | I14: 2177.348 | J14: 106.263 | K14: 66.463 | L14: -1324.324 | M14: -813.032
B15: 0201 | C15: Mięso wołowe świeże lub chłodzone | D15: 384663.82 | E15: 377013.47 | F15: 58727.561 | G15: 45297.701 | H15: 23191.852 | I15: 41781.213 | J15: 4201.716 | K15: 6563.634 | L15: 361471.97 | M15: 335232.26
B16: 0202 | C16: Mięso wołowe mrożone | D16: 107823.69 | E16: 114219.36 | F16: 17372.557 | G16: 14986.385 | H16: 6563.412 | I16: 10822.307 | J16: 1259.906 | K16: 1761.363 | L16: 101260.28 | M16: 103397.05
B17: 0203 | C17: Mięso wieprzowe świeże, chłodzone lub mrożone | D17: 147301.85 | E17: 129770.64 | F17: 62385.355 | G17: 63150.712 | H17: 270409.14 | I17: 232582.25 | J17: 114577.53 | K17: 122164.17 | L17: -123107.29 | M17: -102811.62
B18: 0204 | C18: Mięso baranie i kozie - świeże, chłodzone l. mrożone | D18: 462.102 | E18: 1697.403 | F18: 54.843 | G18: 222.042 | H18: 1203.407 | I18: 1891.023 | J18: 158.835 | K18: 224.268 | L18: -741.305 | M18: -193.62
B19: 0205 | C19: Mięso końskie | D19: 6574.573 | E19: 8514.853 | F19: 1245.902 | G19: 1597.648 | H19: 164.778 | I19: 175.794 | J19: 22.609 | K19: 15.989 | L19: 6409.795 | M19: 8339.059
B20: 0206 | C20: Jadalne podroby wołowe, wieprzowe, baranie, kozie, | D20: 31754.643 | E20: 31600.962 | F20: 30556.266 | G20: 29334.897 | H20: 3679.421 | I20: 5547.717 | J20: 2358.441 | K20: 3959.303 | L20: 28075.222 | M20: 26053.245
... B212: 2404 | C212: Produkty zaw. tytoń, nikotynę, przezn. do wdychania bez spalania; | D212: 35227.698 | E212: 74124.196 | F212: 1158.209 | G212: 1028.115 | H212: 61096.451 | I212: 35621.377 | J212: 2151.475 | K212: 787.753 | L212: -25868.753 | M212: 38502.819

Sheet EXP KRAJE I-II 2026
B2: HANDEL ZAGRANICZNY - DANE WSTĘPNE
B4: Źródło danych: Ministerstwo Finansów | Q4: =[3]POMOC!B5
B5: UWAGA! DANE W TRAKCIE WERYFIKACJI - MOGĄ BYĆ OBARCZONE ISTOTNYMI BŁĘDAMI
B6: Eksport jabłek (CN 080810) wg. ważniejszych krajów | J6: Eksport pomidorów (CN 070200) wg. ważniejszych krajów
B7: według ważniejszych krajów | K7: według ważniejszych krajów
B8: II 2025r.* | F8: II 2026r.* | K8: II 2025r.* | O8: II 2026r.*
B9: Kraj | C9: Wartość [tys. EUR] | D9: Wolumen [tony] | F9: Kraj | G9: Wartość [tys. EUR] | H9: Wolumen [tony] | K9: Kraj | L9: Wartość [tys. EUR] | M9: Wolumen [tony] | O9: Kraj | P9: Wartość [tys. EUR] | Q9: Wolumen [tony]
B10: OGÓŁEM | C10: 94296.884 | D10: 142907.02 | F10: OGÓŁEM | G10: 99738.715 | H10: 157433.87 | K10: OGÓŁEM | L10: 16504.714 | M10: 6524.635 | O10: OGÓŁEM | P10: 8599.366 | Q10: 3283.061
B11: Egipt | C11: 10109.075 | D11: 14169.275 | F11: Egipt | G11: 13189.905 | H11: 19240.133 | K11: Niemcy | L11: 8849.301 | M11: 3143.208 | O11: Holandia | P11: 4213.884 | Q11: 1057.829
B12: Niemcy | C12: 8994.215 | D12: 15022.812 | F12: Rumunia | G12: 7500.176 | H12: 13294.097 | K12: Holandia | L12: 3428.358 | M12: 1404.901 | O12: Ukraina | P12: 1963.365 | Q12: 1215.865
B13: Republika Czeska | C13: 7380.504 | D13: 10651.454 | F13: Niemcy | G13: 7426.92 | H13: 9829.662 | K13: Ukraina | L13: 1460.147 | M13: 817.138 | O13: Niemcy | P13: 1472.349 | Q13: 575.444
B14: Holandia | C14: 6732.964 | D14: 13647.156 | F14: Republika Czeska | G14: 5031.073 | H14: 8038.99 | K14: Wielka Brytania | L14: 864.288 | M14: 277.952 | O14: Wielka Brytania | P14: 543.82 | Q14: 222.009
B15: Rumunia | C15: 6328.219 | D15: 10091.886 | F15: India | G15: 4766.277 | H15: 10458.278 | K15: Szwecja | L15: 731.016 | M15: 314.767 | O15: Republika Czeska | P15: 89.941 | Q15: 44.13
B16: India | C16: 6228.358 | D16: 7794.72 | F16: Białoruś | G16: 4575.625 | H16: 7671.823 | K16: Republika Czeska | L16: 471.695 | M16: 204.423 | O16: Białoruś | P16: 64.22 | Q16: 17.55
B17: Wielka Brytania | C17: 4056.85 | D17: 5068.41 | F17: Holandia | G17: 4042.831 | H17: 8118.453 | K17: Węgry | L17: 297.523 | M17: 165.001 | O17: Litwa | P17: 43.228 | Q17: 24.435
B18: Szwecja | C18: 3600.39 | D18: 4670.076 | F18: Węgry | G18: 3719.405 | H18: 5377.881 | K18: Białoruś | L18: 128.27 | M18: 51.325 | O18: Słowacja | P18: 38.967 | Q18: 16.066
B19: Węgry | C19: 3593.553 | D19: 5736.99 | F19: Szwecja | G19: 3531.785 | H19: 4897.142 | K19: Litwa | L19: 90.173 | M19: 53.71 | O19: Węgry | P19: 34.619 | Q19: 41.105
B20: Hiszpania | C20: 3390.856 | D20: 4582.98 | F20: Kazachstan | G20: 3247.253 | H20: 5303.951 | K20: Francja | L20: 46.734 | M20: 33.955 | O20: Irlandia | P20: 34.567 | Q20: 11.63
B21: Kazachstan | C21: 2899.465 | D21: 6251.866 | F21: Litwa | G21: 3149.852 | H21: 5049.899 | K21: Łotwa | L21: 43.723 | M21: 15.201 | O21: Włochy | P21: 28.148 | Q21: 30.293
... B24: Mongolia | C24: 1834.29 | D24: 2688.805 | F24: Ukraina | G24: 2559.437 | H24: 4100.424 | K24: Belgia | L24: 16.136 | M24: 4.806 | O24: Łotwa | P24: 13.02 | Q24: 2.664
B25: Finlandia | C25: 1745.459 | D25: 2664.354 | F25: Słowacja | G25: 2476.685 | H25: 2972.501 | O25: Estonia | P25: 8.79 | Q25: 1.733
B26: Belgia | C26: 1724.598 | D26: 2522.36 | F26: Jordania | G26: 2325.778 | H26: 3491.395

Sheet IMP KRAJE I-XII 2025
B2: HANDEL ZAGRANICZNY I-XI 2025 - DANE WSTĘPNE
B4: Źródło danych: Ministerstwo Finansów | Q4: =[3]POMOC!B5
B5: UWAGA! DANE W TRAKCIE WERYFIKACJI - MOGĄ BYĆ OBARCZONE ISTOTNYMI BŁĘDAMI
B6: Import pomarańczy (CN 080510) wg. ważniejszych krajów | J6: Import winogron (CN 080610) wg. ważniejszych krajów
B7: według ważniejszych krajów | K7: według ważniejszych krajów
B8: I-XII 2024r. | F8: I-XII 2025r.* | K8: I-XII 2024r. | O8: I-XII 2025r.*
B9: Kraj | C9: Wartość [tys. EUR] | D9: Wolumen [tony] | F9: Kraj | G9: Wartość [tys. EUR] | H9: Wolumen [tony] | K9: Kraj | L9: Wartość [tys. EUR] | M9: Wolumen [tony] | O9: Kraj | P9: Wartość [tys. EUR] | Q9: Wolumen [tony]
B10: OGÓŁEM | C10: 132678.96 | D10: 153645.18 | F10: OGÓŁEM | G10: 141542.86 | H10: 155386.55 | K10: OGÓŁEM | L10: 253467.64 | M10: 123915.93 | O10: OGÓŁEM | P10: 266661.98 | Q10: 137711.73
B11: Hiszpania | C11: 46973.179 | D11: 52170.665 | F11: Hiszpania | G11: 54614.552 | H11: 57751.299 | K11: Włochy | L11: 76020.069 | M11: 45258.874 | O11: Włochy | P11: 82454.215 | Q11: 51058.577
B12: Niemcy | C12: 23778.266 | D12: 22662.082 | F12: Niemcy | G12: 23017.112 | H12: 22119.654 | K12: Niemcy | L12: 42346.738 | M12: 15822.594 | O12: Niemcy | P12: 46541.621 | Q12: 17915.067
B13: Grecja | C13: 21630.095 | D13: 26988.807 | F13: Egipt | G13: 17778.799 | H13: 24100.734 | K13: Peru | L13: 18599.061 | M13: 5691.825 | O13: Peru | P13: 22021.268 | Q13: 8795.527
B14: Egipt | C14: 13826.024 | D14: 24299.338 | F14: Republika Południowej Afryki | G14: 17467.278 | H14: 18664.663 | K14: Holandia | L14: 17711.005 | M14: 6652.908 | O14: India | P14: 18847.363 | Q14: 9151.269
B15: Republika Południowej Afryki | C15: 12712.954 | D15: 13855.719 | F15: Grecja | G15: 16961.194 | H15: 20440.511 | K15: Hiszpania | L15: 16147.945 | M15: 6826.342 | O15: Chile | P15: 15608.446 | Q15: 6896.697
B16: Włochy | C16: 3488.998 | D16: 3240.985 | F16: Zimbabwe | G16: 3750.019 | H16: 4852.788 | K16: Republika Południowej Afryki | L16: 15593.338 | M16: 6052.69 | O16: Mołdowa | P16: 14457.088 | Q16: 11491.432
B17: Holandia | C17: 3455.966 | D17: 2934.207 | F17: Włochy | G17: 2630.714 | H17: 2404.308 | K17: India | L17: 14674.232 | M17: 8216.408 | O17: Holandia | P17: 13849.502 | Q17: 4693.092
B18: Portugalia | C18: 2190.646 | D18: 2104.521 | F18: Portugalia | G18: 1836.693 | H18: 1746.701 | K18: Mołdowa | L18: 14261.16 | M18: 9425.039 | O18: Republika Południowej Afryki | P18: 13252.279 | Q18: 5406.039
B19: Zimbabwe | C19: 2128.474 | D19: 2578.098 | F19: Holandia | G19: 1303.63 | H19: 1378.27 | K19: Turcja | L19: 10629.273 | M19: 6491.362 | O19: Hiszpania | P19: 12216.576 | Q19: 5913.352
B20: Turcja | C20: 1403.846 | D20: 1714.432 | F20: Turcja | G20: 664.744 | H20: 798.411 | K20: Chile | L20: 8849.538 | M20: 3758.045 | O20: Grecja | P20: 9231.052 | Q20: 6222.532
B21: Urugwaj | C21: 300.514 | D21: 432.887 | F21: Iran | G21: 567.664 | H21: 103.6 | K21: Grecja | L21: 6001.072 | M21: 3838.416 | O21: Turcja | P21: 5212.929 | Q21: 3568.377
... B26: Izrael | C26: 70.875 | D26: 64.897 | F26: Cypr | G26: 65.137 | H26: 92.82 | K26: Macedonia | L26: 1183.496 | M26: 1012.34 | O26: Łotwa | P26: 1671.836 | Q26: 750.866

Sheet Sł_Pol-Ang
B2: DICTIONARY
B5: WARZYWA | C5: VEGETABLES | D5: OWOCE | E5: FRUITS
B6: Buraki czerwone | C6: Red beets | D6: Arbuzy | E6: Watermelons
B7: Cebula biała | C7: Onions dry | D7: Banany | E7: Bananas
B8: Czosnek | C8: Garlic | D8: Brzoskwinie | E8: Peaches
B9: Kalafiory | C9: Cauliflowers | D9: Cytryny | E9: Lemons
B10: Kapusta biała | C10: Cabbage- white | D10: Grapefruity | E10: Grapefruit
B11: Marchew | C11: Carrots | D11: Gruszki | E11: Pears
B12: Ogórki długie | C12: Cucumbers | D12: Jabłka | E12: Apples
B13: Ogórki krótkie | C13: Gherkins | D13: Kiwi | E13: Kiwifruit
B14: Ogórki gruntowe | C14: Cucumbers field | D14: Mandarynki | E14: Tangerine
B15: Papryka czerwona | C15: Peppers - red | D15: Nektaryny | E15: Nectarines
B16: Papryka żółta | C16: Peppers - yellow | D16: Pomarańcze | E16: Oranges
... B25: Ziemniaki | C25: Potatoes | D25: Pieczarki | E25: Champignons

Sheet POMOC
B2: POMOC
P4: =B5
B5: Notowania 27.04 - 05.05.2026 / Tydzień 18
B6: NR 18/2026

Sheet Moduł1

Sheet Moduł2

Sheet Moduł3

Sheet Moduł4

Sheet Moduł5

Sheet Moduł6

Sheet HURT OWOC
B1: Miejscowość | E1: Bronisze | G1: Kalisz | I1: Kraków | K1: Poznań | M1: Wrocław
B2: Data notowania | E2: 46147 | G2: 46146 | I2: 46146 | K2: 46146 | M2: 46146
B3: Owoce | D3: Jedn. | E3: Min | F3: Max | G3: Min | H3: Max | I3: Min | J3: Max | K3: Min | L3: Max | M3: Min | N3: Max
B4: KRAJOWE
B5: Gruszki | D5: kg
B6: Jabłka | E6: 4.5 | F6: 6.5 | G6: 5 | H6: 5 | I6: 3.5 | J6: 6 | K6: 5 | L6: 6.5 | M6: 3 | N6: 6
D7: kg
D8: kg | E8: 3 | F8: 5 | G8: 3.08 | H8: 3.46 | K8: 3.33 | L8: 4.33
D9: kg | E9: 2.5 | F9: 3.5 | G9: 3.08 | H9: 3.08
D10: kg | E10: 2.5 | F10: 3.75 | G10: 3.08 | H10: 3.08 | K10: 4 | L10: 4
D11: kg | E11: 2 | F11: 3 | G11: 3.08 | H11: 3.08 | K11: 3.33 | L11: 4
D12: kg | E12: 2 | F12: 3 | G12: 3.08 | H12: 3.08 | K12: 3.33 | L12: 4
D13: kg | E13: 2.85 | F13: 4 | G13: 3.08 | H13: 3.85 | K13: 3.33 | L13: 4.33
D14: kg | E14: 2 | F14: 3.5 | G14: 3.08 | H14: 3.08 | K14: 3.33 | L14: 4
D15: kg | E15: 3.25 | F15: 4 | G15: 3.08 | H15: 3.85
D16: kg | E16: 80 | F16: 95 | K16: 104 | L16: 112 | M16: 72 | N16: 100
B17: Truskawki | D17: kg | E17: 28 | F17: 35 | G17: 28 | H17: 30 | I17: 25 | J17: 35 | K17: 36 | L17: 40
B18: IMPORTOWANE
B19: Ananasy | D19: szt. | E19: 6 | F19: 9 | G19: 5 | H19: 15 | I19: 7.5 | J19: 8 | M19: 7 | N19: 11
B20: Arbuzy | D20: kg | E20: 7 | F20: 10 | G20: 4 | H20: 6 | I20: 6 | J20: 7 | K20: 11.5 | L20: 12.5 | M20: 7 | N20: 10.5
B21: Banany | D21: kg | E21: 4.2 | F21: 6.15 | G21: 4.44 | H21: 4.44 | I21: 5.5 | J21: 6 | K21: 5.28 | L21: 6.94 | M21: 4 | N21: 8.5
B22: Borówki amerykańskie | D22: kg | E22: 45 | F22: 80 | G22: 48 | H22: 80 | I22: 70 | J22: 80 | K22: 75 | L22: 80 | M22: 62 | N22: 66
B23: Cytryny | D23: kg | I23: 12 | J23: 14
B24: Grejpfruty | D24: kg | E24: 10 | F24: 14 | G24: 6.5 | H24: 9 | I24: 10.5 | J24: 11.5 | K24: 9.5 | L24: 12 | M24: 6.5 | N24: 9.5
B25: Gruszki | D25: kg | E25: 65 | F25: 100
B26: Maliny | D26: kg | E26: 5 | F26: 26 | G26: 5 | H26: 7 | I26: 6.5 | J26: 7 | K26: 7.14 | L26: 7.86 | M26: 6 | N26: 9
B27: Mandarynki | D27: kg | E27: 7 | F27: 7.25 | G27: 5 | H27: 7 | K27: 8.5 | L27: 10
B28: Nektarynki | D28: kg | I28: 60 | J28: 75 | K28: 88 | L28: 104
B29: Pomarańcze | D29: kg | E29: 4 | F29: 15 | G29: 6 | H29: 10 | I29: 4.8 | J29: 5.5 | K29: 9 | L29: 14 | M29: 6.5 | N29: 11
B30: Śliwki | D30: kg | E30: 28 | F30: 35 | M30: 7 | N30: 12
B31: Truskawki | D31: kg | E31: 2.5 | F31: 14 | G31: 4 | H31: 8 | I31: 3.5 | J31: 5.5 | K31: 7.5 | L31: 9.5 | M31: 5 | N31: 9.5
B32: Winogrona | D32: kg | E32: 17 | F32: 20 | G32: 14 | H32: 18 | I32: 12.5 | J32: 13 | K32: 15 | L32: 17 | M32: 12 | N32: 38
E33: 17 | F33: 22 | G33: 15 | H33: 20 | I33: 17 | J33: 20.7 | K33: 14 | L33: 18 | M33: 16 | N33: 20
