Workbook
Name \a: #N/A
Name \s: #REF!
Name _17_11_2011: #REF!
Name _7_11_2011: #REF!
Name _A: #REF!
Name a: #REF!
Name aa: #REF!
Name aaa: #REF!
Name aaaa: #REF!
Name aaas: #REF!
Name aassss: #REF!
Name AllPerc: #REF!,#REF!
Name AmisData: OFFSET(#REF!,0,0,COUNTA(#REF!),23)
Name AmisDataPig: OFFSET(#REF!,0,0,COUNTA(#REF!),20)
Name AmisDataPiglet: OFFSET(#REF!,0,0,COUNTA(#REF!),27)
Name aqwq: #REF!,#REF!
Name BothPerc: #REF!
Name Ceny: #REF!
Name cenyd: #REF!
Name Charakterystyka_tabela1_Lista: #REF!
Name ColPre: #REF!
Name CurShe: #REF!
Name dd: #REF!
Name dsxa: #REF!
Name fg: #REF!
Name FirstPerc: #REF!
Name gg: #REF!
Name hh: #REF!
Name hj: #REF!
Name j: OFFSET(#REF!,0,0,COUNTA(#REF!),20)
Name jgg: OFFSET(#REF!,0,0,COUNTA(#REF!),20)
Name jjjjjj: #REF!
Name jose: #REF!
Name Last5: #REF!
Name MaxDate: '[2]Amis Exchange rate'!$D$2
Name MonPre: #REF!
Name n: #REF!
Name NumPri: #REF!
Name oooooooo: #REF!
Name ppp: #REF!
Name Prosieta: #REF!
Name q: #REF!
Name recap: #REF!
Name s: #REF!
Name SecondPerc: #REF!
Name ss: #REF!
Name ssfg: #REF!
Name sss: #REF!
Name ssssaaa: #REF!
Name TodDat: #REF!
Name uboje: #REF!
Name uuu: #REF!
Name WeeNum: #REF!
Name zx: #REF!
Name zywiec: #REF!
Name zzz: #N/A
Name \s: #REF!
Name _17_11_2011: #REF!
Name _7_11_2011: #REF!
Name aa: OFFSET(#REF!,0,0,COUNTA(#REF!),27)

Sheet INFO
B5: ZINTEGROWANY SYSTEM ROLNICZEJ INFORMACJI RYNKOWEJ
B10: Rynek
B11: owoców i warzyw
B14: NR 34/2026
M16: 27 sierpnia 2026 r.
D19: zsrir.minrol.gov.pl
A22: Informacje dot. cen hurtowych dostarczone są przez przedstawicieli niżej wymienionych rynków hurtowych.
A23: Warszawski Rolno-Spożywczy Rynek Hurtowy S.A. – Bronisze – www.bronisze.com.pl; Giełda - Białystok Podlaskie Centrum Rolno Towarowe S.A. - https://www.podlaskiecentrum.pl/; Lubelski Rynek Hurtowy S.A. – Lublin – www.elizowka.pl, Wielkopolska Gildia Rolno-Ogrodnicza S.A. – Poznań – www.wgro.com.pl; Podkarpackie Centrum Hurtowe Agrohurt S.A. – Rzeszów – www.mgrt.rzeszow.pl; Zachodniopomorskie Centrum Hurtowe Rolhurt- www.rolhurt.pl, Mewat Bydgoszcz - www.targowisko.mewat.pl, Rolno-spożywczy rynek hurtowy we Wrocławiu - http://www.targpiast.com.pl/, Łódzki Rynek Hurtowy ZJAZDOWA S.A. https://zjazdowa.com.pl/., Radomska Giełda Rolna - https://rsrh-radom.pl/, Targowisko Miejskie Sandomierz - http://targowiskasandomierz.pl/, Kompleks Handlowy RYBITWY - https://khrybitwy.pl/.

Sheet SPIS
B2: SPIS TREŚCI
C6: ZMIANY CEN HURTOWYCH
C7: CENY HURTOWE WARZYW
C8: CENY HURTOWE OWOCÓW
C9: CENY OWOCÓW ORGANIZACJI PRODUCENTÓW
C10: CENY OWOCÓW DO PRZETWORSTWA
C11: CENY WARZYW DO PRZETWORSTWA
C12: CENY DETALICZNE OWOCÓW
C13: CENY DETALICZNE WARZYW
C14: WYKRESY - OWOCE DETAL
C15: WYKRESY - WARZYWA DETAL
C16: IERGZ - CENY WARZYW
C17: IRGZ- CENY W ZAKŁADACH PRZETWÓRCZYCH I SPÓLDZIELNIACH
... C20: HANDEL ZAGRANICZNY

Sheet ZMIANY HURT
B2: ZMIANY ŚREDNICH CEN HURTOWYCH DLA WYBRANEGO ASORTYMENTU OWOCÓW I WARZYW
O4: =POMOC!B5
D5: Cena zł/jedn | H5: Zmiany ceny (%)
B6: Produkt | C6: Jedn. | D6: 46261 | F6: 46254 | H6: w stosunku do poprzedniego notowania*) | J6: 2 tyg. | L6: 3 tyg. | N6: 4 tyg.
D7: Min | E7: Max | F7: Min | G7: Max | H7: Min | I7: Max | J7: Min | K7: Max | L7: Min | M7: Max | N7: Min | O7: Max
B8: 1 | C8: 2 | D8: 3 | E8: 4 | F8: 5 | G8: 6 | H8: 7 | I8: 8 | J8: 9 | K8: 10 | L8: 11 | M8: 12 | N8: 13 | O8: 14
B9: Warzywa krajowe
B10: Boczniaki | C10: kg | D10: 21.75 | E10: 27.5 | F10: 21.166667 | G10: 27 | H10: -5.7683326 | I10: -1.3247863 | J10: -3.2837967 | K10: -4.2385534 | L10: -5.7683326 | M10: -4.2385534 | N10: -11.771137 | O10: -11.645408
B11: Buraki ćwikłowe | C11: kg | D11: 0.93333333 | E11: 1.2666667 | F11: 1.0166667 | G11: 1.31 | H11: -8.1967213 | I11: -3.307888 | J11: 7.6923077 | K11: 0 | L11: 3.7037037 | M11: -7.3170732 | N11: 0.9009009 | O11: -6.1728395
B12: Cebula biała | C12: kg | D12: 1.1 | E12: 1.5833333 | F12: 1.1825 | G12: 1.605 | H12: -6.9767442 | I12: -1.3499481 | J12: -34.6211 | K12: -32.191292 | L12: -34.6211 | M12: -31.084512 | N12: -34.328358 | O12: -31.15942
B13: Cebula młoda | C13: kg | D13: 3.75 | E13: 5 | F13: 4.1666667 | G13: 4.8333333 | H13: -10 | I13: 3.4482759 | J13: -13.461538 | K13: 0 | L13: 18.421053 | M13: 0 | N13: -19.642857 | O13: -16.666667
B14: Kalafiory | C14: szt. | D14: 3.75 | E14: 5.7925 | F14: 4.626 | G14: 6.814 | H14: -18.936446 | I14: -14.991195 | J14: -20.212766 | K14: -12.234848 | L14: -8.5365854 | M14: -1.8220339 | N14: -19.642857 | O14: -15.231707
B15: Kapusta biała | C15: kg | D15: 0.86666667 | E15: 1.1 | F15: 0.9 | G15: 1.1 | H15: -3.7037037 | I15: 0 | J15: -18.75 | K15: -13.157895 | L15: -24.637681 | M15: -21.428571 | N15: -24.637681 | O15: -21.428571
B16: Kapusta młoda | C16: szt. | D16: 2.2075 | E16: 3.125 | F16: 2.666 | G16: 3.25 | H16: -17.19805 | I16: -3.8461538 | J16: -20.191612 | K16: -15.540541 | L16: -22.976274 | M16: -17.763158 | N16: -25.042445 | O16: -17.291575
B17: Marchew | C17: kg | D17: 1.1 | E17: 1.6333333 | F17: 1.1666667 | G17: 1.7333333 | H17: -5.7142857 | I17: -5.7692308 | J17: -5.7142857 | K17: -5.7692308 | L17: -13.157895 | M17: -18.333333 | N17: -27.868852 | O17: -24.031008
B18: Ogórki gruntowe | C18: kg | D18: 3.1 | E18: 6 | F18: 2.6 | G18: 4.7333333 | H18: 19.230769 | I18: 26.760563 | J18: 16.25 | K18: 20 | L18: 25.675676 | M18: 52.542373 | N18: -31.111111 | O18: -7.6923077
B19: Papryka czerwona | C19: kg | D19: 6.65 | E19: 8.25 | F19: 6.12 | G19: 8.1 | H19: 8.6601307 | I19: 1.8518519 | J19: -6.8627451 | K19: -5.3899083 | L19: 3.90625 | M19: -8.3333333 | N19: -7.2093023 | O19: -14.655172
B20: Papryka zielona | C20: kg | D20: 4.9 | E20: 6.1 | F20: 4.65 | G20: 5.85 | H20: 5.3763441 | I20: 4.2735043 | J20: 6.5217391 | K20: 8.9285714 | L20: -2 | M20: 1.6666667 | N20: 2.0833333 | O20: -3.1746032
B21: Papryka żółta | C21: kg | D21: 7.65 | E21: 9.25 | F21: 7.65 | G21: 9.25 | H21: 0 | I21: 0 | J21: 5.9556787 | K21: 7.5581395 | L21: 13.333333 | M21: 2.7777778 | N21: 13.333333 | O21: 0
... B31: Ziemniaki młode | C31: kg | D31: 1.4 | E31: 1.7 | F31: 1.4 | G31: 1.68 | H31: -1.5860329e-14 | I31: 1.1904762 | J31: 18.98017 | K31: 19.437939 | L31: 18.98017 | M31: 19.437939 | N31: -10.828025 | O31: -7.3569482
B32: Owoce krajowe
B33: Borówki amerykańskie | C33: kg | D33: 20.75 | E33: 26.75 | F33: 19.2 | G33: 24 | H33: 0 | I33: 0 | J33: 0 | K33: 0 | L33: 0 | M33: 0 | N33: 0 | O33: 0
B34: Brzoskwinie | C34: kg | D34: 5 | E34: 7.7 | F34: 5.1 | G34: 7.88 | H34: -1.9607843 | I34: -2.284264 | J34: -17.491749 | K34: -8.3333333 | L34: -17.491749 | M34: -6.097561 | N34: -28.571429 | O34: -12.5
B35: Gruszki | C35: kg | D35: 4.6666667 | E35: 6.1666667 | F35: 5 | G35: 5.75 | H35: -6.6666667 | I35: 7.2463768 | J35: -6.6666667 | K35: 7.2463768 | L35: -6.6666667 | M35: 7.2463768 | N35: 3.7037037 | O35: 9.6296296
B36: Czereśnie | C36: kg | D36: 11.75 | E36: 17.5 | F36: 11.666667 | G36: 17.583333 | H36: 0.71428571 | I36: -0.47393365 | J36: -6 | K36: -11.764706 | L36: 15.196078 | M36: -8.8541667 | N36: 6.8181818 | O36: -11.764706
B37: Maliny | C37: kg | D37: 33.25 | E37: 45.25 | F37: 33.2 | G37: 44 | H37: 0.15060241 | I37: 2.8409091 | J37: -7.6388889 | K37: -2.0562771 | L37: 3.90625 | M37: 4.9883991 | N37: 0.75757576 | O37: 8.6
B38: Morele | C38: kg | D38: 6.25 | E38: 9.375 | F38: 5.8 | G38: 8.6 | H38: 7.7586207 | I38: 9.0116279 | J38: -2.34375 | K38: -1.3157895 | L38: 0.80645161 | M38: -1.3157895 | N38: -0.26595745 | O38: -2.173913
B39: Nektarynki | C39: kg | D39: 6.5 | E39: 6.5 | F39: 6.5 | G39: 6.5 | H39: 0 | I39: 0 | J39: -7.1428571 | K39: -7.1428571 | L39: -7.1428571 | M39: -7.1428571 | N39: -18.75 | O39: -18.75
B40: Śliwki | C40: kg | D40: 3.5 | E40: 6 | F40: 3.6 | G40: 5.8 | H40: -2.7777778 | I40: 3.4482759 | J40: -14.634146 | K40: -10.447761 | L40: -10.25641 | M40: -6.25 | N40: -26.956522 | O40: -28
B41: Truskawki | C41: kg | D41: 18 | E41: 21.625 | F41: 17.4 | G41: 21 | H41: 3.4482759 | I41: 2.9761905 | J41: 21.621622 | K41: 12.046632 | L41: 17.647059 | M41: -4.7356828 | N41: 18.681319 | O41: -7.6512456
B42: Porzeczki czarne | C42: kg | D42: 15 | E42: 15 | F42: 15 | G42: 17.5 | H42: 0 | I42: -14.285714 | J42: -13.461538 | K42: -21.052632 | L42: -15.730337 | M42: -27.884615 | N42: -21.052632 | O42: -35.251799
B43: Porzeczki czerwone | C43: kg | D43: 17 | E43: 18 | F43: 12.5 | G43: 15.75 | H43: 36 | I43: 14.285714 | J43: 28.787879 | K43: 13.924051 | L43: 28.787879 | M43: 20 | N43: 34.210526 | O43: 18.681319
B44: Wiśnie | C44: kg | D44: 8.4175 | E44: 10.5825 | F44: 8.394 | G44: 10.13 | H44: 0.27996188 | I44: 4.4669299 | J44: 2.652439 | K44: 0.47949107 | L44: 6.0940257 | M44: 3.0829924 | N44: -5.058651 | O44: -7.1710526
B45: Jabłka:
B46: Antonówki | C46: kg | D46: 2.7125 | E46: 4.295 | F46: 3.425 | G46: 3.925 | H46: -20.80292 | I46: 9.4267516 | J46: -20.80292 | K46: 0.94007051 | L46: -37.064965 | M46: -10.706861
B47: Celesta | C47: kg | D47: 2.6433333 | E47: 4.1366667 | F47: 3.08 | G47: 3.08 | H47: -14.177489 | I47: 34.307359 | J47: -14.177489 | K47: 34.307359 | L47: -14.177489 | M47: 34.307359
B48: Gala | C48: kg | D48: 2.54 | E48: 3.04 | F48: 2 | G48: 3 | H48: 27 | I48: 1.3333333 | J48: 27 | K48: 1.3333333 | L48: 1.6 | M48: -13.142857 | N48: -8.9605735 | O48: -7.5987842
B49: Golden | C49: kg | D49: 2.54 | E49: 3.04 | F49: 2 | G49: 3 | H49: 27 | I49: 1.3333333 | J49: 27 | K49: 1.3333333 | L49: -21.846154 | M49: -21.548387 | N49: -21.846154 | O49: -21.548387
B50: Idared | C50: kg | D50: 1.33 | E50: 2.67 | F50: 1.33 | G50: 2.67 | H50: 0 | I50: 0 | J50: 0 | K50: 0 | L50: -42.918455 | M50: -11 | N50: -42.918455 | O50: -11
B51: Jonagold | C51: kg | D51: 2.36 | E51: 3.1366667 | F51: 2 | G51: 3 | H51: 18 | I51: 4.5555556 | J51: 18 | K51: -10.380952 | L51: 18 | M51: -10.380952 | N51: 18 | O51: -10.380952
...

Sheet HURT WARZ
B2: ŚREDNIE CENY WARZYW NA RYNKACH HURTOWYCH
E5: Bronisze | G5: Kalisz | I5: Łódź | K5: Poznań
B6: Data notowania | E6: 46260 | G6: 46259 | I6: 46260 | K6: 46259
B7: Warzywa | E7: Min | F7: Max | G7: Min | H7: Max | I7: Min | J7: Max | K7: Min | L7: Max
B8: KRAJOWE
B9: Buraki ćwikłowe | D9: kg | E9: 0.8 | F9: 1.2 | G9: 1 | H9: 1 | I9: 1 | J9: 1.6 | K9: 3 | L9: 3.2
B10: Cebula biała | D10: kg | E10: 1.1 | F10: 1.75 | G10: 1 | H10: 1 | I10: 1.2 | J10: 2
B11: Cebula młoda | D11: kg | E11: 3.5 | F11: 5 | K11: 4 | L11: 5
B12: Kalafiory | D12: szt. | E12: 4 | F12: 5 | G12: 1 | H12: 1.17 | I12: 3 | J12: 9 | K12: 7 | L12: 8
B13: Kapusta biała | D13: kg | E13: 0.7 | F13: 0.9 | G13: 0.9 | H13: 1 | I13: 1 | J13: 1.4
B14: Kapusta młoda | D14: szt. | E14: 2.5 | F14: 3 | G14: 1 | H14: 1.5 | I14: 2 | J14: 4 | K14: 3.33 | L14: 4
B15: Marchew | D15: kg | E15: 1 | F15: 1.5 | G15: 1 | H15: 1.2 | I15: 1.3 | J15: 2.2
B16: Marchew młoda | D16: pęczek | E16: 3.5 | F16: 4.5 | G16: 2.5 | H16: 2.5 | K16: 5 | L16: 5
B17: Ogórki gruntowe | D17: kg | E17: 3 | F17: 9 | G17: 3 | H17: 4 | I17: 2 | J17: 6 | K17: 4.4 | L17: 5
B18: Ogórki szklarniowe | D18: kg | E18: 2 | F18: 4 | G18: 2 | H18: 2.5 | I18: 3 | J18: 6 | K18: 4 | L18: 5
B19: Papryka czerwona | D19: kg | E19: 6 | F19: 9 | G19: 6 | H19: 6 | I19: 6 | J19: 9 | K19: 8.6 | L19: 9
B20: Papryka zielona | D20: kg | E20: 5 | F20: 7 | G20: 4 | H20: 4 | I20: 5 | J20: 7 | K20: 5.6 | L20: 6.4
B21: Papryka żółta | D21: kg | E21: 6 | F21: 9 | G21: 7 | H21: 7 | I21: 9 | J21: 12 | K21: 8.6 | L21: 9
B22: Pietruszka | D22: kg | E22: 3.5 | F22: 5 | G22: 3 | H22: 3 | I22: 4 | J22: 6 | K22: 5 | L22: 6
B23: Pomidory | D23: kg | E23: 5.5 | F23: 7 | G23: 4.5 | H23: 4.5 | I23: 4 | J23: 7.5 | K23: 6 | L23: 6.67
B24: Pomidory gruntowe | D24: kg | E24: 2.2 | F24: 3.5 | G24: 2.5 | H24: 3 | I24: 2.26 | J24: 4.17 | K24: 5 | L24: 5.83
B25: Pomidory malinowe | D25: kg | E25: 3.66 | F25: 8.33 | G25: 4.5 | H25: 5 | I25: 4.17 | J25: 7.5 | K25: 6 | L25: 6.67
B26: Pory | D26: szt. | G26: 1 | H26: 2 | I26: 1.5 | J26: 2.5
B27: Pory młode | D27: szt. | E27: 2.25 | F27: 3 | I27: 2 | J27: 3 | K27: 2.3 | L27: 2.5
B28: Rzodkiewka | D28: pęczek | E28: 2 | F28: 2.75 | G28: 1.5 | H28: 1.5 | I28: 1.5 | J28: 2.5 | K28: 2 | L28: 2
B29: Sałata | D29: szt. | E29: 2.25 | F29: 4 | G29: 2.08 | H29: 2.08 | I29: 2.5 | J29: 3.5 | K29: 3 | L29: 3.33
B30: Selery | D30: kg | E30: 1.4 | F30: 2 | G30: 2 | H30: 2 | I30: 2 | J30: 4 | K30: 3.6 | L30: 4
B31: Ziemniaki | D31: kg | E31: 0.66 | F31: 1.75 | G31: 0.8 | H31: 1 | I31: 0.53 | J31: 1.07 | K31: 2 | L31: 2.4
B32: Boczniaki | D32: kg | E32: 13.5 | F32: 20 | K32: 30 | L32: 35
B33: Pieczarki | D33: kg | E33: 9 | F33: 12 | G33: 10 | H33: 10 | I33: 6.67 | J33: 11.67 | K33: 11 | L33: 13
B34: Selery młode | D34: kg
D35: szt. | E35: 2 | F35: 3
B36: Ziemniaki | D36: kg | E36: 0.66 | F36: 1.1 | I36: 1.34 | J36: 1.34 | K36: 0.53 | L36: 1.07
B37: Ziemniaki młode | D37: kg | G37: 0.53 | H37: 0.67 | I37: 1.67 | J37: 2

Sheet HURT OWOC
B2: ŚREDNIE CENY OWOCÓW NA RYNKACH HURTOWYCH
M4: =POMOC!B5
B5: Miejscowość | E5: Bronisze | G5: Kalisz | I5: Łódź | K5: Poznań
B6: Data notowania | E6: 46260 | G6: 46259 | I6: 46260 | K6: 46259
B7: Owoce | D7: Jedn. | E7: Min | F7: Max | G7: Min | H7: Max | I7: Min | J7: Max | K7: Min | L7: Max
B8: KRAJOWE
B9: Borówki amerykańskie | D9: kg | E9: 18 | F9: 30 | G9: 20 | H9: 24 | I9: 20 | J9: 23 | K9: 25 | L9: 30
B10: Brzoskwinie | D10: kg | E10: 5 | F10: 7 | G10: 4 | H10: 5 | I10: 5 | J10: 8 | K10: 6 | L10: 10.8
B11: Czereśnie | D11: kg | E11: 10 | F11: 20 | G11: 15 | H11: 15 | I11: 10 | J11: 18 | K11: 12 | L11: 17
B12: Gruszki | D12: kg | E12: 6 | F12: 6.5 | G12: 5 | H12: 5 | K12: 3 | L12: 7
B13: Jabłka
C14: Antonówki | D14: kg | E14: 3 | F14: 4 | G14: 3.85 | H14: 3.85 | I14: 2 | J14: 4 | K14: 2 | L14: 5.33
C15: Celesta | D15: kg | E15: 2.85 | F15: 4 | G15: 3.08 | H15: 3.08 | K15: 2 | L15: 5.33
C16: Delikates | D16: kg | E16: 3 | F16: 4 | I16: 2 | J16: 4
C17: Gala | D17: kg | E17: 2 | F17: 3 | G17: 3.08 | H17: 3.08
C18: Golden | D18: kg | E18: 2 | F18: 3 | G18: 3.08 | H18: 3.08
C19: Jonagold | D19: kg | E19: 2 | F19: 3 | G19: 3.08 | H19: 3.08 | I19: 2 | J19: 3.33
C20: Ligol | D20: kg | E20: 2 | F20: 3 | G20: 3.85 | H20: 3.85
C21: Piros | D21: kg | E21: 3 | F21: 4 | G21: 3.08 | H21: 3.08 | I21: 2.67 | J21: 4.33 | K21: 2 | L21: 4.67
C22: Szampion | D22: kg | E22: 2 | F22: 3.5 | G22: 3.08 | H22: 3.08 | I22: 1.67 | J22: 3.33
C23: Paula-Red | D23: kg | E23: 3 | F23: 4 | G23: 3.08 | H23: 3.08 | I23: 2 | J23: 4 | K23: 2 | L23: 4.67
D24: kg | E24: 25 | F24: 35 | G24: 32 | H24: 48 | I24: 32 | J24: 50 | K24: 44 | L24: 48
D25: kg | E25: 5 | F25: 9 | G25: 5 | H25: 8 | I25: 5 | J25: 8.5 | K25: 10 | L25: 12
D26: kg | G26: 5 | H26: 5 | K26: 8 | L26: 8
D27: kg | E27: 2 | F27: 5 | G27: 3 | H27: 4 | I27: 3 | J27: 9 | K27: 6 | L27: 6
B28: Maliny | D28: kg | E28: 17 | F28: 25 | G28: 15 | H28: 20 | I28: 16 | J28: 17.5 | K28: 24 | L28: 24
B29: Morele | D29: kg | E29: 9 | F29: 12 | G29: 8 | H29: 8 | I29: 6 | J29: 10 | K29: 10.67 | L29: 12.33
B30: Nektarynki
B31: Porzeczki czarne | D31: szt. | E31: 5 | F31: 9 | G31: 5 | H31: 15 | I31: 5 | J31: 17
B32: Porzeczki czerwone | D32: kg | E32: 1.75 | F32: 4.3 | G32: 2 | H32: 4.5 | I32: 1.8 | J32: 4 | K32: 4.5 | L32: 5
B33: Śliwki | D33: kg | E33: 4.2 | F33: 6.15 | G33: 3.89 | H33: 3.89 | I33: 3.33 | J33: 6.11 | K33: 4.72 | L33: 6.94
B34: Truskawki | D34: kg | E34: 6 | F34: 8 | G34: 6 | H34: 6 | I34: 7 | J34: 9
B35: Wiśnie | D35: kg | E35: 5 | F35: 7 | G35: 5 | H35: 5 | I35: 8 | J35: 10 | K35: 8 | L35: 9
B36: IMPORTOWANE | D36: kg | E36: 5 | F36: 26 | G36: 5 | H36: 7 | I36: 7 | J36: 9 | K36: 7.14 | L36: 7.86
B37: Ananasy | D37: kg | E37: 7 | F37: 7.25 | G37: 7 | H37: 7 | I37: 7.5 | J37: 8.33 | K37: 8.5 | L37: 9
B38: Arbuzy | D38: kg | E38: 7 | F38: 12 | G38: 8 | H38: 8 | I38: 7.5 | J38: 11 | K38: 9 | L38: 10
B39: Banany | D39: kg | E39: 5 | F39: 10 | G39: 7 | H39: 7 | I39: 9 | J39: 12 | K39: 10 | L39: 12
B40: Brzoskwinie | D40: kg | E40: 5 | F40: 9 | G40: 6 | H40: 7 | I40: 6 | J40: 10 | K40: 7 | L40: 9
B41: Cytryny | D41: kg | E41: 2.5 | F41: 14 | G41: 4 | H41: 8 | I41: 7 | J41: 9 | K41: 7.5 | L41: 8
B42: Grejpfruty | D42: kg | E42: 3 | F42: 6 | K42: 8 | L42: 9.5
...

Sheet ADRESY RYNKÓW HURTOWYCH 
A2: Adresy rynków hurtowych z których MINROL pobiera informacje do Biuletynu Informacyjnego ;
A3: 1. www.bronisze.com.pl
A4: 2. https://podlaskiecentrum.pl/
A5: 3. https://gieldakaliska.pl/
A6: 4. https://www.elizowka.pl/
A7: 5. https://www.targpiast.com.pl/pl
A8: 6. https://www.zjazdowa.com.pl/pl/serwis-cenowy/
A9: 7. https://wgro.com.pl/notowania-cenowe-maly-hurt/
A10: 8. https://khrybitwy.pl/
A11: 9. https://www.agrohurtsa.pl/

Sheet OWOCE ORGANIZACJE SKUP
B2: ŚREDNIE CENY ZAKUPU JABŁEK I GRUSZEK PŁACONE PRZEZ ORGANIZACJE PRODUCENTÓW - najważniejsze odmiany
B3: (zł/100 kg)
B5: TOWAR | C5: 23.08.2026 | D5: 16.08.2026 | E5: 24.08.2025 | F5: Zmiana ceny (%)
F6: tygodniowa | G6: roczna
B7: Jabłka (razem) | C7: 139.07946 | D7: nld | E7: nld | F7: - | G7: -
B8: Boskoop | C8: --- | D8: --- | E8: --- | F8: - | G8: -
B9: Gala | C9: nld | D9: nld | E9: nld | F9: - | G9: -
B10: Gloster | C10: --- | D10: --- | E10: --- | F10: - | G10: -
B11: Golden delicious | C11: 143.975 | D11: nld | E11: nld | F11: - | G11: -
B12: Idared | C12: nld | D12: nld | E12: nld | F12: - | G12: -
B13: Jonagold/Jonagored | C13: nld | D13: nld | E13: nld | F13: - | G13: -
B14: Ligol | C14: nld | D14: nld | E14: nld | F14: - | G14: -
B15: Szampion | C15: nld | D15: nld | E15: nld | F15: - | G15: -
B16: Gruszki (razem) | C16: --- | D16: --- | E16: --- | F16: - | G16: -

Sheet OWOCE ORGANIZACJE SPRZEDAŻ
B2: ŚREDNIE CENY SPRZEDAŻY JABŁEK I GRUSZEK PŁACONE PRZEZ ORGANIZACJE PRODUCENTÓW - główne odmiany
B3: (zł/100 kg)
B5: TOWAR | C5: 23.08.2026 | D5: 16.08.2026 | E5: 24.08.2025 | F5: Zmiana ceny (%)
F6: tygodniowa | G6: roczna
B7: Jabłka (razem) | C7: 260.40505 | D7: nld | E7: nld | F7: - | G7: -
B8: Boskoop | C8: --- | D8: --- | E8: --- | F8: - | G8: -
B9: Gala | C9: 299.62165 | D9: nld | E9: nld | F9: - | G9: -
B10: Gloster | C10: --- | D10: --- | E10: --- | F10: - | G10: -
B11: Golden delicious | C11: 268.13363 | D11: nld | E11: nld | F11: - | G11: -
B12: Idared | C12: nld | D12: nld | E12: nld | F12: - | G12: -
B13: Jonagold/Jonagored | C13: 266.58451 | D13: nld | E13: nld | F13: - | G13: -
B14: Ligol | C14: 291.97079 | D14: nld | E14: nld | F14: - | G14: -
B15: Szampion | C15: 245.28931 | D15: nld | E15: nld | F15: - | G15: -
B16: Gruszki (razem) | C16: --- | D16: --- | E16: --- | F16: - | G16: -

Sheet OWOCE PRZETWÓRSTWO
B2: ŚREDNIE CENY ZAKUPU OWOCÓW płacone przez podmioty zajmujące się przetwórstwem
B3: (zł/100 kg)
B5: Towar | C5: Przeznaczenie | D5: 23.08.2026 | E5: 16.08.2026 | F5: 24.08.2025 | G5: Zmiana ceny (%)
G6: tygodniowa | H6: roczna
B7: Jabłka | C7: ogółem | D7: 71.221317 | E7: 70.643757 | F7: 75.029479 | G7: 0.81756784 | H7: -5.0755543
C8: na sok zagęszczony | D8: 71.063521 | E8: 70.495278 | F8: 74.99795 | G8: 0.80607249 | H8: -5.2460496
C9: Inne (np. dżemy, przeciery, marmolada) | D9: 71.493747 | E9: --- | F9: nld | G9: - | H9: -
B10: Maliny | C10: ogółem | D10: 1913.1843 | E10: 1826.1201 | F10: 982.24487 | G10: 4.7677106 | H10: 94.776711
C11: na mrożonki | D11: 1913.1843 | E11: 1858.5519 | F11: nld | G11: 2.9395129 | H11: -
B12: Wiśnie | C12: ogółem | D12: nld | E12: 354.6862 | F12: 474.28577 | G12: - | H12: -
C13: na sok zagęszczony | D13: nld | E13: 329.03773 | F13: nld | G13: - | H13: -
C14: na mrożonki | D14: --- | E14: 513.41365 | F14: nld | G14: - | H14: -
B15: Aronia | C15: ogółem | D15: 495.24485 | E15: 400.74592 | F15: 322.67328 | G15: 23.580759 | H15: 53.481828
C16: na sok zagęszczony | D16: 494.15193 | E16: 409.3872 | F16: 320.06543 | G16: 20.70527 | H16: 54.39091

Sheet WARZYWA PRZETWÓRSTWO
B2: ŚREDNIE CENY ZAKUPU WARZYW płacone przez podmioty zajmujące się przetwórstwem
B3: (zł/100 kg)
B5: Towar | C5: 23.08.2026 | D5: 16.08.2026 | E5: 24.08.2025 | F5: Zmiana ceny (%)
F6: tygodniowa | G6: roczna
B7: Cebula biała obierana | C7: 126.98339 | D7: 111.84045 | E7: nld | F7: 13.539768 | G7: -
B8: Ogórki / ogółem | C8: 305.43484 | D8: 297.46395 | E8: 363.6884 | F8: 2.6796167 | G8: -16.017437
B9: Ogórki / 6-9 cm | C9: 331.10864 | D9: 329.54629 | E9: nld | F9: 0.47409305 | G9: -
B10: Ogórki / 9-12 cm | C10: 131.66361 | D10: 139.54278 | E10: 185.47893 | F10: -5.6464224 | G10: -29.01425
B11: Ogórki / powyżej 12 cm | C11: 133.43797 | D11: nld | E11: nld | F11: - | G11: -

Sheet ZAKUP OWOCE DETAL - LUZ
B2: ŚREDNIE CENY ZAKUPU OWOCÓW PŁACONE PRZEZ PODMIOTY HANDLU DETALICZNEGO - luz
B3: (zł/100 kg)
B5: OWOCE krajowe - luzem
B6: TOWAR | C6: 23.08.2026 | D6: 16.08.2026 | E6: 24.08.2025 | F6: Zmiana ceny (%)
F7: tygodniowa | G7: roczna
B8: Jabłka (razem) | C8: 294.21946 | D8: 297.54843 | E8: 497.88119 | F8: -1.1187995 | G8: -40.905689
B9: Gala | C9: 381.76499 | D9: 377.03061 | E9: 474.79088 | F9: 1.2557008 | G9: -19.593024
B10: Golden delicious | C10: 358.80947 | D10: 353.50395 | E10: 514.93741 | F10: 1.5008372 | G10: -30.319791
B11: Idared | C11: 343.90143 | D11: 343.32005 | E11: 476.25364 | F11: 0.16934119 | G11: -27.790278
B12: Jonagold/Jonagored | C12: 274.23138 | D12: 275.82317 | E12: 504.29269 | F12: -0.57710513 | G12: -45.620592
B13: Ligol | C13: 345.0183 | D13: 334.66603 | E13: 506.04024 | F13: 3.0933126 | G13: -31.819988
B14: Cortland | C14: --- | D14: --- | E14: --- | F14: - | G14: -
B15: Boskoop | C15: --- | D15: --- | E15: --- | F15: - | G15: -
B16: Granny Smith | C16: --- | D16: --- | E16: --- | F16: - | G16: -
B17: Elstar | C17: --- | D17: --- | E17: --- | F17: - | G17: -
B18: Lobo | C18: --- | D18: --- | E18: --- | F18: - | G18: -
B19: Red Delicious | C19: --- | D19: --- | E19: --- | F19: - | G19: -
B20: Szampion | C20: 324.71917 | D20: 309.50568 | E20: 503.20917 | F20: 4.9154141 | G20: -35.47034
B22: OWOCE z importu - luzem
B23: TOWAR | C23: 23.08.2026 | D23: 16.08.2026 | E23: 24.08.2025 | F23: Zmiana ceny (%)
F24: tygodniowa | G24: roczna
B25: Jabłka-Granny Smith | C25: nld | D25: nld | E25: nld | F25: - | G25: -
B26: Pomarańcze (razem) | C26: 1527.4894 | D26: 508.08634 | E26: 522.14593 | F26: 200.6358 | G26: 192.54071
B27: Pomarańcze nieokreślone | C27: 1696.0171 | D27: 519.38688 | E27: 512.36266 | F27: 226.54216 | G27: 231.01888
B28: Navel | C28: nld | D28: nld | E28: nld | F28: - | G28: -
B29: Salustiana Novelinas | C29: nld | D29: nld | E29: nld | F29: - | G29: -
B30: Tarroco | C30: --- | D30: --- | E30: --- | F30: - | G30: -
B31: Lanelate | C31: nld | D31: nld | E31: nld | F31: - | G31: -
B32: Navelate | C32: --- | D32: --- | E32: --- | F32: - | G32: -
B33: Valencia Late | C33: nld | D33: nld | E33: nld | F33: - | G33: -
B34: Brzoskwinie (razem) | C34: 635.58006 | D34: 640.54356 | E34: 785.90456 | F34: -0.77488943 | G34: -19.127577
B35: Brzoskwinie biały miąższ | C35: 857.1913 | D35: 860.85159 | E35: nld | F35: -0.42519376 | G35: -
B36: Brzoskwinie zółty miąższ | C36: 631.67279 | D36: 663.28118 | E36: 777.94309 | F36: -4.7654588 | G36: -18.802185
B37: Nektaryny (razem) | C37: 650.14975 | D37: 576.24763 | E37: 819.56121 | F37: 12.824716 | G37: -20.670995
B38: Nektaryny biały miąższ | C38: --- | D38: --- | E38: nld | F38: - | G38: -
B39: Nektaryny żółty miąższ | C39: 600.18149 | D39: 584.7012 | E39: 780.5023 | F39: 2.6475573 | G39: -23.103174

Sheet ZAKUP WARZ DETAL - LUZ
B2: ŚREDNIE CENY ZAKUPU WARZYW PŁACONE PRZEZ PODMIOTY HANDLU DETALICZNEGO - luz
B3: (zł/100 kg)
B5: WARZYWA krajowe - luzem
B6: TOWAR | C6: 23.08.2026 | D6: 16.08.2026 | E6: 24.08.2025 | F6: Zmiana ceny (%)
F7: tygodniowa | G7: roczna
B8: Cebula biała | C8: 219.00932 | D8: 216.65981 | E8: --- | F8: 1.0844217 | G8: -
B9: Marchew | C9: 169.52512 | D9: 186.13748 | E9: 172.21716 | F9: -8.9247765 | G9: -1.563165
B10: Ogórki szklarniowe | C10: 392.89486 | D10: 377.41715 | E10: --- | F10: 4.1009573 | G10: -
B11: Papryka czerwona | C11: 818.54567 | D11: 734.07444 | E11: --- | F11: 11.507175 | G11: -
B12: Pomidory okrągłe | C12: 532.53498 | D12: 522.05044 | E12: 459.01458 | F12: 2.0083386 | G12: 16.017007
B13: Pomidory na gałązkach | C13: 572.9945 | D13: 502.60144 | E13: 445.6115 | F13: 14.005743 | G13: 28.586111
B14: Pomidory typu "cherry" | C14: 1013.2494 | D14: 1012.7967 | E14: 1056.2785 | F14: 0.044702057 | G14: -4.073653
B15: Ziemniaki | C15: 107.29196 | D15: 106.93315 | E15: 121.9055 | F15: 0.33554469 | G15: -11.987601
B17: WARZYWA z importu - luzem
B18: TOWAR | C18: 23.08.2026 | D18: 16.08.2026 | E18: 24.08.2025 | F18: Zmiana ceny (%)
F19: tygodniowa | G19: roczna
B20: Cebula biała | C20: nld | D20: nld | E20: --- | F20: - | G20: -
B21: Marchew | C21: nld | D21: nld | E21: nld | F21: - | G21: -
B22: Ogórki szklarniowe | C22: --- | D22: --- | E22: --- | F22: - | G22: -
B23: Papryka czerwona | C23: 688.79298 | D23: 596.87487 | E23: --- | F23: 15.399896 | G23: -
B24: Pomidory okrągłe | C24: nld | D24: nld | E24: nld | F24: - | G24: -
B25: Pomidory na gałązkach | C25: nld | D25: 624.95987 | E25: nld | F25: - | G25: -
B26: Pomidory typu "cherry" | C26: nld | D26: nld | E26: 1587.6996 | F26: - | G26: -
B27: Ziemniaki | C27: nld | D27: nld | E27: nld | F27: - | G27: -

Sheet ZAKUP WARZ DETAL - DO 2 KG
B2: ŚREDNIE CENY ZAKUPU WARZYW PŁACONE PRZEZ PODMIOTY HANDLU DETALICZNEGO - opakowania do 2 kg
B3: (zł/100 kg)
B5: WARZYWA krajowe - opakowania do 2 kg
B6: TOWAR | C6: 23.08.2026 | D6: 16.08.2026 | E6: 24.08.2025 | F6: Zmiana ceny (%)
F7: tygodniowa | G7: roczna
B8: Cebula biała | C8: 224.11136 | D8: 211.91179 | E8: --- | F8: 5.7569113 | G8: -
B9: Marchew | C9: 324.56246 | D9: 334.75458 | E9: 316.78326 | F9: -3.0446554 | G9: 2.4556854
B10: Ogórki szklarniowe | C10: --- | D10: --- | E10: --- | F10: - | G10: -
B11: Papryka czerwona | C11: 1620.9266 | D11: 1610.3219 | E11: --- | F11: 0.65854367 | G11: -
B12: Pomidory okrągłe | C12: 763.81511 | D12: 760.55892 | E12: 662.26116 | F12: 0.42813063 | G12: 15.334426
B13: Pomidory na gałązkach | C13: 1141.5901 | D13: 1147.9993 | E13: 1149.133 | F13: -0.55829278 | G13: -0.65640171
B14: Pomidory typu "cherry" | C14: 1693.8574 | D14: 1684.4921 | E14: 1414.2144 | F14: 0.55597296 | G14: 19.773733
B15: Ziemniaki | C15: 176.76751 | D15: 177.41482 | E15: 206.52941 | F15: -0.36485668 | G15: -14.410488
B17: WARZYWA z importu - do 2 kg
B18: TOWAR | C18: 23.08.2026 | D18: 16.08.2026 | E18: 24.08.2025 | F18: Zmiana ceny (%)
F19: tygodniowa | G19: roczna
B20: Cebula biała | C20: 905.42368 | D20: 855.46291 | E20: --- | F20: 5.8402021 | G20: -
B21: Marchew | C21: nld | D21: nld | E21: nld | F21: - | G21: -
B22: Ogórki szklarniowe | C22: nld | D22: nld | E22: --- | F22: - | G22: -
B23: Papryka czerwona | C23: 2396.338 | D23: 594.88805 | E23: --- | F23: 302.82168 | G23: -
B24: Pomidory okrągłe | C24: nld | D24: nld | E24: nld | F24: - | G24: -
B25: Pomidory na gałązkach | C25: nld | D25: nld | E25: nld | F25: - | G25: -
B26: Pomidory typu "cherry" | C26: 663.60321 | D26: 680.4369 | E26: 1191.4368 | F26: -2.4739532 | G26: -44.302275
B27: Ziemniaki | C27: --- | D27: --- | E27: --- | F27: - | G27: -

Sheet DETAL OWOCE WYKRES 
B2: Średnie ceny zakupu jabłek (luzem) płacone przez podmioty handlu detalicznego
M4: =POMOC!B5

Sheet DETAL WARZ WYKRES
B2: Średnie ceny zakupu warzyw (luzem) płacone przez podmioty handlu detalicznego
M4: =POMOC!B5
B60: 12.07.2026 | C60: 05.07.2026
A61: Marchew | B61: 2.48 | C61: 2.56
A62: Pomidory okrągłe | B62: 4.207 | C62: 3.86
A63: Ziemniaki | B63: 1.259 | C63: 1.43

Sheet IERGZ_warzywa
B2: Ogrodniczy Informator Cenowy
B3: Instytut Ekonomiki Rolnictwa i Gospodarki Żywnościowej Państwowy Instytut Badawczy
B4: 00-950 Warszawa, ul.Świętokrzyska 20, P.O. Box 984
B5: tel. (22) 505 44 32, e-mail: Tomasz.Smolenski@ierigz.waw.pl
B7: Ceny skupu netto warzyw i owoców w spółdzielniach ogrodniczych zbierane 24 VIII 2026 r.
B8: Województwo | C8: Buraki ćwikłowe | D8: Cebula | E8: Kaputa wczesna/a | F8: Kapusta włoska | G8: Kapusta pekińska | H8: Fasola szparagowa | I8: Kiszona kapusta | J8: Ogórki kiszone | K8: Sałata masłowa | L8: Kalafiory/a | M8: Brokuły/a | N8: Kalarepa/a | O8: Cukinia
B9: kujawsko-pomorskie | C9: 0,42-0,51 | D9: 0,44-0,49 | E9: 1,15-1,20 | F9: 2,00-2,15 | G9: 1,75-1,95 | H9: 6,75-7,65 | J9: 6,98-7,66 | K9: 1,40-1,55 | L9: 2,45-2,87 | N9: 1,15-1,56 | O9: 1,00-1,25
B10: lubelskie | C10: 0,41-0,47 | D10: 0,51-0,60 | E10: 1,15-1,25 | F10: 1,95-2,10 | I10: 6,89-7,45 | L10: 2,66-3,10 | M10: 2,35-2,65
B11: lubelskie | C11: 0,46-0,53 | D11: 0,57-0,68 | G11: 1,85-1,99 | H11: 6,25-6,89 | J11: 6,89-7,55
B12: łódzkie | C12: 0,46-0,53 | D12: 0,46-0,54 | F12: 2,20-2,30 | I12: 6,35-7,38 | L12: 2,98-3,45 | M12: 2,15-2,72 | N12: 1,37-1,45 | O12: 1,.27-1,38
B13: łódzkie | C13: 0,47-0,58 | D13: 0,51-0,55 | G13: 1,76-2,10 | H13: 6,25-6,77 | I13: 6,22-7,45 | J13: 7,68-7,95 | K13: 1,45-1,52 | L13: 2,75-3,58
B14: małopol. | C14: 0,44-0,52 | D14: 0,49-0,57 | E14: 1,00-1,10 | F14: 1,96-2,23 | I14: 5,89-6,75 | J14: 6,98-7,36 | L14: 2,56-3,10 | N14: 1,37-1,40 | O14: 1,15-1,33
B15: małopol. | C15: 0,41-0,46 | D15: 0,51-0,63 | I15: 6,21-6,88 | J15: 6,80-7,44 | K15: 1,46-1,55 | M15: 2,23-2,69
B16: małopol. | C16: 0,45-0,48 | D16: 0,53-0,57 | H16: 6,82-7,41 | I16: 6,44-7,65
B17: małopol. | C17: 0,46-0,50 | D17: 0,45-0,67 | E17: 1,10-1,13 | F17: 1,98-2,45 | G17: 1,85-1,93 | J17: 6,87-7,54 | K17: 1,43-1,56 | L17: 2,89-3,25 | N17: 1,20-1,60 | O17: 1,24-1,36
B18: mazowiec. | C18: 0,43-0,53 | D18: 0,52-0,58 | F18: 2,00-2,25 | G18: 1,77-1,94 | H18: 6,45-7,35 | I18: 6,99-7,45 | L18: 3,35-3,87 | M18: 2,15-2,68
B19: podkarp. | C19: 0,40-0,46 | D19: 0,51-0,57 | E19: 1,15-1,25 | I19: 6,80-7,33 | J19: 6,66-7,54
B20: podkarp. | C20: 0,42-0,46 | D20: 0,46-0,52 | H20: 6,38-6,90 | J20: 6,56-7,13 | L20: 2,98-3,45
B21: Cena średnia | C21: 0,40-0,58 | D21: 0,44-0,68 | E21: 1,00-1,25 | F21: 1,95-2,45 | G21: 1,75-2,10 | H21: 6,25-7,65 | I21: 5,89-7,65 | J21: 6,56-7,95 | K21: 1,40-1,56 | L21: 2,45-3,87 | M21: 2,15-2,72 | N21: 1,15-1,60 | O21: 1,00-1,38
B22: tydzień temu | C22: 0,41-0,60 | D22: 0,46-0,69 | E22: 1,10-1,35 | F22: 2,00-2,60 | G22: 1,80-2,52 | H22: 5,89-7,68 | I22: 6,25-7,95 | J22: 6,56-7,95 | K22: 1,40-1,56 | L22: 2,55-3,66 | M22: 2,25-2,60 | N22: 1,10-1,65 | O22: 1,10-1,58
B23: rok temu | C23: 0,56-0,78 | D23: 0,65-0,78 | E23: 1,22-1,54 | F23: 2,15-2,53 | G23: 1,85-2,30 | H23: 6,58-7,89 | I23: 6,45-7,85 | J23: 6,89-8,55 | K23: 1,56-1,80 | L23: 2,89-3,99 | M23: 2,25-2,89 | N23: 1,35-1,87 | O23: 1,09-1,45
B25: Województwo | C25: Marchew (myta) | D25: Pieczarki | E25: Pietruszka | F25: Pory | G25: Czosnek/a | H25: Rzodkiewka/b | I25: Selery | J25: Pomidory | K25: Ogórki | L25: Sałata masłowa
B26: kujawsko-pomorskie | C26: 1,89-2,37 | D26: 6,35-7,35 | E26: 1,65-1,98 | F26: 1,75-1,89 | G26: 1,25-1,45 | H26: 1,75-2,15 | I26: 0,75-0,96 | J26: 1,55-1,98 | K26: 1,55-1,89 | L26: 1,75-1,90
B27: lubelskie | C27: 2,10-2,45 | D27: 5,78-6,98 | E27: 1,75-2,15 | F27: 1,89-2,45 | G27: 1,35-1,40 | I27: 0,84-0,93 | J27: 1,65-2,56 | K27: 1,66-1,78 | L27: 1,65-1,77
B28: małopol. | C28: 2,00-2,21 | D28: 7,45-8,00 | E28: 2,20-2,45 | F28: 2,20-2,38 | H28: 1,96-2,45 | I28: 0,82-0,97 | K28: 1,45-1,68
B29: małopol. | C29: 1,95-2,45 | D29: 6,70-7,35 | E29: 2,35-2,89 | F29: 2,44-2,89 | G29: 1,45--1,68 | I29: 0,84-0,93 | J29: 2,15-2,65 | K29: 2,25-2,68 | L29: 1,80-2,10
B30: mazowiec. | C30: 2,10-2,56 | D30: 7,15-7,45 | E30: 2,20-2,40 | F30: 1,80-2,14 | G30: 1,14-1,38 | H30: 2,25-2,78 | I30: 0,83-0,94 | J30: 2,25-2,45 | K30: 2,35-2,84
B31: mazowiec. | C31: 2,15-2,60 | D31: 6,85-7,99 | E31: 2,31-2,69 | F31: 2,54-2,66 | G31: 1,30-1,40 | H31: 2,40-2,89 | I31: 0,92-1,10 | L31: 1,95-2,35
B32: podkarp. | C32: 2,10-2,38 | D32: 6,55-7,35 | E32: 2,34-2,78 | F32: 2,44-2,78 | J32: 2,46-2,68 | K32: 2,56-2,80
B33: podkarp. | C33: 2,00-2,35 | D33: 6,25-7,80 | E33: 2,17-2,90 | F33: 2,35-2,88 | G33: 1,25-1,38 | H33: 2,35-2,68 | I33: 0,78-0,93
B34: Cena średnia | C34: 1,89-2,60 | D34: 5,78-8,00 | E34: 1,65-2,90 | F34: 1,75-2,89 | G34: 1,14-1,68 | H34: 1,75-2,89 | I34: 0,75-1,10 | J34: 1,55-2,68 | K34: 1,45-2,84 | L34: 1,65-2,35
B35: tydzień temu | C35: 1,78-2,68 | D35: 6,31-7,96 | E35: 1,85-2,99 | F35: 2,35-2,99 | G35: 1,12-1,57 | H35: 1,88-2,66 | I35: 0,65-0,97 | J35: 1,45-2,60 | K35: 1,64-2,87 | L35: 1,58-1,97
B36: rok temu | C36: 1,85-2,78 | D36: 6,35-8,45 | E36: 1,85-3,15 | F36: 2,78-3,15 | G36: 1,25-1,75 | H36: 1,75-2,88 | I36: 0,85-1,15 | J36: 1,77-2,54 | K36: 1,75-2,69 | L36: 1,45-1,97
B37: a/sztuka,b/peczek

Sheet IERGZ_owoce
B2: Ogrodniczy Informator Cenowy
B3: Instytut Ekonomiki Rolnictwa i Gospodarki Żywnościowej Państwowy Instytut Badawczy
B5: Ceny skupu netto owoców w spółdzielniach ogrodniczych zbierane 24 VIII 2026 r.
B6: Województwo | C6: Jabłka deserowe | D6: Jabłka przemysłowe | E6: Gruszki | F6: Wiśnie | G6: Maliny | H6: Borówki wysokie
B7: kujawsko-pomorskie | C7: 1,35-1,56
B8: lubelskie | C8: 1,25-1,55 | D8: 0,50-0,75 | E8: 3,65-4,56 | H8: 7,56-7,98
B9: łódzkie | C9: 1,20-1,60 | E9: 3,88-4,98 | F9: 7,89-8,66 | G9: 22,56-24,69 | H9: 6,75-7,66
B10: łódzkie | C10: 1,10-1,37 | D10: 0,56-0,65 | E10: 3,76-4,60
B11: łódzkie | G11: 24,78-26,33 | H11: 6,56-8,45
B12: małopolskie | C12: 1,47-1,76 | E12: 3,98-4,90
B13: małopolskie | C13: 1,45-1,65 | G13: 21,56-22,78 | H13: 8,56-11,25
B14: małopolskie | C14: 1,10-1,20 | D14: 0,64-0,70 | E14: 3,87-4,72 | F14: 7,45-8,33
B15: małopolskie
B16: małopolskie | D16: 0,52-0,63 | H16: 8,40-9,35
B17: mazowiec. | C17: 1,35-1,54 | E17: 3,98-4,70 | F17: 6,98-7,99 | G17: 21,65-24,68
B18: podkarp. | C18: 1,35-1,45 | D18: 0,55-0,70
B19: podkarp. | E19: 3,65-4,76
B20: Cena średnia | C20: 1,10-1,76 | D20: 0,50-0,75 | E20: 3,65-4,98 | F20: 6,98-8,66 | G20: 21,56--26,33 | H20: 6,56-11,25
B21: tydzień temu | C21: 1,15-1,75 | D21: 0,55-0,70 | E21: 3,56-4,98 | F21: 6,35-8,99 | G21: 20,45-26,89 | H21: 5,45-11,30
B22: rok temu | C22: 1,15-2,30 | D22: 0,60-0,79 | E22: 3,98-5,10 | F22: 7,98-8,77 | G22: 17,89-21,65 | H22: 8,98-12,45
B23: s/"suchy" przemysł, */jabłka w kal. 65+ i do średniej nie wliczana jest odmiana Antonówka

Sheet Zaklady 
B2: Ogrodniczy Informator Cenowy
B3: Instytut Ekonomiki Rolnictwa i Gospodarki Żywnościowej Państwowy Instytut Badawczy
B4: Zakład Ekonomiki Gospodarstw Rolnych i Ogrodniczych
B7: Ceny skupu netto w zakładach przetwórczych i chłodniach zbierane 17 VIII 2026 r. (zł/kg)
K8: Jabłka | O8: Fasola szparagowa | P8: Cebula | Q8: Truskawki | R8: Rabarbar | S8: Jabłka | Z8: Malina | AA8: Jabłka | AB8: Jeżyny | AC8: Cuukinia
K9: przemysłowe | P9: obrana | Q9: z szyp[ułką | S9: przemyslowe | Z9: do mrożenia | AA9: przemyslowe | AC9: na kostkę
B10: kujawsko-pomor.
B11: kujawsko-pomor. | P11: 1,15-1,20lz | AC11: 0,60-0,68lz
B12: kujawsko-pomor. | P12: 1,20lz-1,25lz | R12: 2,50lz-2,50lz
B13: kujawsko-pomor. | P13: 1,25lz-1,35lz | R13: 2,50lz-3,00lz
B14: lubelskie | K14: 0,32-0,36lz | O14: 1,15lz-1,25lz | S14: 0,60lz-0,60lz | AA14: 0,60lz-0,60lz
B15: lubelskie | R15: 3,50lz | AC15: 0,65lz
B16: lubelskie | Q16: 3,45lz-3,89lz | S16: 0,50-0,60lz-0,90lz-1,20lz | Z16: 16,50lz/II-17,00lz/I | AA16: 0,55lz-0,65lz | AB16: 6,50lz-7,00lz
B17: lubelskie | O17: 1,15lz-1,25lz | S17: 0,65lz-0,75lz
B18: lubelskie | Z18: 16,00lz/II-16,50lz-17,00lz/I | AC18: 0,60-0,65lz
B19: lubuskie | Q19: 3,56lz-4,00lz | R19: 2,50lz-3,50lz
B20: łódzkie | O20: 1,30lz/k | S20: 0,50lz-0,60lz | AA20: 0,50lz-0,70lz
B21: łódzkie | Q21: 3,45lz-3,75lz
B22: małopolskie | K22: 0,31-0,35lz | AB22: 6,00lz-7,00lz
B23: mazowieckie | S23: 0,65lz-0,90lz-1,15lz-1,20lz
B24: mazowieckie | K24: 0,32-0,35lz | Q24: 3,58lz-3,80lz | AB24: 5,50-6,00lz-7,00lz
B25: podkarpackie
B26: podkarpackie
B27: podlaskie | K27: 0,36lz
B28: podlaskie
B29: śląskie
B30: świętokrzyskie | Q30: 3,68lz-3,85lz
B31: wielkopolskie | P31: 1,35lz
B32: wielkopolskie
B33: zachodnio-pomor.
B35: średnio | K35: 0,32-0,36lz | O35: 1,10lz-1,25lz-1,30lz/k | P35: 1,15-1,20lz-1,35lz | Q35: 3,45lz-4,00lz | R35: 2,50lz-3,50lz | S35: 0,50lz-0,65lz/na sok-0,90lz-1,20lz/do obierania | Z35: 16,00lz-16,50lz/II--17,00lz/I | AA35: 0,50lz-0,70lz | AB35: 5,50lz-6,00lz-7,00lz | AC35: 0,60-0,65lz-0,68lz
B37: tydzień temu | K37: 0,32-0,36lz | O37: 1,10lz-1,25lz | P37: 1,15-1,20-1,30lz | Q37: 3,50-3,50lz-4,50lz | R37: 2,50lz-3,50lz | S37: 0,50lz-0,65lz/na sok-0,90lz-1,20lz/do obierania | Z37: 17,00lz-17,50lz/II--17,50lz-18,00lz/I | AA37: 0,50lz-0,65lz | AB37: 5,50lz-6,00lz-7,50lz | AC37: 0,60-0,68lz-0,70lz
B39: rok temu | K39: 0,27-0,33lz | O39: 1,00-1,10/k | P39: 1,40-1,50lz | Q39: 5,75-6,00lz-6,50lz | R39: 5,00-6,50lz | S39: 1,00lz-1,25lz 1,30;-1,40lz-1,60lz/do obierania | Z39: 8,00lz/II-9,25lz/I-10,25lz/extra | AA39: 1,00lz-1,25lz 1,30;-1,40lz-1,60lz/do obierania | AB39: 5,00-5,50lz-6,00lz | AC39: 0,65-0,70
B72: lz/ cena loco zakład, k/kontraktacja,kl.I/klasa I, kl.II/klasa II,extra/klasa ekstra,m/"mokry" przemysł,s/ "suchy" przemysł,W/Węgierka

Sheet ow_KRIR
C1: Tygodniowy Serwis Cenowy
B2: 34 tydzień | C2: dla producentów owoców i warzyw
B3: 17.08-23.08.2026 r | C3: Krajowa Rada Izb Rolniczych
C4: Parzniew ul. Przyszłości 5, 05-804 Pruszków
C5: tel. 881-939-421, www.krir.pl, sekretariat@krir.pl
B6: Serwis znajduje się obecnie w fazie rozwoju i dotyczy wybranych produktów w niektórych województwach.
B8: Województwo/Towar | C8: Mazowieckie | F8: Świętokrzyskie | I8: Wielkopolskie
C9: 17.08 - 23.08.2026r. cena w zł/kg (szt*) | D9: 20.07 - 26.07.2026r. cena w zł/kg (szt*) | E9: tygodniowa zmiana ceny w % | F9: 17.08 - 23.08.2026r. cena w zł/kg (szt*) | G9: 20.07 - 26.07.2026r. cena w zł/kg (szt*) | H9: tygodniowa zmiana ceny w % | I9: 17.08 - 23.08.2026r. cena w zł/kg (szt*) | J9: 20.07 - 26.07.2026r. cena w zł/kg (szt*) | K9: tygodniowa zmiana ceny w %
B10: Jabłka (op.5-20 kg) Golden delicious (70/80mm) | C10: -- | D10: -- | E10: =((C10-D10)/D10)*100 | H10: -- | I10: -- | J10: -- | K10: --
B11: Jabłka (op.5-20 kg) Jonagold+Jonagored (70/80mm) | C11: -- | D11: -- | E11: -- | G11: -- | H11: -- | I11: -- | J11: -- | K11: --
B12: Jabłka (op.5-20 kg) Idared (70/80mm) | C12: -- | D12: -- | E12: =((C12-D12)/D12)*100 | G12: -- | H12: -- | I12: -- | J12: -- | K12: --
B13: Jabłka (op.5-20 kg) Shampion (70/80mm) | C13: -- | D13: -- | E13: =((C13-D13)/D13)*100 | F13: 1.7 | G13: -- | H13: -- | I13: -- | J13: -- | K13: --
B14: Jabłka (op.5-20 kg) Boskoop (70/80mm) | C14: -- | D14: -- | E14: -- | F14: 2 | G14: -- | H14: -- | I14: -- | J14: -- | K14: --
B15: Jabłka (op.5-20 kg) Gala (65/70mm) | C15: -- | D15: -- | E15: -- | G15: -- | H15: -- | I15: -- | J15: -- | K15: --
B16: Gruszki (op.5-20 kg) Lukasówka (65/70 mm) | C16: 3.45 | D16: -- | E16: =((C16-D16)/D16)*100 | F16: 2.5 | G16: -- | H16: -- | I16: -- | J16: -- | K16: --
B17: Cebula żółta 40-80 mm; op.5-25 kg | C17: -- | D17: -- | E17: -- | G17: -- | H17: -- | I17: -- | J17: -- | K17: --
B18: Cebula biała 40-80 mm op.5-25 kg | C18: 1.48 | D18: -- | E18: =((C18-D18)/D18)*100 | G18: -- | H18: -- | I18: 1.2 | J18: -- | K18: --
B19: Marchew wszystkie odmiany pakowane luzem | C19: 1.3 | D19: -- | E19: =((C19-D19)/D19)*100 | G19: -- | H19: -- | I19: 1.2 | J19: -- | K19: --
B20: Pietruszka korzeń op. 10 kg | C20: -- | D20: -- | E20: -- | G20: -- | H20: -- | I20: 3 | J20: -- | K20: --
B21: Pomidory, typ okrągły; op. 5-6-kg | C21: 4.5 | D21: -- | E21: =((C21-D21)/D21)*100 | G21: -- | H21: -- | I21: 4.9227455 | J21: -- | K21: =((I21-J21)/J21)*100
B22: Ogórki, typ gładkie; op. 5-6 kg | C22: 4.04 | D22: -- | E22: =((C22-D22)/D22)*100 | F22: 2.5 | G22: -- | H22: =((F22-G22)/G22)*100 | I22: 2.1357175 | J22: -- | K22: --
B23: Seler | C23: -- | D23: -- | E23: -- | G23: -- | H23: -- | I23: 2.5003048 | J23: -- | K23: --
B24: Sałata masłowa za główkę | C24: -- | D24: -- | E24: -- | G24: -- | H24: -- | I24: -- | J24: -- | K24: --
B25: Szparagi biało/fioletowe >16mm | C25: -- | D25: -- | E25: -- | G25: -- | H25: -- | I25: -- | J25: -- | K25: --
B26: Burak ćwikłowy op. 10-15 kg | C26: -- | D26: -- | E26: -- | G26: -- | H26: -- | I26: 0.9 | J26: -- | K26: --
B27: Kalafiory 12-20 cm | C27: -- | D27: -- | E27: -- | F27: 4 | G27: -- | H27: =((F27-G27)/G27)*100 | I27: 5 | J27: -- | K27: =((I27-J27)/J27)*100
B28: Kapusta biała zł/kg | C28: -- | D28: -- | E28: -- | G28: -- | H28: -- | I28: 1.02 | J28: -- | K28: --
B29: Rzodkiewka za pęczek 1 szt | C29: -- | D29: -- | E29: -- | G29: -- | H29: -- | I29: -- | J29: -- | K29: --
B30: Ziemniaki (op. 15 kg) | C30: 1.11 | D30: -- | E30: =((C30-D30)/D30)*100 | F30: 0.7 | G30: -- | H30: -- | I30: -- | J30: -- | K30: --
B31: Pieczarki 30-65 mm | C31: -- | D31: -- | E31: -- | F31: 11.35 | G31: -- | H31: -- | I31: 10 | J31: -- | K31: =((I31-J31)/J31)*100

Sheet HANDEL ZAGRANICZNY_I_XII_2025
D6: EKSPORT/WYWÓZ | H6: IMPORT/PRZYWÓZ | L6: SALDO
B7: CN | C7: Nazwa towaru | D7: Wartość [tys. EUR] | F7: Wolumen [tony] | H7: Wartość [tys. EUR] | J7: Wolumen [tony] | L7: Wartość [tys. EUR]
D8: I-XII 2024r. | E8: I-XII 2025r.* | F8: I-XII 2024r. | G8: I-XII 2025r.* | H8: I-XII 2024r. | I8: I-XII 2025r.* | J8: I-XII 2024r. | K8: I-XII 2025r.* | L8: I-XII 2024r. | M8: I-XII 2025r.*
B9: 0701 | C9: Ziemniaki, świeże lub chłodzone | D9: 46460.788 | E9: 47534.142 | F9: 119743.26 | G9: 160663.39 | H9: 63341.138 | I9: 68038.956 | J9: 157064.05 | K9: 179710.18 | L9: -16880.35 | M9: -20504.814
B10: 0702 | C10: Pomidory świeże lub chłodzone | D10: 118770.49 | E10: 127718.81 | F10: 78265.073 | G10: 80423.129 | H10: 420922.98 | I10: 440881.68 | J10: 246260.81 | K10: 237223.77 | L10: -302152.49 | M10: -313162.87
B11: 0703 | C11: Cebula, szalotka, czosnek, pory oraz inne warzywa | D11: 129088.63 | E11: 114533.35 | F11: 170182.02 | G11: 161761.06 | H11: 102974.43 | I11: 90718.876 | J11: 228146.95 | K11: 178305.02 | L11: 26114.198 | M11: 23814.477
B12: 0704 | C12: Kapusta, kalafiory, kalarepa, kapusta włoska, | D12: 78418.27 | E12: 72408.866 | F12: 103773.7 | G12: 93572.299 | H12: 91457.973 | I12: 96192.435 | J12: 85863.155 | K12: 87124.957 | L12: -13039.703 | M12: -23783.569
B13: 0705 | C13: Sałata (Lactuca sativa) i cykoria (Cichorium spp.), | D13: 32269.805 | E13: 32275.545 | F13: 26063.481 | G13: 24667.471 | H13: 97087.925 | I13: 103169.86 | J13: 73073.851 | K13: 79840.871 | L13: -64818.12 | M13: -70894.314
B14: 0706 | C14: Marchew, rzepa, buraki sałatkowe, salsefia, selery, | D14: 42404.232 | E14: 40859.998 | F14: 64597.357 | G14: 83701.753 | H14: 78545.05 | I14: 77346.817 | J14: 96386.332 | K14: 108823.43 | L14: -36140.818 | M14: -36486.819
B15: 0707 | C15: Ogórki i korniszony świeże | D15: 25426.211 | E15: 28415.476 | F15: 19346.303 | G15: 20608.521 | H15: 121899.39 | I15: 141998.66 | J15: 106985.88 | K15: 109228.17 | L15: -96473.177 | M15: -113583.19
B16: 0708 | C16: Warzywa strączkowe, nawet łuskane, świeże | D16: 15052.011 | E16: 13872.72 | F16: 27324.965 | G16: 32373.875 | H16: 4006.423 | I16: 4059.883 | J16: 4157.331 | K16: 3804.698 | L16: 11045.588 | M16: 9812.837
B17: 0709 | C17: Inne warzywa świeże lub chłodzone | D17: 681523.48 | E17: 670939.82 | F17: 323321.09 | G17: 310841.7 | H17: 345498.76 | I17: 384711.16 | J17: 168142.9 | K17: 182179.82 | L17: 336024.72 | M17: 286228.66
B18: 0710 | C18: Warzywa niegotowane lub gotowane na parze, zamrożone | D18: 432572.37 | E18: 415272.98 | F18: 407308.91 | G18: 396677.51 | H18: 78589.331 | I18: 92194.668 | J18: 68252.737 | K18: 78001.767 | L18: 353983.04 | M18: 323078.31
B19: 0711 | C19: Warzywa zakonserwowane tymczasowo | D19: 16368.888 | E19: 16323.561 | F19: 8776.655 | G19: 8581.733 | H19: 36676.991 | I19: 42908.572 | J19: 18377.683 | K19: 23606.869 | L19: -20308.103 | M19: -26585.011
B20: 0712 | C20: Warzywa suszone, całe, cięte w kawałki | D20: 110353.24 | E20: 110838.96 | F20: 45331.324 | G20: 33558.361 | H20: 71873.124 | I20: 66246.777 | J20: 22262.13 | K20: 21623.151 | L20: 38480.121 | M20: 44592.179
... B32: 0810 | C32: Pozostałe owoce, świeże | D32: 292567.88 | E32: 281130.08 | F32: 70540.003 | G32: 65970.394 | H32: 423150.1 | I32: 516564.96 | J32: 109894.76 | K32: 124926.08 | L32: -130582.21 | M32: -235434.88

Sheet HANDEL ZAGRANICZNY_I _V_2026
D5: EKSPORT/WYWÓZ | H5: IMPORT/PRZYWÓZ | L5: SALDO
B6: CN | C6: Nazwa towaru | D6: Wartość [tys. EUR] | F6: Wolumen [tony] | H6: Wartość [tys. EUR] | J6: Wolumen [tony] | L6: Wartość [tys. EUR]
D7: I-V 2025r.* | E7: I-V 2026r.* | F7: I-V 2025r.* | G7: I-V 2026r.* | H7: I-V 2025r.* | I7: I-V 2026r.* | J7: I-V 2025r.* | K7: I-V 2026r.* | L7: I-V 2025r.* | M7: I-V 2026r.*
B8: 0701 | C8: Ziemniaki, świeże lub chłodzone | D8: 29466.344 | E8: 10021.329 | F8: 87310.648 | G8: 41806.624 | H8: 52155.928 | I8: 25657.319 | J8: 125244.39 | K8: 62393.499 | L8: -22689.584 | M8: -15635.99
B9: 0702 | C9: Pomidory świeże lub chłodzone | D9: 54172.437 | E9: 54434.862 | F9: 25256.618 | G9: 25876.714 | H9: 248174.37 | I9: 286410.96 | J9: 127578.55 | K9: 119409.11 | L9: -194001.93 | M9: -231976.1
B10: 0703 | C10: Cebula, szalotka, czosnek, pory oraz inne warzywa | D10: 50280.282 | E10: 46711.958 | F10: 70977.051 | G10: 75666.96 | H10: 50831.952 | I10: 34821.055 | J10: 96648.628 | K10: 74014.677 | L10: -551.67 | M10: 11890.903
B11: 0704 | C11: Kapusta, kalafiory, kalarepa, kapusta włoska, | D11: 33380.098 | E11: 21127.97 | F11: 42994.561 | G11: 29323.576 | H11: 75518.599 | I11: 73257.069 | J11: 68832.151 | K11: 62068.067 | L11: -42138.501 | M11: -52129.099
B12: 0705 | C12: Sałata (Lactuca sativa) i cykoria (Cichorium spp.), | D12: 13908.677 | E12: 12227.786 | F12: 8838.279 | G12: 7876.627 | H12: 68645.638 | I12: 60731.346 | J12: 53788.028 | K12: 44396.278 | L12: -54736.961 | M12: -48503.56
B13: 0706 | C13: Marchew, rzepa, buraki sałatkowe, salsefia, selery, | D13: 22850.568 | E13: 16217.269 | F13: 49658.085 | G13: 35406.46 | H13: 52633.419 | I13: 41688.325 | J13: 77106.396 | K13: 42914.338 | L13: -29782.851 | M13: -25471.056
B14: 0707 | C14: Ogórki i korniszony świeże | D14: 11616.221 | E14: 11421.747 | F14: 7252.822 | G14: 7041.688 | H14: 66825.16 | I14: 76101.921 | J14: 42173.86 | K14: 41664.05 | L14: -55208.939 | M14: -64680.174
B15: 0708 | C15: Warzywa strączkowe, nawet łuskane, świeże | D15: 5071.517 | E15: 3963.699 | F15: 9769.131 | G15: 7596.174 | H15: 2507.939 | I15: 3828.318 | J15: 1726.969 | K15: 2751.749 | L15: 2563.578 | M15: 135.381
B16: 0709 | C16: Inne warzywa świeże lub chłodzone | D16: 271963.47 | E16: 264597.08 | F16: 122570.93 | G16: 115484.46 | H16: 237680.3 | I16: 246464.8 | J16: 110127.7 | K16: 100536.74 | L16: 34283.179 | M16: 18132.274
B17: 0710 | C17: Warzywa niegotowane lub gotowane na parze, zamrożone | D17: 175573.64 | E17: 170227.42 | F17: 164911.17 | G17: 172530.9 | H17: 42305.149 | I17: 43031.463 | J17: 36803.703 | K17: 36465.187 | L17: 133268.49 | M17: 127195.96
B18: 0711 | C18: Warzywa zakonserwowane tymczasowo | D18: 6931.896 | E18: 7128.884 | F18: 3570.839 | G18: 3797.982 | H18: 17518.291 | I18: 19763.294 | J18: 9277.459 | K18: 11709.96 | L18: -10586.395 | M18: -12634.41
B19: 0712 | C19: Warzywa suszone, całe, cięte w kawałki | D19: 51641.147 | E19: 45242.191 | F19: 15187.341 | G19: 11961.38 | H19: 29855.102 | I19: 29608.797 | J19: 9316.748 | K19: 9850.814 | L19: 21786.045 | M19: 15633.394
... B31: 0810 | C31: Pozostałe owoce, świeże | D31: 45365.05 | E31: 43965.759 | F31: 18339.172 | G31: 18428.91 | H31: 287691.73 | I31: 336765.61 | J31: 70564.741 | K31: 84406.978 | L31: -242326.68 | M31: -292799.85

Sheet EXP KRAJE I-V 2026
B2: HANDEL ZAGRANICZNY - DANE WSTĘPNE
B4: Źródło danych: Ministerstwo Finansów | Q4: =POMOC!B5
B5: UWAGA! DANE W TRAKCIE WERYFIKACJI - MOGĄ BYĆ OBARCZONE ISTOTNYMI BŁĘDAMI
B6: Eksport jabłek (CN 080810) wg. ważniejszych krajów | K6: Eksport pomidorów (CN 070200) wg. ważniejszych krajów
B7: według ważniejszych krajów | K7: według ważniejszych krajów
B8: I-V 2025r.* | F8: I-V 2026r.* | K8: I-V 2025r.* | O8: I-V 2026r.*
B9: Kraj | C9: Wartość [tys. EUR] | D9: Wolumen [tony] | F9: Kraj | G9: Wartość [tys. EUR] | H9: Wolumen [tony] | K9: Kraj | L9: Wartość [tys. EUR] | M9: Wolumen [tony] | O9: Kraj | P9: Wartość [tys. EUR] | Q9: Wolumen [tony]
B10: OGÓŁEM | C10: 244814.33 | D10: 359199.88 | F10: OGÓŁEM | G10: 246472.02 | H10: 400356.33 | K10: OGÓŁEM | L10: 54172.437 | M10: 25256.618 | O10: OGÓŁEM | P10: 54434.862 | Q10: 25876.714
B11: Niemcy | C11: 22710.475 | D11: 35731.932 | F11: Egipt | G11: 24534.341 | H11: 36870.121 | K11: Niemcy | L11: 22455.432 | M11: 8579.858 | O11: Holandia | P11: 23026.353 | Q11: 7477.029
B12: Rumunia | C12: 21198.708 | D12: 29473.751 | F12: Rumunia | G12: 20259.227 | H12: 33694.686 | K12: Holandia | L12: 16175.863 | M12: 6677.998 | O12: Ukraina | P12: 16990.289 | Q12: 11645.287
B13: Republika Czeska | C13: 17082.681 | D13: 23115.742 | F13: Kazachstan | G13: 18900.554 | H13: 41931.272 | K13: Ukraina | L13: 5901.582 | M13: 4531.773 | O13: Niemcy | P13: 6296.322 | Q13: 2851.083
B14: Egipt | C14: 16762.43 | D14: 22478.775 | F14: Białoruś | G14: 17311.911 | H14: 32159.682 | K14: Wielka Brytania | L14: 2300.452 | M14: 920.195 | O14: Wielka Brytania | P14: 1965.7 | Q14: 760.14
B15: Kazachstan | C15: 14577.316 | D15: 29840.358 | F15: India | G15: 15046.658 | H15: 20511.928 | K15: Szwecja | L15: 1647.107 | M15: 780.869 | O15: Bułgaria | P15: 1552.041 | Q15: 814.673
B16: Holandia | C16: 13697.71 | D16: 26257.68 | F16: Węgry | G16: 11888.821 | H16: 18782.37 | K16: Republika Czeska | L16: 1433.075 | M16: 633.132 | O16: Szwecja | P16: 1121.56 | Q16: 505.639
B17: Białoruś | C17: 12224.97 | D17: 20680.627 | F17: Litwa | G17: 10986.784 | H17: 18366.369 | K17: Białoruś | L17: 915.885 | M17: 641.433 | O17: Białoruś | P17: 983.291 | Q17: 648.023
B18: Węgry | C18: 10360.475 | D18: 15105.159 | F18: Republika Czeska | G18: 9394.785 | H18: 14922.528 | K18: Bułgaria | L18: 706.462 | M18: 549.864 | O18: Republika Czeska | P18: 797.47 | Q18: 406.893
B19: Szwecja | C19: 10026.055 | D19: 12470.226 | F19: Szwecja | G19: 8658.207 | H19: 12002.964 | K19: Litwa | L19: 441.945 | M19: 292.3 | O19: Łotwa | P19: 422.919 | Q19: 166.565
B20: India | C20: 8389.594 | D20: 10963.288 | F20: Niemcy | G20: 8424.746 | H20: 14314.494 | K20: Węgry | L20: 422.235 | M20: 238.173 | O20: Litwa | P20: 386.957 | Q20: 183.061
B21: Wielka Brytania | C21: 7887.829 | D21: 9654.103 | F21: Hiszpania | G21: 7223.279 | H21: 9940.49 | K21: Łotwa | L21: 394.682 | M21: 214 | O21: Słowacja | P21: 182.154 | Q21: 76.211
... B26: Łotwa | C26: 4968.695 | D26: 7223.491 | F26: Wielka Brytania | G26: 5232.062 | H26: 6291.852 | K26: Słowacja | L26: 120.969 | M26: 70.298 | O26: Węgry | P26: 66.605 | Q26: 26.455
B30: Eksport grzybów agaricus (CN 70095100) wg. ważniejszych krajów | K30: Eksport cebuli i szalotki (CN 070310) wg. ważniejszych krajów
B31: według ważniejszych krajów | K31: według ważniejszych krajów
B32: I-IV 2025r.* | F32: I-IV 2026r.* | K32: I-IV 2025r.* | O32: I-IV 2026r.*
B33: Kraj | C33: Wartość [tys. EUR] | D33: Wolumen [tony] | F33: Kraj | G33: Wartość [tys. EUR] | H33: Wolumen [tony] | K33: Kraj | L33: Wartość [tys. EUR] | M33: Wolumen [tony] | O33: Kraj | P33: Wartość [tys. EUR] | Q33: Wolumen [tony]
B34: OGÓŁEM | C34: 196843.82 | D34: 85744.637 | F34: OGÓŁEM | G34: 190546.14 | H34: 81680.519 | K34: OGÓŁEM | L34: 39674.431 | M34: 59395.803 | O34: OGÓŁEM | P34: 38777.673 | Q34: 64072.976
B35: Niemcy | C35: 55409.377 | D35: 22660.764 | F35: Niemcy | G35: 56375.955 | H35: 21953.82 | K35: Holandia | L35: 11007.226 | M35: 16551.743 | O35: Holandia | P35: 11233.004 | Q35: 18783.72
B36: Wielka Brytania | C36: 37422.31 | D36: 15979.846 | F36: Wielka Brytania | G36: 34072.243 | H36: 14894.218 | K36: Wielka Brytania | L36: 9075.19 | M36: 10477.814 | O36: Wielka Brytania | P36: 7221.698 | Q36: 8793.715
B37: Francja | C37: 29016.448 | D37: 11777.669 | F37: Francja | G37: 30864.553 | H37: 12027.222 | K37: Niemcy | L37: 4200.232 | M37: 6423.265 | O37: Niemcy | P37: 4467.267 | Q37: 7158.792
B38: Włochy | C38: 11825.855 | D38: 7948.714 | F38: Grecja | G38: 10043.785 | H38: 4873.164 | K38: Francja | L38: 3466.81 | M38: 5244.423 | O38: Francja | P38: 4315.418 | Q38: 5977.797
B39: Grecja | C39: 10952.092 | D39: 5031.481 | F39: Szwecja | G39: 8546.398 | H39: 3080.195 | K39: Ukraina | L39: 2475.336 | M39: 2171.948 | O39: Belgia | P39: 3713.198 | Q39: 7929.002
B40: Szwecja | C40: 7614.626 | D40: 2748.295 | F40: Włochy | G40: 8439 | H40: 5865.809 | K40: Belgia | L40: 2461.102 | M40: 5303.44 | O40: Ukraina | P40: 1623.882 | Q40: 1578.372
B41: Dania | C41: 5839.683 | D41: 1920.819 | F41: Dania | G41: 5695.022 | H41: 1852.196 | K41: Włochy | L41: 1439.875 | M41: 1763.513 | O41: Włochy | P41: 1255.505 | Q41: 1719.218
B42: Austria | C42: 5033.714 | D42: 1896.141 | F42: Bułgaria | G42: 5445.693 | H42: 3318.401 | K42: Republika Czeska | L42: 1218.371 | M42: 2718.237 | O42: Rumunia | P42: 842.52 | Q42: 2420.761
B43: Rumunia | C43: 5003.524 | D43: 2430.614 | F43: Holandia | G43: 3744.104 | H43: 1623.548 | K43: Rumunia | L43: 967.318 | M43: 2410.951 | O43: Hiszpania | P43: 769.774 | Q43: 1845.742
B44: Bułgaria | C44: 4904.753 | D44: 2595.652 | F44: Norwegia | G44: 3696.212 | H44: 1347.834 | K44: Słowacja | L44: 944.59 | M44: 1892.105 | O44: Słowacja | P44: 677.458 | Q44: 1696.502
B45: Holandia | C45: 4141.148 | D45: 1770.236 | F45: Belgia | G45: 3640.057 | H45: 1477.654 | K45: Szwecja | L45: 420.166 | M45: 272.095 | O45: Republika Czeska | P45: 582.208 | Q45: 1421.71
... B50: Węgry | C50: 1973 | D50: 1051.314 | F50: Słowacja | G50: 1825.163 | H50: 1063.528 | K50: Łotwa | L50: 179.85 | M50: 397.628 | O50: Mołdowa | P50: 149.121 | Q50: 152

Sheet IMP KRAJE I-V 2025
B2: HANDEL ZAGRANICZNY I-XI 2025 - DANE WSTĘPNE
B4: Źródło danych: Ministerstwo Finansów | Q4: =POMOC!B5
B5: UWAGA! DANE W TRAKCIE WERYFIKACJI - MOGĄ BYĆ OBARCZONE ISTOTNYMI BŁĘDAMI
B6: Import bananów (CN 0803) wg. ważniejszych krajów | J6: Import pomidorów (CN 0702) wg. ważniejszych krajów
B7: według ważniejszych krajów | K7: według ważniejszych krajów
B8: I-V 2025r.* | F8: I-V 2026r.* | K8: I-V 2025r.* | O8: I-V 2026r.*
B9: Kraj | C9: Wartość [tys. EUR] | D9: Wolumen [tony] | F9: Kraj | G9: Wartość [tys. EUR] | H9: Wolumen [tony] | K9: Kraj | L9: Wartość [tys. EUR] | M9: Wolumen [tony] | O9: Kraj | P9: Wartość [tys. EUR] | Q9: Wolumen [tony]
B10: OGÓŁEM | C10: 164883.21 | D10: 219630.02 | F10: OGÓŁEM | G10: 169823.25 | H10: 234434.21 | K10: OGÓŁEM | L10: 248174.37 | M10: 127578.55 | O10: OGÓŁEM | P10: 286410.96 | Q10: 119409.11
B11: Ekwador | C11: 83760.821 | D11: 114217.32 | F11: Ekwador | G11: 83455.948 | H11: 116762.21 | K11: Holandia | L11: 88759.458 | M11: 50031.509 | O11: Holandia | P11: 94309.686 | Q11: 43562.05
B12: Kolumbia | C12: 38096.739 | D12: 44499.123 | F12: Kolumbia | G12: 39808.359 | H12: 52501.457 | K12: Hiszpania | L12: 45508.524 | M12: 23982.588 | O12: Hiszpania | P12: 83083.126 | Q12: 33904.12
B13: Gwatemala | C13: 20034.98 | D13: 28951.234 | F13: Gwatemala | G13: 25835.592 | H13: 38537.482 | K13: Niemcy | L13: 38086.946 | M13: 13804.135 | O13: Niemcy | P13: 43327.51 | Q13: 12894.128
B14: Kostaryka | C14: 16306.224 | D14: 22237.717 | F14: Kostaryka | G14: 13835.891 | H14: 18262.398 | K14: Maroko | L14: 33719.784 | M14: 16365.65 | O14: Maroko | P14: 26292.415 | Q14: 12040.58
B15: Panama | C15: 3592.329 | D15: 5514.272 | F15: Kamerun | G15: 2739.554 | H15: 3456.197 | K15: Turcja | L15: 21134.359 | M15: 15432.983 | O15: Turcja | P15: 17088.877 | Q15: 9826.157
B16: Dominikana | C16: 568.594 | D16: 1086.005 | F16: Panama | G16: 1375.489 | H16: 2164.817 | K16: Francja | L16: 6733.255 | M16: 2633.562 | O16: Włochy | P16: 10345.895 | Q16: 3024.44
B17: Hiszpania | C17: 512.02 | D17: 512.892 | F17: Hiszpania | G17: 494.489 | H17: 493.992 | K17: Włochy | L17: 5663.31 | M17: 1872.925 | O17: Belgia | P17: 5390.064 | Q17: 1273.07
B18: Włochy | C18: 404.457 | D18: 19.354 | F18: Włochy | G18: 434.398 | H18: 19.631 | K18: Belgia | L18: 2726.016 | M18: 589.585 | O18: Tunezja | P18: 2227.788 | Q18: 691.301
B19: Wybrzeże Kości Słoniowej | C19: 397.057 | D19: 605.047 | F19: Wybrzeże Kości Słoniowej | G19: 313.309 | H19: 391.196 | K19: Portugalia | L19: 1533.306 | M19: 695.755 | O19: Azerbejdżan | P19: 1165.803 | Q19: 804
B20: Francja | C20: 369.528 | D20: 979.893 | F20: Nikaragua | G20: 259.683 | H20: 366.013 | K20: Senegal | L20: 1368.462 | M20: 476.988 | O20: Macedonia | P20: 526.431 | Q20: 239.544
B21: Kamerun | C21: 266.598 | D21: 318.889 | F21: Francja | G21: 251.434 | H21: 192.188 | K21: Tunezja | L21: 1184.082 | M21: 685.056 | O21: Francja | P21: 514.9 | Q21: 191.073
... B25: Nikaragua | C25: 59.286 | D25: 172.642 | F25: Niemcy | G25: 101.201 | H25: 46.181 | K25: Węgry | L25: 125.531 | M25: 90.547 | O25: Egipt | P25: 257.366 | Q25: 88.425
B31: Import papryki czerwonej (CN 07096010) wg. ważniejszych krajów
B32: według ważniejszych krajów
B33: I-IV 2025r.* | F33: I-IV 2026r.*
B34: Kraj | C34: Wartość [tys. EUR] | D34: Wolumen [tony] | F34: Kraj | G34: Wartość [tys. EUR] | H34: Wolumen [tony]
B35: OGÓŁEM | C35: 98636.298 | D35: 40444.928 | F35: OGÓŁEM | G35: 100958.62 | H35: 37592.525
B36: Hiszpania | C36: 43451.57 | D36: 17525.422 | F36: Hiszpania | G36: 44300.478 | H36: 16201.947
B37: Niemcy | C37: 19235.48 | D37: 6165.693 | F37: Niemcy | G37: 21544.015 | H37: 6677.193
B38: Holandia | C38: 17042.7 | D38: 9076.773 | F38: Turcja | G38: 12885.179 | H38: 4688.726
B39: Turcja | C39: 10362.827 | D39: 4164.529 | F39: Holandia | G39: 9274.526 | H39: 4433.287
B40: Izrael | C40: 5810.946 | D40: 2193.865 | F40: Izrael | G40: 7089.863 | H40: 2761.914
B41: Maroko | C41: 1427.436 | D41: 656.511 | F41: Jordania | G41: 2172.823 | H41: 897.987
B42: Belgia | C42: 276.581 | D42: 134.053 | F42: Bułgaria | G42: 1291.802 | H42: 460.001
B43: Słowenia | C43: 194.882 | D43: 115.925 | F43: Maroko | G43: 1056.595 | H43: 765.643
B44: Iran | C44: 169.364 | D44: 115.59 | F44: Egipt | G44: 384.94 | H44: 185.02
B45: Szwecja | C45: 169.336 | D45: 64.511 | F45: Belgia | G45: 322.49 | H45: 129.034
B46: Grecja | C46: 120.818 | D46: 47.945 | F46: Iran | G46: 199.765 | H46: 219.09
... B51: Jordania | C51: 42.418 | D51: 20.59 | F51: Włochy | G51: 32.357 | H51: 14.353

Sheet EXP-IMP KRAJE
B2: HANDEL ZAGRANICZNY ARTYKUŁAMI Z RYNKU OWOCÓW
B3: W OKRESIE I - IV 2026 - DANE WSTĘPNE
B4: Źródło danych: Ministerstwo Finansów
B5: UWAGA! DANE W TRAKCIE WERYFIKACJI - MOGĄ BYĆ OBARCZONE ISTOTNYMI BŁĘDAMI
B7: Eksport jabłek z Polski (CN 080810)
B8: I-V 2025r.* | G8: I-V 2026r.*
B9: Kraj | C9: Wartość [tys. EUR] | D9: Wolumen [tony] | E9: Wolumen (t) | G9: Kraj | H9: Wartość [tys. EUR] | I9: Wolumen [tony] | J9: Wolumen (t)
B10: OGÓŁEM | C10: 244814.33 | D10: 359199.88 | E10: 121510.12 | G10: OGÓŁEM | H10: 246472.02 | I10: 400356.33 | J10: 120336.79
B11: Niemcy | C11: 22710.475 | D11: 35731.932 | E11: 10668.68 | G11: Egipt | H11: 24534.341 | I11: 36870.121 | J11: 11543.733
B12: Rumunia | C12: 21198.708 | D12: 29473.751 | E12: 11481.727 | G12: Rumunia | H12: 20259.227 | I12: 33694.686 | J12: 11611.22
B13: Republika Czeska | C13: 17082.681 | D13: 23115.742 | E13: 7050.959 | G13: Kazachstan | H13: 18900.554 | I13: 41931.272 | J13: 6158.882
B14: Egipt | C14: 16762.43 | D14: 22478.775 | E14: 6809.036 | G14: Białoruś | H14: 17311.911 | I14: 32159.682 | J14: 6963.219
B15: Kazachstan | C15: 14577.316 | D15: 29840.358 | E15: 6046.84 | G15: India | H15: 15046.658 | I15: 20511.928 | J15: 4852.63
B16: Holandia | C16: 13697.71 | D16: 26257.68 | E16: 6254.455 | G16: Węgry | H16: 11888.821 | I16: 18782.37 | J16: 5704.42
B17: Białoruś | C17: 12224.97 | D17: 20680.627 | E17: 7444.331 | G17: Litwa | H17: 10986.784 | I17: 18366.369 | J17: 5203.753
B18: Węgry | C18: 10360.475 | D18: 15105.159 | E18: 4380.392 | G18: Republika Czeska | H18: 9394.785 | I18: 14922.528 | J18: 9388.439
B19: Szwecja | C19: 10026.055 | D19: 12470.226 | E19: 9217.92 | G19: Szwecja | H19: 8658.207 | I19: 12002.964 | J19: 5278.734
B20: India | C20: 8389.594 | D20: 10963.288 | E20: 7895.188 | G20: Niemcy | H20: 8424.746 | I20: 14314.494 | J20: 5599.52
B21: Wielka Brytania | C21: 7887.829 | D21: 9654.103 | E21: 3627.163 | G21: Hiszpania | H21: 7223.279 | I21: 9940.49 | J21: 4048.644
... B26: Łotwa | C26: 4968.695 | D26: 7223.491 | E26: 5164.449 | G26: Wielka Brytania | H26: 5232.062 | I26: 6291.852 | J26: 1980.584

Sheet EXP-IMP KRAJE LATA
B2: HANDEL ZAGRANICZNY ARTYKUŁAMI Z RYNKU WIEPRZOWINY W OKRESIE I - XII 2025 - DANE WSTĘPNE
B4: Źródło danych: Ministerstwo Finansów
B7: Eksport jabłek z Polski (CN 080810)
B8: I - XII 2024 r. | G8: I - XII 2025 r. (dane wstępne)
