Workbook
Name \a: #N/A
Name \s: #REF!
Name \s: #REF!
Name \s: #REF!
Name \s: #REF!
Name \s: #REF!
Name _17_11_2011: #REF!
Name _17_11_2011: #REF!
Name _17_11_2011: #REF!
Name _17_11_2011: #REF!
Name _17_11_2011: #REF!
Name _7_11_2011: #REF!
Name _7_11_2011: #REF!
Name _7_11_2011: #REF!
Name _7_11_2011: #REF!
Name _7_11_2011: #REF!
Name _A: #REF!
Name _A: #REF!
Name _A: #REF!
Name _A: #REF!
Name a: #REF!
Name a: #REF!
Name a: #REF!
Name a: #REF!
Name aa: OFFSET(#REF!,0,0,COUNTA(#REF!),27)
Name aa: OFFSET(#REF!,0,0,COUNTA(#REF!),27)
Name aa: OFFSET(#REF!,0,0,COUNTA(#REF!),27)
Name aa: #REF!
Name aa: OFFSET(#REF!,0,0,COUNTA(#REF!),27)
Name aa: OFFSET(#REF!,0,0,COUNTA(#REF!),27)
Name aa: #REF!
Name aaa: #REF!
Name aaa: #REF!
Name aaa: #REF!
Name aaa: #REF!
Name aaaa: #REF!
Name aaaa: #REF!
Name aaaa: #REF!
Name aaaa: #REF!
Name aaas: #REF!
Name aaas: #REF!
Name aaas: #REF!
Name aaas: #REF!
Name aassss: #REF!
Name aassss: #REF!
Name aassss: #REF!
Name aassss: #REF!
Name AllPerc: #REF!,#REF!
Name AllPerc: #REF!,#REF!
Name AllPerc: #REF!,#REF!
Name AllPerc: #REF!,#REF!
Name AllPerc: #REF!,#REF!
Name AmisData: OFFSET(#REF!,0,0,COUNTA(#REF!),23)
Name AmisData: OFFSET(#REF!,0,0,COUNTA(#REF!),23)
Name AmisDataPig: OFFSET(#REF!,0,0,COUNTA(#REF!),20)
Name AmisDataPig: OFFSET(#REF!,0,0,COUNTA(#REF!),20)
Name AmisDataPig: OFFSET(#REF!,0,0,COUNTA(#REF!),20)
Name AmisDataPig: OFFSET(#REF!,0,0,COUNTA(#REF!),20)
Name AmisDataPig: OFFSET(#REF!,0,0,COUNTA(#REF!),20)
Name AmisDataPiglet: OFFSET(#REF!,0,0,COUNTA(#REF!),27)

Sheet INFO
B5: ZINTEGROWANY SYSTEM ROLNICZEJ INFORMACJI RYNKOWEJ
B10: Rynek
B11: owoców i warzyw
B14: NR 11/2026
M16: 19 marca 2026 r.
D19: zsrir.minrol.gov.pl

Sheet SPIS
B2: SPIS TREŚCI
C6: ZMIANY CEN HURTOWYCH
C7: CENY HURTOWE WARZYW
C8: CENY HURTOWE OWOCÓW
C9: CENY OWOCÓW ORGANIZACJI PRODUCENTÓW
C10: CENY OWOCÓW DO PRZETWORSTWA
C11: CENY WARZYW DO PRZETWORSTWA
C12: CENY DETALICZNE OWOCÓW
C13: CENY DETALICZNE WARZYW
C14: WYKRESY - OWOCE DETAL
C15: WYKRESY - WARZYWA DETAL
C16: IERGZ - CENY WARZYW
C17: IRGZ- CENY W ZAKŁADACH PRZETWÓRCZYCH I SPÓLDZIELNIACH
... C20: HANDEL ZAGRANICZNY

Sheet ZMIANY HURT
B2: ZMIANY ŚREDNICH CEN HURTOWYCH DLA WYBRANEGO ASORTYMENTU OWOCÓW I WARZYW
O4: =POMOC!B5 -> Notowania 09.03 - 18.03.2026 / Tydzień 10
D5: Cena zł/jedn | H5: Zmiany ceny (%)
B6: Produkt | C6: Jedn. | D6: 46100 | F6: 46093 | H6: w stosunku do poprzedniego notowania*) | J6: 2 tyg. | L6: 3 tyg. | N6: 4 tyg.
D7: Min | E7: Max | F7: Min | G7: Max | H7: Min | I7: Max | J7: Min | K7: Max | L7: Min | M7: Max | N7: Min | O7: Max
B8: 1 | C8: 2 | D8: 3 | E8: 4 | F8: 5 | G8: 6 | H8: 7 | I8: 8 | J8: 9 | K8: 10 | L8: 11 | M8: 12 | N8: 13 | O8: 14
B9: Warzywa krajowe
B10: Boczniaki | C10: kg | D10: 20.833333 | E10: 23.333333 | F10: 20.833333 | G10: 23.166667 | H10: 0 | I10: 0.71942446 | J10: 0 | K10: 0 | L10: 0 | M10: 0 | N10: 5.0420168 | O10: 2.9411765
B11: Buraki ćwikłowe | C11: kg | D11: 1.15 | E11: 1.76 | F11: 1.15 | G11: 1.68 | H11: 0 | I11: 4.7619048 | J11: -4.8275862 | K11: 1.5384615 | L11: 0 | M11: 0 | N11: 3.6036036 | O11: 4.7619048
B12: Cebula biała | C12: kg | D12: 1.156 | E12: 1.654 | F12: 1.136 | G12: 1.468 | H12: 1.7605634 | I12: 12.6703 | J12: -3.3983287 | K12: 5.1271186 | L12: 0 | M12: 0 | N12: -3.3444816 | O12: 3.7641154
B13: Kalafiory | C13: szt. | D13: 7.5 | E13: 9.034 | F13: 7.5 | G13: 8.8 | H13: 0 | I13: 2.6590909 | J13: 2.2727273 | K13: 4.2384615 | L13: 0 | M13: 0 | N13: 7.1428571 | O13: 2.2639801
B14: Kapusta biała | C14: kg | D14: 0.92 | E14: 1.39 | F14: 0.9 | G14: 1.33 | H14: 2.2222222 | I14: 4.5112782 | J14: -12.380952 | K14: -3.583815 | L14: 0 | M14: 0 | N14: 9.5238095 | O14: 25.225225
B15: Marchew | C15: kg | D15: 1.34 | E15: 1.88 | F15: 1.32 | G15: 1.84 | H15: 1.5151515 | I15: 2.173913 | J15: -1.9512195 | K15: -1.0526316 | L15: 0 | M15: 0 | N15: 6.3492063 | O15: 6.8181818
B16: Ogórki gruntowe | C16: kg | D16: 17.333333 | E16: 21.333333 | F16: 15.333333 | G16: 18 | H16: 13.043478 | I16: 18.518519 | J16: 8.3333333 | K16: 14.285714 | L16: 0 | M16: 0 | N16: -30.666667 | O16: -32.631579
B17: Ogórki szklarniowe | C17: kg | D17: 11.86125 | E17: 14.18 | F17: 8.9842857 | G17: 10.705714 | H17: 32.022182 | I17: 32.452629 | J17: 18.757648 | K17: 24.580242 | L17: 0 | M17: 0 | N17: -5.8911038 | O17: -3.4059946
B18: Pietruszka | C18: kg | D18: 3.76 | E18: 4.63 | F18: 3.86 | G18: 4.73 | H18: -2.5906736 | I18: -2.1141649 | J18: -3.1759657 | K18: -3.0366492 | L18: 0 | M18: 0 | N18: 10.588235 | O18: 9.4562648
B19: Pomidory | C19: kg | D19: 9.618 | E19: 12.7 | F19: 13.70875 | G19: 17.52125 | H19: -29.84043 | I19: -27.516587 | J19: -26.022498 | K19: -22.347906 | L19: 0 | M19: 0 | N19: 8.4573748 | O19: -8.8560356
B20: Pomidory malinowe | C20: kg | D20: 15.1875 | E20: 18.875 | F20: 19.083333 | G20: 23.361667 | H20: -20.414847 | I20: -19.205251 | J20: -15.232558 | K20: -15.478767 | L20: 0 | M20: 0 | N20: 3.997261 | O20: -6.0126976
B21: Pory | C21: szt. | D21: 2 | E21: 2.6666667 | F21: 2 | G21: 2.6666667 | H21: 0 | I21: 0 | J21: -11.111111 | K21: -11.111111 | L21: 0 | M21: 0 | N21: 2.5641026 | O21: 1.5873016
... B24: Ziemniaki | C24: kg | D24: 0.83 | E24: 1.246 | F24: 0.83 | G24: 1.246 | H24: 0 | I24: 0 | J24: -3.3009709 | K24: 0.61911171 | L24: 0 | M24: 0 | N24: 10.666667 | O24: 9.4903339
B25: Owoce krajowe
B26: Gruszki | C26: kg | D26: 5.5744444 | E26: 6.9444444 | F26: 5.63 | G26: 6.8888889 | H26: -0.98677719 | I26: 0.80645161 | J26: -0.75762071 | K26: -0.79365079 | L26: 0 | M26: 0 | N26: 7.4994643 | O26: 4.1666667
B27: Jabłka:
B28: Boskoop | C28: kg | D28: 2.5 | E28: 3 | F28: 2.5 | G28: 3 | H28: 0 | I28: 0 | J28: 0 | K28: 0 | L28: 0 | M28: 0 | N28: -16.666667 | O28: 0
B29: Cortland | C29: kg | D29: 2.9375 | E29: 4.15 | F29: 2.9375 | G29: 4.15 | H29: 0 | I29: 0 | J29: 0 | K29: 0 | L29: 0 | M29: 0 | N29: -2.0833333 | O29: -3.1128405
B30: Gala | C30: kg | D30: 2.79 | E30: 3.665 | F30: 2.665 | G30: 3.3525 | H30: 4.6904315 | I30: 9.3214019 | J30: 4.6904315 | K30: 9.3214019 | L30: 0 | M30: 0 | N30: 0 | O30: 11.398176
B31: Golden | C31: kg | D31: 2.9575 | E31: 3.52 | F31: 2.9575 | G31: 3.5825 | H31: 0 | I31: -1.7445918 | J31: 0 | K31: -1.7445918 | L31: 0 | M31: 0 | N31: -7.3851775 | O31: -0.18903592
B32: Jonagold | C32: kg | D32: 2.54 | E32: 3.04 | F32: 2.54 | G32: 3.04 | H32: 0 | I32: 0 | J32: 0 | K32: 0 | L32: 0 | M32: 0 | N32: 0 | O32: 0
B33: Jonagored | C33: kg | D33: 3.33 | E33: 4 | F33: 3.33 | G33: 4 | H33: 0 | I33: 0 | J33: 0 | K33: 0 | L33: 0 | M33: 0 | N33: 0 | O33: 0
B34: Ligol | C34: kg | D34: 2.482 | E34: 3.382 | F34: 2.482 | G34: 3.382 | H34: 0 | I34: 0 | J34: 0 | K34: 0 | L34: 0 | M34: 0 | N34: -4.6301633 | O34: 0.87994034
B35: Lobo | C35: kg | D35: 2.852 | E35: 3.786 | F35: 2.852 | G35: 3.786 | H35: 0 | I35: 0 | J35: 0 | K35: 0 | L35: 0 | M35: 0 | N35: 1.3143872 | O35: -0.23715415
B36: Szara Reneta | C36: kg | D36: 2.7766667 | E36: 3.7266667 | F36: 2.7766667 | G36: 3.7266667 | H36: 0 | I36: 0 | J36: -9.9216004 | K36: -7.8697981 | L36: 0 | M36: 0 | N36: 0 | O36: 0
B37: Szampion | C37: kg | D37: 2.416 | E37: 3.416 | F37: 2.416 | G37: 3.416 | H37: 0 | I37: 0 | J37: 0 | K37: 0 | L37: 0 | M37: 0 | N37: -13.816885 | O37: -3.1379962
B38: Warzywa importowane
B39: Czosnek | C39: kg | D39: 14 | E39: 15 | F39: 14 | G39: 15 | H39: 0 | I39: 0 | J39: 0 | K39: 0 | L39: 0 | M39: 0 | N39: 0 | O39: 0
B40: Kalafiory | C40: szt. | D40: 0 | E40: 0 | F40: 0 | G40: 0 | H40: 0 | I40: 2.6590909 | J40: 2.2727273 | K40: 4.2384615 | L40: 0 | M40: 0 | N40: 7.1428571 | O40: 2.2639801
B41: Kapusta młoda | C41: szt. | D41: 7.7133333 | E41: 8.8566667 | F41: 6.9166667 | G41: 8.8333333 | H41: 11.518072 | I41: 0.26415094 | J41: 3.7086835 | K41: -5.5288889 | L41: 0 | M41: 0
B42: Papryka czerwona | C42: kg | D42: 14.2 | E42: 19 | F42: 14.8 | G42: 20 | H42: -20 | I42: -8.3333333 | J42: -19.207921 | K42: -9.7435897 | L42: 0 | M42: 0 | N42: 1.4925373 | O42: -1.1235955
B43: Papryka zielona | C43: kg | D43: 14 | E43: 14 | F43: 14.2 | G43: 17 | H43: -5.2631579 | I43: -1.1764706 | J43: -6.4935065 | K43: 0 | L43: 0 | M43: 0 | N43: 10.769231 | O43: 7.6923077
B44: Papryka żółta | C44: kg | D44: 21.2 | E44: 21.2 | F44: 17.4 | G44: 22.4 | H44: -10.344828 | I44: -1.9607843 | J44: -12.359551 | K44: 0 | L44: 0 | M44: 0 | N44: 1.2987013 | O44: 2.0408163
...

Sheet HURT WARZ
B2: ŚREDNIE CENY WARZYW NA RYNKACH HURTOWYCH
N4: =POMOC!B5 -> Notowania 09.03 - 18.03.2026 / Tydzień 10
E5: Bronisze | G5: Kalisz | I5: Lublin | K5: Łódź | M5: Poznań
B6: Data notowania | E6: 46099 | G6: 46098 | I6: 46098 | K6: 46098 | M6: 46098
B7: Owoce | E7: Min | F7: Max | G7: Min | H7: Max | I7: Min | J7: Max | K7: Min | L7: Max | M7: Min | N7: Max
B8: KRAJOWE
B9: Buraki ćwikłowe | D9: kg | E9: 0.75 | F9: 1.5 | G9: 0.8 | H9: 1 | I9: 1.2 | J9: 1.5 | K9: 1 | L9: 1.6 | M9: 2 | N9: 2.8
B10: Cebula biała | D10: kg | E10: 0.65 | F10: 1 | G10: 0.8 | H10: 1 | I10: 1.5 | J10: 1.67 | K10: 0.93 | L10: 1.67 | M10: 1.8 | N10: 2
B11: Kapusta biała | D11: kg | E11: 0.6 | F11: 0.85 | G11: 0.5 | H11: 0.5 | I11: 1.2 | J11: 2.2 | K11: 0.5 | L11: 0.9 | M11: 1.7 | N11: 2.2
B12: Marchew | D12: kg | E12: 1.2 | F12: 1.6 | G12: 1 | H12: 1.4 | I12: 1.4 | J12: 2 | K12: 1 | L12: 1.8 | M12: 2 | N12: 2.4
B13: Ogórki gruntowe | D13: kg | E13: 15 | F13: 20 | G13: 14 | H13: 15 | M13: 17 | N13: 19
B14: Ogórki szklarniowe | D14: kg | E14: 7 | F14: 9 | G14: 6 | H14: 7 | M14: 11 | N14: 12
B15: Pietruszka | D15: kg | E15: 3 | F15: 3.65 | G15: 2.5 | H15: 3 | I15: 4.8 | J15: 6 | K15: 3 | L15: 5 | M15: 6 | N15: 6
B16: Pomidory | D16: kg | E16: 22 | F16: 25 | G16: 20 | H16: 20 | I16: 12 | J16: 14.5 | K16: 11.67 | L16: 16.67
B17: Pomidory malinowe | D17: kg | E17: 22 | F17: 30 | G17: 23.33 | H17: 26.67 | K17: 16.67 | L17: 26.67 | M17: 24.17 | N17: 25.83
B18: Pory | D18: szt. | G18: 2 | H18: 2 | K18: 1.5 | L18: 2.5 | M18: 2.5 | N18: 3.5
B19: Sałata | D19: szt. | E19: 5 | F19: 6.5 | G19: 3 | H19: 3 | I19: 3.5 | J19: 6 | M19: 3.33 | N19: 3.5
B20: Selery | D20: kg | E20: 1.6 | F20: 2 | G20: 1 | H20: 1 | I20: 2.6 | J20: 4 | K20: 2 | L20: 4 | M20: 4.4 | N20: 5
B21: Ziemniaki | D21: kg | E21: 0.55 | F21: 1.35 | G21: 1 | H21: 1 | I21: 1 | J21: 1.34 | K21: 0.47 | L21: 1.07 | M21: 1.13 | N21: 1.47
B22: Boczniaki | D22: kg | E22: 13.5 | F22: 20 | I22: 19 | J22: 19.5 | M22: 30 | N22: 30
B23: Pieczarki | D23: kg | E23: 9 | F23: 12 | G23: 10 | H23: 10 | I23: 11.67 | J23: 11.84 | K23: 6.67 | L23: 13.33 | M23: 11 | N23: 13
B24: IMPORTOWANE
B25: Czosnek | D25: kg | E25: 14 | F25: 16 | G25: 14 | H25: 14
B26: Kalafiory | D26: szt. | E26: 7 | F26: 9 | G26: 6 | H26: 8 | I26: 10 | J26: 11 | K26: 7 | L26: 8 | M26: 7.5 | N26: 8
B27: Kapusta młoda | D27: szt. | E27: 7 | F27: 10 | G27: 7 | H27: 9 | M27: 6.75 | N27: 7.5
B28: Ogórki szklarniowe | D28: kg | E28: 5 | F28: 6.5 | I28: 14 | J28: 16 | K28: 7 | L28: 10 | M28: 12.89 | N28: 14.44
B29: Papryka czerwona | D29: kg | E29: 16 | F29: 19 | G29: 14 | H29: 14 | I29: 17 | J29: 21 | K29: 20 | L29: 22 | M29: 18 | N29: 20
B30: Papryka zielona | D30: kg | E30: 15 | F30: 18 | G30: 12 | H30: 14 | I30: 17 | J30: 20 | K30: 18 | L30: 18 | M30: 14 | N30: 15
B31: Papryka żółta | D31: kg | E31: 16 | F31: 19 | G31: 14 | H31: 16 | I31: 19 | J31: 26 | K31: 20 | L31: 22 | M31: 18 | N31: 19
B32: Pomidory | D32: kg | E32: 13 | F32: 26 | G32: 6.67 | H32: 10 | K32: 11 | L32: 13 | M32: 13.33 | N32: 15
B33: Pomidory malinowe | D33: kg | G33: 13.33 | H33: 15 | K33: 15 | L33: 16
B34: Rzodkiewka | D34: pęczek | E34: 2.5 | F34: 3 | G34: 1.8 | H34: 2 | I34: 2.5 | J34: 2.6 | K34: 2 | L34: 2.5 | M34: 2.4 | N34: 2.75
B35: Sałata | D35: szt. | E35: 3.5 | F35: 5.5 | G35: 2.5 | H35: 2.81 | K35: 3 | L35: 5 | M35: 3.5 | N35: 3.88
B36: Ziemniaki młode | D36: kg | E36: 2.2 | F36: 4.5 | M36: 3.33 | N36: 3.67

Sheet HURT OWOC
B2: ŚREDNIE CENY OWOCÓW NA RYNKACH HURTOWYCH
N4: =POMOC!B5 -> Notowania 09.03 - 18.03.2026 / Tydzień 10
B5: Miejscowość | D5: Miejscowość | G5: Bronisze | I5: Kalisz | K5: Lublin | M5: Łódź | O5: Poznań
B6: Data notowania | D6: Data notowania | G6: 46099 | I6: 46098 | K6: 46098 | M6: 46098 | O6: 46098
B7: Owoce | D7: Owoce | F7: Jedn. | G7: Min | H7: Max | I7: Min | J7: Max | K7: Min | L7: Max | M7: Min | N7: Max | O7: Min | P7: Max
B8: KRAJOWE | D8: KRAJOWE
B9: Gruszki | D9: Gruszki | F9: kg | G9: 4.5 | H9: 6.5 | I9: 4 | J9: 4 | K9: 5 | L9: 7 | M9: 4 | N9: 5.5 | O9: 6 | P9: 6.5
B10: Jabłka | D10: Jabłka
C11: Boskoop | E11: Boskoop | F11: kg | K11: 2 | L11: 3 | O11: 3 | P11: 3
C12: Cortland | E12: Cortland | F12: kg | G12: 3 | H12: 5 | I12: 3.08 | J12: 3.85 | K12: 3 | L12: 3.75 | M12: 2.67 | N12: 4
C13: Gala | E13: Gala | F13: kg | G13: 2.5 | H13: 3.75 | I13: 3.08 | J13: 3.08 | K13: 2 | L13: 3.5
C14: Golden | E14: Golden | F14: kg | G14: 2.75 | H14: 3.75 | I14: 3.08 | J14: 3.08 | K14: 2 | L14: 3.5 | O14: 4 | P14: 4
C15: Jonagold | E15: Jonagold | F15: kg | G15: 2 | H15: 3 | I15: 3.08 | J15: 3.08
C16: Jonagored | E16: Jonagored | F16: kg | O16: 3.33 | P16: 4
C17: Ligol | E17: Ligol | F17: kg | G17: 2 | H17: 3 | I17: 3.08 | J17: 3.08 | K17: 2 | L17: 3.5 | M17: 2 | N17: 3.33 | O17: 3.33 | P17: 4
C18: Lobo | E18: Lobo | F18: kg | G18: 2.85 | H18: 4 | I18: 3.08 | J18: 3.85 | K18: 3 | L18: 3.75 | M18: 2 | N18: 3.33 | O18: 3.33 | P18: 4
C19: Szampion | E19: Szampion | F19: kg | G19: 2 | H19: 3.5 | I19: 3.08 | J19: 3.08 | K19: 2 | L19: 3.5 | M19: 1.67 | N19: 3 | O19: 3.33 | P19: 4
C20: Szara Reneta | E20: Szara Reneta | F20: kg | G20: 3.25 | H20: 4 | I20: 3.08 | J20: 3.85 | M20: 2 | N20: 3.33
B21: IMPORTOWANE | D21: IMPORTOWANE
B22: Ananasy | D22: Ananasy | F22: szt. | G22: 6 | H22: 9 | I22: 5 | J22: 15 | K22: 7 | L22: 10 | M22: 5 | N22: 17
B23: Banany | D23: Arbuzy | F23: kg | G23: 6 | H23: 8 | I23: 8 | J23: 10
B24: Borówki amerykańskie | D24: Banany | F24: kg | G24: 4.2 | H24: 6.15 | I24: 4.44 | J24: 4.44 | K24: 4.8 | L24: 6.5 | M24: 5.28 | N24: 6.11 | O24: 5 | P24: 6.94
B25: Cytryny | D25: Borówki amerykańskie | F25: kg | G25: 45 | H25: 75 | I25: 48 | J25: 80 | M25: 40 | N25: 50 | O25: 68 | P25: 72
B26: Grejpfruty | D26: Cytryny | F26: kg | G26: 7 | H26: 11 | I26: 6.5 | J26: 7.5 | K26: 7 | L26: 10 | M26: 8 | N26: 9 | O26: 8.5 | P26: 9.5
B27: Gruszki | D27: Grejpfruty | F27: kg | G27: 5 | H27: 26 | I27: 5 | J27: 7 | K27: 7 | L27: 10.5 | M27: 7 | N27: 9 | O27: 7.14 | P27: 7.86
B28: Maliny | D28: Gruszki | F28: kg | G28: 6 | H28: 7 | I28: 6 | J28: 8 | M28: 6.67 | N28: 7.5 | O28: 8.5 | P28: 10
B29: Mandarynki | D29: Mandarynki | F29: kg | G29: 5 | H29: 15 | I29: 8 | J29: 8 | K29: 6.5 | L29: 10 | M29: 0.7 | N29: 0.8 | O29: 9 | P29: 14
B30: Nektarynki | D30: Nektarynki | F30: kg | K30: 16 | L30: 16
B31: Pomarańcze | D31: Pomarańcze | F31: kg | G31: 3 | H31: 15 | K31: 7 | L31: 10 | M31: 7 | N31: 9 | O31: 7.5 | P31: 9
B32: Śliwki | D32: Śliwki | F32: kg | K32: 14 | L32: 17 | O32: 11 | P32: 12
B33: Truskawki | D33: Truskawki | F33: kg | G33: 11 | H33: 14 | I33: 15 | J33: 16 | K33: 30 | L33: 36 | M33: 22 | N33: 24 | O33: 25 | P33: 26
B34: Winogrona | D34: Winogrona | F34: kg | G34: 16 | H34: 20 | I34: 10 | J34: 20 | K34: 20 | L34: 26 | M34: 22 | N34: 23 | O34: 19 | P34: 28

Sheet OWOCE ORGANIZACJE PROD.
B2: ŚREDNIE CENY ZAKUPU JABŁEK I GRUSZEK PŁACONE PRZEZ ORGANIZACJE PRODUCENTÓW - najważniejsze odmiany
B3: (zł/100 kg)
N4: =POMOC!B5 -> Notowania 09.03 - 18.03.2026 / Tydzień 10
B5: TOWAR | C5: 15.03.2026 | E5: 08.03.2026 | F5: 16.03.2025 | G5: Zmiana ceny (%) w stosunku do poprzedniego okresu | H5: Zmiana ceny (%) w stosunku do okresu sprzed roku
B6: Jabłka (razem) | C6: 148.17 | E6: 148.56 | F6: 179.69 | G6: -0.26 | H6: -17.54
B7: Boskoop | C7: --- | E7: nld | F7: --- | G7: * | H7: *
B8: Gala | C8: nld | E8: nld | F8: 197.61 | G8: * | H8: *
B9: Gloster | C9: nld | E9: nld | F9: nld | G9: * | H9: *
B10: Golden delicious | C10: 148.15 | E10: nld | F10: 166.02 | G10: * | H10: -10.76
B11: Idared | C11: 121.12 | E11: 121.58 | F11: 158.96 | G11: -0.38 | H11: -23.8
B12: Jonagold/Jonagored | C12: 130.22 | E12: nld | F12: 190.65 | G12: * | H12: -31.7
B13: Ligol | C13: nld | E13: nld | F13: 166.52 | G13: * | H13: *
B14: Szampion | C14: 124.56 | E14: 132.41 | F14: 170.34 | G14: -5.93 | H14: -26.88
B15: Gruszki (razem) | C15: nld | E15: nld | F15: nld | G15: * | H15: *
B17: ŚREDNIE CENY SPRZEDAŻY JABŁEK I GRUSZEK PŁACONE PRZEZ ORGANIZACJE PRODUCENTÓW - główne odmiany
B18: (zł/100 kg)
B20: TOWAR | C20: 15.03.2026 | E20: 08.03.2026 | F20: 16.03.2025 | G20: Zmiana ceny (%) w stosunku do poprzedniego okresu | H20: Zmiana ceny (%) w stosunku do okresu sprzed roku
B21: Jabłka (razem) | C21: 278.38 | E21: 280.65 | F21: 300.47 | G21: -0.81 | H21: -7.35
B22: Boskoop | C22: nld | E22: nld | F22: --- | G22: * | H22: *
B23: Gala | C23: 381.01 | E23: 335.34 | F23: 343.92 | G23: 13.62 | H23: 10.78
B24: Gloster | C24: nld | E24: --- | F24: nld | G24: * | H24: *
B25: Golden delicious | C25: 252.39 | E25: 246.75 | F25: 269.4 | G25: 2.29 | H25: -6.31
B26: Idared | C26: 216.41 | E26: nld | F26: 257.99 | G26: * | H26: -16.12
B27: Jonagold/Jonagored | C27: 264.43 | E27: 256.53 | F27: 294.04 | G27: 3.08 | H27: -10.07
B28: Ligol | C28: 286.91 | E28: 270.42 | F28: 326.57 | G28: 6.1 | H28: -12.14
B29: Szampion | C29: 242.72 | E29: 270.72 | F29: 299.5 | G29: -10.34 | H29: -18.96
B30: Gruszki (razem) | C30: 369.75 | E30: 494.54 | F30: nld | G30: -25.23 | H30: *
B32: Odmiany, dla których zbierane są dane:
B33: Boskoop, Cortland, Elstar, Gala, Gloster, Golden delicious, Idared, Jonagold/Jonagored, Ligol, Lobo, Red delicious, Shampion

Sheet OWOCE PRZETWÓRSTWO
B2: ŚREDNIE CENY ZAKUPU OWOCÓW PŁACONE PRZEZ PODMIOTY ZAJMUJĄCE SIĘ PRZETWÓRSTWEM
B3: (zł/100 kg)
L4: =POMOC!B5 -> Notowania 09.03 - 18.03.2026 / Tydzień 10
B5: TOWAR | C5: 46096 | D5: 46089 | E5: Zmiana ceny (%) w stosunku do okresu sprzed roku
B6: Jabłka /ogółem | C6: 67.6 | D6: 69 | E6: =(C6-D6)/D6*100 -> -2.0289855
B7: Jabłka / na sok zagęszczony | C7: 67.68 | D7: 68.12 | E7: =(C7-D7)/D7*100 -> -0.64591897
B8: Jabłka / na sok NFC | C8: 64.61 | D8: nld | E8: *

Sheet WARZYWA PRZETWÓRSTWO
B2: ŚREDNIE CENY ZAKUPU WARZYW PŁACONE PRZEZ PODMIOTY ZAJMUJĄCE SIĘ PRZETWÓRSTWEM
B3: (zł/100 kg)
J4: =POMOC!B5 -> Notowania 09.03 - 18.03.2026 / Tydzień 10
B5: TOWAR | C5: 46096 | D5: 46089 | E5: Zmiana ceny (%) w stosunku do poprzedniego okresu
B6: Buraki ćwikłowe | C6: 33.92 | D6: 30.69 | E6: =(C6-D6)/D6*100 -> 10.524601
B7: Cebula biała obierana | C7: 124.15 | D7: 125.58 | E7: =(C7-D7)/D7*100 -> -1.1387164
B8: Kapusta biała | C8: 61.09 | D8: 55 | E8: =(C8-D8)/D8*100 -> 11.072727
B9: Marchew | C9: 49.88 | D9: 44.73 | E9: =(C9-D9)/D9*100 -> 11.513526

Sheet ZAKUP OWOCE DETAL
B2: ŚREDNIE CENY ZAKUPU OWOCÓ PŁACONE PRZEZ PODMIOTY HANDLU DETALICZNEGO
B3: (zł/100 kg)
L4: =POMOC!B5 -> Notowania 09.03 - 18.03.2026 / Tydzień 10
B5: OWOCE krajowe - luzem
B6: TOWAR | C6: 15.03.2026 | D6: 08.03.2026 | E6: 16.03.2025 | F6: Zmiana ceny (%) w stosunku do poprzedniego okresu | G6: Zmiana ceny (%) w stosunku do okresu sprzed roku
B7: Jabłka (razem) | C7: 276.64 | D7: 283.68 | E7: 332.33 | F7: -2.48 | G7: -16.76
B8: Gala | C8: 344.68 | D8: 341.59 | E8: 365.41 | F8: 0.9 | G8: -5.67
B9: Golden delicious | C9: 317.19 | D9: 329.22 | E9: 334.91 | F9: -3.65 | G9: -5.29
B10: Idared | C10: 290.12 | D10: 304.78 | E10: 298.17 | F10: -4.81 | G10: -2.7
B11: Jonagold/Jonagored | C11: 258.05 | D11: 262.25 | E11: 314.59 | F11: -1.6 | G11: -17.97
B12: Ligol | C12: 302.44 | D12: 311.04 | E12: 340.75 | F12: -2.76 | G12: -11.24
B13: Szampion | C13: 282.06 | D13: 292.25 | E13: 324.29 | F13: -3.49 | G13: -13.02
B15: OWOCE z importu - luzem
B16: TOWAR | C16: 15.03.2026 | D16: 08.03.2026 | E16: 16.03.2025 | F16: Zmiana ceny (%) w stosunku do poprzedniego okresu | G16: Zmiana ceny (%) w stosunku do okresu sprzed roku
B17: Jabłka-Granny Smith | C17: nld | D17: nld | E17: nld | F17: * | G17: *
B18: Pomarańcze | C18: 403.49 | D18: 408.5 | E18: 390.77 | F18: -1.23 | G18: 3.26
B19: Brzoskwinie | C19: nld | D19: nld | E19: nld | F19: * | G19: *
B20: Nektaryny | C20: 948.62 | D20: 950.21 | E20: 820.57 | F20: -0.17 | G20: 15.61

Sheet ZAKUP WARZ DETAL
B2: ŚREDNIE CENY ZAKUPU WARZYW PŁACONE PRZEZ PODMIOTY HANDLU DETALICZNEGO
B3: (zł/100 kg)
L4: =POMOC!B5 -> Notowania 09.03 - 18.03.2026 / Tydzień 10
B5: WARZYWA krajowe - luzem
B6: TOWAR | C6: 15.03.2026 | D6: 08.03.2026 | E6: 16.03.2025 | F6: Zmiana % w stosunku do poprzedniego okresu | G6: Zmiana % w stosunku do okresu sprzed roku
B7: Marchew | C7: 219.35 | D7: 231.02 | E7: 255.15 | F7: -5.05 | G7: -14.03
B8: Ogórki szklarniowe | C8: 898.67 | D8: 1156.89 | E8: nld | F8: =(C8-D8)/D8*100 -> -22.320186 | G8: *
B9: Pomidory okrągłe | C9: 1758.23 | D9: 1605.27 | E9: 1542.89 | F9: 9.53 | G9: 13.96
B10: Ziemniaki | C10: 115.17 | D10: 110.83 | E10: 163.24 | F10: 3.92 | G10: -29.45
B12: WARZYWA z importu - luzem
B13: TOWAR | C13: 15.03.2026 | D13: 08.03.2026 | E13: 16.03.2025 | F13: Zmiana ceny (%) w stosunku do poprzedniego okresu | G13: Zmiana ceny (%) w stosunku do okresu sprzed roku
B14: Marchew | C14: nld | D14: nld | E14: nld | F14: * | G14: *
B15: Papryka czerwona | C15: 1325.06 | D15: 1390.58 | E15: nld | F15: =(C15-D15)/D15*100 -> -4.711703 | G15: *
B16: Pomidory okrągłe | C16: 872.38 | D16: 855.47 | E16: 897.42 | F16: 1.98 | G16: -2.79
B17: Pomidory na gałązkach | C17: 818.33 | D17: nld | E17: 731.7 | F17: * | G17: 11.84
B18: Pomidory typu "cherry" | C18: 1671.1 | D18: 1599.14 | E18: 1662.14 | F18: 4.5 | G18: 0.54
B19: Ziemniaki | C19: 457.28 | D19: 503.04 | E19: 472.14 | F19: -9.1 | G19: -3.15
B21: WARZYWA krajowe - opakowania do 2 kg
B22: TOWAR | C22: 15.03.2026 | D22: 08.03.2026 | E22: 16.03.2025 | F22: Zmiana ceny (%) w stosunku do poprzedniego okresu | G22: Zmiana ceny (%) w stosunku do okresu sprzed roku
B23: Marchew | C23: 310.94 | D23: 316.67 | E23: 367.21 | F23: -1.81 | G23: -15.32
B24: Pomidory okrągłe | C24: 1635 | D24: 1673.85 | E24: 1315 | F24: -2.32 | G24: 24.33
B25: Pomidory typu "cherry" | C25: 1428.7 | D25: 1550.53 | E25: 1329.46 | F25: -7.86 | G25: 7.46
B26: Ziemniaki | C26: 179.02 | D26: 177.76 | E26: 291.7 | F26: 0.71 | G26: -38.63
B28: WARZYWA z importu - do 2 kg
B29: TOWAR | C29: 15.03.2026 | D29: 08.03.2026 | E29: 16.03.2025 | F29: Zmiana ceny (%) w stosunku do poprzedniego okresu | G29: Zmiana ceny (%) w stosunku do okresu sprzed roku
B30: Marchew | C30: nld | D30: 530.32 | E30: nld | F30: * | G30: *
B31: Ogórki spod osłon | C31: 451.86 | D31: 646.78
B32: Pomidory okrągłe | C32: 953.91 | D32: 890.18 | E32: 898.6 | F32: 7.16 | G32: 6.16
B33: Pomidory na gałązkach | C33: 903.64 | D33: 869.72 | E33: 882.45 | F33: 3.9 | G33: 2.4
B34: Pomidory typu "cherry" | C34: 1922.06 | D34: 1617.87 | E34: 1965.18 | F34: 18.8 | G34: -2.19

Sheet DETAL OWOCE WYKRES 
B2: Średnie ceny zakupu jabłek (luzem) płacone przez podmioty handlu detalicznego
M4: =POMOC!B5 -> Notowania 09.03 - 18.03.2026 / Tydzień 10
B63: 46096 | C63: 46089
A64: Gala | B64: 3.4468 | C64: 3.4159
A65: Golden delicious | B65: 3.1719 | C65: 3.2922
A66: Idared | B66: 2.9012 | C66: 3.0478
A67: Jonagold/jonagored | B67: 2.5805 | C67: 2.625
A68: Ligol | B68: 3.0244 | C68: 3.11
A69: Szampion | B69: 2.8206 | C69: 2.9225

Sheet DETAL WARZ WYKRES
B2: Średnie ceny zakupu warzyw (luzem) płacone przez podmioty handlu detalicznego
M4: =POMOC!B5 -> Notowania 09.03 - 18.03.2026 / Tydzień 10
B60: 46096 | C60: 46089
A61: Marchew | B61: 2.01935 | C61: 2.3102
A62: Pomidory okrągłe | B62: 17.5823 | C62: 16.0527
A63: Ziemniaki | B63: 1.1517 | C63: 1.1083

Sheet IERGZ_warzywa
A5: Ogrodniczy Informator Cenowy | L5: Warszawa
L6: 16 III
L7: 2026 r.
B8: Instytut Ekonomiki Rolnictwa i Gospodarki Żywnościowej Państwowy Instytut Badawczy
B9: 00-950 Warszawa, ul.Świętokrzyska 20, P.O. Box 984
B10: tel. (22) 505 44 32, e-mail: Tomasz.Smolenski@ierigz.waw.pl
B11: Ceny skupu netto warzyw i owoców w spółdzielniach ogrodniczych zbierane 16 III 2026 r.
B12: Województwo | C12: Buraki ćwikłowe | D12: Cebula | E12: Kapusta biała | F12: Kapusta włoska | G12: Kapusta pekińska | H12: Kiszona kapusta | I12: Ogórki kiszone
B13: kujawsko-pomorskie | C13: 0,50-0,65 | D13: 0,54-0,67 | E13: 0,52-0,60 | F13: 1,75-2,00 | G13: 2,65-2,88 | I13: 6,55-7,80
B14: lubelskie | C14: 0,56-0,64 | D14: 0,51-0,63 | E14: 0,54-0,66 | F14: 1,84-2,25 | H14: 4,89-6,55
B15: lubelskie | C15: 0,55-0,60 | D15: 0,52-0,66 | E15: 0,51-0,63 | G15: 2,75-2,99 | I15: 6,75-7,45
B16: łódzkie | C16: 0,50-0,60 | D16: 0,55-0,67 | E16: 0,54-0,58 | F16: 1,87-1,98 | H16: 4,95-5,66
B17: łódzkie | C17: 0,55-0,61 | D17: 0,52-0,66 | H17: 5,25-5,66 | I17: 6,55-7,89
B18: małopol. | C18: 0,51-0,64 | D18: 0,63-0,67 | E18: 0,51-0,57 | F18: 1,86-1,91 | H18: 5,55-6,18 | I18: 6,65-7,88
B19: małopol. | C19: 0,54-0,66 | D19: 0,55-0,60 | H19: 5,25-6,77 | I19: 6,66-7,25
B20: małopol. | C20: 0,60-0,64 | D20: 0,51-0,63 | E20: 0,53-0,57 | H20: 5,23-6,13
B21: małopol. | C21: 0,50-0,63 | D21: 0,51-0,63 | F21: 1,88-1,93 | G21: 2,75-2,98 | I21: 6,65-7,45
B22: mazowiec. | C22: 0,54-0,62 | D22: 0,55-0,65 | E22: 0,53-0,58 | F22: 1,67-1,86 | G22: 2,65-2,88 | H22: 5,25-6,70
B23: podkarp. | C23: 0,54-0,62 | D23: 0,60-0,64 | H23: 6,15-7,10 | I23: 6,98-7,65
B24: podkarp. | I24: 6,45-7,13
B25: Cena średnia | C25: 0,50-0,66 | D25: 0,51-0,67 | E25: 0,51-0,66 | F25: 1,67-2,25 | G25: 2,65-2,99 | H25: 4,89-7,10 | I25: 6,45-7,89
B26: dwa tygodnie temu | C26: 0,50-0,70 | D26: 0,55-0,72 | E26: 0,52-0,70 | F26: 1,89-2,66 | G26: 2,75-2,87 | H26: 4,78-6,90 | I26: 6,25-8,66
B27: rok temu | C27: 0,65-0,84 | D27: 0,75-1,16 | E27: 0,65-0,98 | F27: 2,10-2,89 | G27: 2,89-3,79 | H27: 5,25-7,69 | I27: 6,88-7,90
B29: Województwo | C29: Marchew (myta) | D29: Pieczarki | E29: Pietruszka | F29: Pory | G29: Czosnek/a | H29: Rzodkiewka/b | I29: Selery
B30: kujawsko-pomorskie | C30: 0,65-0,74 | D30: 6,45-6,89 | E30: 2,10-2,55 | F30: 3,10-3,25 | G30: 0,92-1,17 | H30: 1,53-1,78 | I30: 0,85-0,95
B31: lubelskie | C31: 0,66-0,78 | D31: 6,89-7,98 | E31: 2,35-2,45 | F31: 2,89-3,10 | G31: 0,90-1,14 | I31: 0,75-0,88
B32: małopol. | C32: 0,66-0,72 | D32: 6,45-6,87 | E32: 2,37-2,66 | F32: 2,45-2,99 | H32: 1,54-1,74 | I32: 0,85-0,90
B33: małopol. | C33: 0,66-0,74 | D33: 6,55-7,66 | E33: 2,45-2,70 | F33: 2,78-3,15 | G33: 0,95-1,00 | I33: 0,88-0,92
B34: mazowiec. | C34: 0,55-0,68 | D34: 6,78-7,89 | E34: 2,25-2,38 | F34: 2,89-3,25 | G34: 0,87-0,96 | H34: 1,66-1,80 | I34: 0,84-0,95
B35: mazowiec. | C35: 0,62-0,69 | D35: 6,45-7,99 | E35: 2,25-2,45 | F35: 2,65-2,78 | G35: 0,89-1,12 | H35: 1,35-1,89 | I35: 0,75-0,83
B36: podkarp. | C36: 0,72-0,80 | D36: 6,35-7,15 | E36: 2,35-2,56 | F36: 2,68-2,87 | I36: 0,96-1,10
B37: podkarp. | C37: 0,55-0,69 | D37: 6,78-7,25 | E37: 2,15-2,45 | F37: 2,65-3,10 | G37: 0,88-0,96 | H37: 1,45-1,66 | I37: 0,75-0,84
B38: Cena średnia | C38: 0,55-0,80 | D38: 6,35-7,99 | E38: 2,10-2,70 | F38: 2,45-3,25 | G38: 0,87-1,17 | H38: 1,35-1,89 | I38: 0,75-1,10
B39: dwa tygodnie temu | C39: 0,55-0,78 | D39: 5,98-8,14 | E39: 1,65-2,78 | F39: 2,25-3,12 | G39: 0,85-1,14 | H39: 1,45-1,98 | I39: 0,55-0,92
B40: rok temu | C40: 0,68-0,88 | D40: 6,85-8,25 | E40: 1,74-2,88 | F40: 2,47-3,24 | G40: 0,80-1,10 | H40: 1,55-2,15 | I40: 0,75-1,17
B41: a/sztuka,b/peczek

Sheet IERGZ_Zaklady  
A5: Ogrodniczy Informator Cenowy
A8: Instytut Ekonomiki Rolnictwa i Gospodarki Żywnościowej - Państwowy Instytut Badawczy
A9: Zakład Ekonomiki Gospodarstw Rolnych i Ogrodniczych
A10: 00-950 Warszawa, ul.Świętokrzyska 20, P.O. Box 984
A11: Ceny skupu netto w zakładach przetwórczych i chłodniach zbierane 16 III 2026 r. (zł/kg)
K12: Jabłka | P12: Cebula | Q12: Buraki | AA12: Pory | AB12: Kapusta | AC12: Marchew | AD12: Jabłka
K13: przemysłowe | P13: obrana | Q13: ćwikłowe | AB13: biała | AC13: na plastry | AD13: przemyslowe
A14: kujawsko-pomor.
A15: kujawsko-pomor. | P15: 1,15lz-1,20lz
A16: kujawsko-pomor.
A17: kujawsko-pomor. | P17: 1,15lz-1,28lz | Q17: 0,50-0,55lz-0,60lz | AA17: 0,95-1,10lz | AB17: 0,55-0,60lz | AC17: 0,55-0,65lz
A18: lubelskie | K18: 0,32-0,36lz | AD18: 0,65lz-0,70lz
A19: lubelskie | Q19: 0,60lz-0,70lz
A20: lubelskie | P20: 1,10lz-1,23lz | AC20: 0,60lz/k | AD20: 0,60lz-1,10lz
A21: lubelskie | AA21: 1,10lz-1,25lz | AB21: 0,65lz | AD21: 0,70lz
A22: lubelskie
A23: lubuskie | AB23: 0,50lz
A24: łódzkie | AC24: 0,50-0,55-0,60lz-0,65lz | AD24: 0,60lz-0,70lz
A25: łódzkie | AA25: 0,95lz-1,10lz
A26: małopolskie | K26: 0,31-0,35lz | Q26: 0,55lz-0,65lz
A27: mazowieckie | AD27: 0,65lz-0,90lz-1,15lz-1,30lz
A28: mazowieckie | K28: 0,32-0,35lz
A29: podkarpackie
A30: podkarpackie
A31: podlaskie | K31: 0,36lz
A32: podlaskie
A33: śląskie
A34: świętokrzyskie | AB34: 0,55lz-0,60lz
A35: wielkopolskie | P35: 1,10lz-1,20
A36: wielkopolskie | P36: 1,10lz-1,20lz
A37: zachodnio-pomor.
A39: średnio | K39: 0,32-0,36lz | P39: 1,10lz-1,28lz | Q39: 0,50-0,60lz--0,70lz | AA39: 0,95-0,95lz-1,25lz | AB39: 0,55-0,55lz-0,65lz | AC39: 0,50-0,55-0,60lz-0,65lz | AD39: 0,60lz-0,70lz/na sok-0,90lz-1,30lz/do obierania
A41: tydzień temu | K41: 0,32-0,36lz | P41: 1,10lz-1,23lz | Q41: 0,50-0,50lz--0,60lz | AA41: 0,95-0,95lz-1,20lz | AB41: 0,55-0,55lz-0,60lz | AC41: 0,50-0,60-0,65lz | AD41: 0,60lz-0,70lz/na sok-0,90lz-1,25lz/do obierania
A43: rok temu | K43: 0,27-0,33lz | P43: 1,30lz-1,50lz | Q43: 0,60-0,60lz-0,65lz | AA43: 1,35-1,40lz-1,50lz | AB43: 0,70-0,70lz-0,80lz | AC43: 0,65-0,70-0,70lz-0,73lz | AD43: 1,00-1,00lz-1,25lzlz, 1,30lz-1,40lz/do obierania

Sheet IERGZ_owoce
B5: Województwo | C5: Jabłka deserowe | D5: Jabłka przemysłowe | E5: Gruszki
B6: kujawsko-pomorskie | C6: 1,75-2,50
B7: lubelskie | C7: 1,65-2,15 | D7: 0,65-0,75
B8: łódzkie | C8: 1,70-2,65 | E8: 3,45-3,65
B9: łódzkie | C9: 1,87-2,55 | D9: 0,60-0,70 | E9: 3,35-3,89
B10: łódzkie
B11: małopolskie | C11: 1,87-1,99 | E11: 3,38-3,78
B12: małopolskie | C12: 1,60-2,45 | D12: 0,60-0,75
B13: małopolskie | C13: 1,75-2,26 | D13: 0,65-0,68 | E13: 3,55-3,69
B14: małopolskie
B15: małopolskie | D15: 0,65-0,70
B16: mazowiec. | C16: 1,85-2,35 | E16: 3,20-3,48
B17: podkarp. | C17: 1,65-1,98 | D17: 0,65-0,70
B18: podkarp. | E18: 3,56-3,70
B19: Cena średnia | C19: 1,60-2,65 | D19: 0,60-0,75 | E19: 3,20-3,89
B20: dwa tygodnie temu | C20: 1,60-2,40 | D20: 0,55-0,75 | E20: 3,25-4,10
B21: rok temu | C21: 1,70-2,78 | D21: 0,75-1,10 | E21: 3,40-4,45
B22: s/"suchy" przemysł, */jabłka w kal. 65+ i do średniej nie wliczana jest odmiana Antonówka

Sheet ow_KRIR
C1: Tygodniowy Serwis Cenowy
B2: 11 tydzień | C2: dla producentów owoców i warzyw
B3: 09.03. - 15.03.2026 r | C3: Krajowa Rada Izb Rolniczych
C4: Parzniew ul. Przyszłości 5, 05-804 Pruszków
C5: tel. 881-939-421, www.krir.pl, sekretariat@krir.pl
B6: Serwis znajduje się obecnie w fazie rozwoju i dotyczy wybranych produktów w niektórych województwach.
B8: Województwo/Towar | C8: Mazowieckie | F8: Świętokrzyskie | I8: Wielkopolskie
C9: 09.03. - 15.03.2026r. cena w zł/kg (szt*) | D9: 02.03. - 08.03.2026r. cena w zł/kg (szt*) | E9: tygodniowa zmiana ceny w % | F9: 09.03. - 15.03.2026r. cena w zł/kg (szt*) | G9: 02.03. - 08.03.2026r. cena w zł/kg (szt*) | H9: tygodniowa zmiana ceny w % | I9: 09.03. - 15.03.2026r. cena w zł/kg (szt*) | J9: 02.03. - 08.03.2026r. cena w zł/kg (szt*) | K9: tygodniowa zmiana ceny w %
B10: Jabłka (op.5-20 kg) Golden delicious (70/80mm) | E10: -- | F10: 1.45 | G10: 1.45 | H10: =((F10-G10)/G10)*100 -> 0 | I10: -- | J10: -- | K10: --
B11: Jabłka (op.5-20 kg) Jonagold+Jonagored (70/80mm) | C11: 1.65 | D11: 2 | E11: =((C11-D11)/D11)*100 -> -17.5 | F11: -- | G11: -- | H11: -- | I11: -- | J11: -- | K11: --
B12: Jabłka (op.5-20 kg) Idared (70/80mm) | C12: 2 | D12: 2 | E12: =((C12-D12)/D12)*100 -> 0 | F12: 1.35 | G12: 1.25 | H12: =((F12-G12)/G12)*100 -> 8 | I12: -- | J12: -- | K12: --
B13: Jabłka (op.5-20 kg) Shampion (70/80mm) | C13: 2 | D13: 2 | E13: =((C13-D13)/D13)*100 -> 0 | F13: 1.45 | G13: 1.45 | H13: =((F13-G13)/G13)*100 -> 0 | I13: -- | J13: -- | K13: --
B14: Jabłka (op.5-20 kg) Boskoop (70/80mm) | C14: 2.65 | D14: 3 | E14: =((C14-D14)/D14)*100 -> -11.666667 | F14: 1.7 | G14: 1.9 | H14: =((F14-G14)/G14)*100 -> -10.526316 | I14: -- | J14: -- | K14: --
B15: Jabłka (op.5-20 kg) Gala (65/70mm) | C15: 2 | D15: 2 | E15: =((C15-D15)/D15)*100 -> 0 | F15: -- | G15: -- | H15: -- | I15: -- | J15: -- | K15: --
B16: Gruszki (op.5-20 kg) Lukasówka (65/70 mm) | C16: 5 | D16: 5 | E16: =((C16-D16)/D16)*100 -> 0 | F16: 4.6 | G16: 4.12 | H16: =((F16-G16)/G16)*100 -> 11.650485 | I16: -- | J16: -- | K16: --
B17: Cebula żółta 40-80 mm; op.5-25 kg | C17: -- | D17: -- | E17: -- | F17: -- | G17: -- | H17: -- | I17: -- | J17: -- | K17: --
B18: Cebula biała 40-80 mm op.5-25 kg | C18: 0.85 | D18: 0.86 | E18: =((C18-D18)/D18)*100 -> -1.1627907 | F18: 0.9 | G18: 0.9 | H18: =((F18-G18)/G18)*100 -> 0 | I18: 1 | J18: 0.86912492 | K18: =((I18-J18)/J18)*100 -> 15.058258
B19: Marchew wszystkie odmiany pakowane luzem | C19: 1.42 | D19: 1.43 | E19: =((C19-D19)/D19)*100 -> -0.6993007 | F19: 0.85 | G19: 0.95 | H19: =((F19-G19)/G19)*100 -> -10.526316 | I19: 1 | J19: 0.90835694 | K19: =((I19-J19)/J19)*100 -> 10.088883
B20: Pietruszka korzeń op. 10 kg | C20: -- | D20: -- | E20: -- | F20: 2.5 | G20: 2.5 | H20: =((F20-G20)/G20)*100 -> 0 | I20: 3 | J20: 2.4989583 | K20: =((I20-J20)/J20)*100 -> 20.05002
B21: Pomidory, typ okrągły; op. 5-6-kg | C21: -- | D21: -- | E21: -- | F21: 13.5 | G21: 12.5 | H21: =((F21-G21)/G21)*100 -> 8 | I21: -- | J21: -- | K21: --
B22: Ogórki, typ gładkie; op. 5-6 kg | C22: -- | D22: -- | E22: -- | F22: -- | G22: -- | H22: -- | I22: -- | J22: -- | K22: --
B23: Seler | C23: -- | D23: -- | E23: -- | F23: 1.8 | G23: 1.8 | H23: =((F23-G23)/G23)*100 -> 0 | I23: 1 | J23: 1.1584335 | K23: =((I23-J23)/J23)*100 -> -13.676533
B24: Sałata masłowa za główkę | C24: -- | D24: -- | E24: -- | F24: 3.5 | G24: 3.45 | H24: =((F24-G24)/G24)*100 -> 1.4492754 | I24: -- | J24: -- | K24: --
B25: Szparagi biało/fioletowe >16mm | C25: -- | D25: -- | E25: -- | F25: -- | G25: -- | H25: -- | I25: -- | J25: -- | K25: --
B26: Burak ćwikłowy op. 10-15 kg | C26: -- | D26: -- | E26: -- | F26: 0.85 | G26: 0.95 | H26: =((F26-G26)/G26)*100 -> -10.526316 | I26: 0.9 | J26: 0.9 | K26: =((I26-J26)/J26)*100 -> 0
B27: Kalafiory 12-20 cm | C27: -- | D27: -- | E27: -- | F27: -- | G27: -- | H27: -- | I27: -- | J27: -- | K27: --
B28: Kapusta biała zł/kg | C28: -- | D28: -- | E28: -- | F28: 0.66 | G28: 0.76 | H28: =((F28-G28)/G28)*100 -> -13.157895 | I28: 0.5 | J28: 0.5 | K28: =((I28-J28)/J28)*100 -> 0
B29: Rzodkiewka za pęczek 1 szt | C29: -- | D29: -- | E29: -- | F29: 2 | G29: 2.33 | H29: =((F29-G29)/G29)*100 -> -14.16309 | I29: -- | J29: -- | K29: --
B30: Ziemniaki (op. 15 kg) | C30: -- | D30: -- | E30: -- | F30: 0.45 | G30: 0.5 | H30: =((F30-G30)/G30)*100 -> -10 | I30: -- | J30: -- | K30: --
B31: Pieczarki 30-65 mm | C31: -- | D31: -- | E31: -- | F31: 11.15 | G31: 11.15 | H31: =((F31-G31)/G31)*100 -> 0 | I31: 8.8456371 | J31: 7.72 | K31: =((I31-J31)/J31)*100 -> 14.580792

Sheet HANDEL ZAGRANICZNY_I _XII_2024
D5: EKSPORT/WYWÓZ | H5: IMPORT/PRZYWÓZ | L5: SALDO
B6: CN | C6: Nazwa towaru | D6: Wartość [tys. EUR] | F6: Wolumen [tony] | H6: Wartość [tys. EUR] | J6: Wolumen [tony] | L6: Wartość [tys. EUR]
D7: 2023r. | E7: 2024r. | F7: 2023r. | G7: 2024r. | H7: 2023r. | I7: 2024r. | J7: 2023r. | K7: 2024r. | L7: 2023r. | M7: 2024r.
B8: 0701 | C8: Ziemniaki, świeże lub chłodzone | D8: 21187.311 | E8: 46460.788 | F8: 52251.573 | G8: 119743.26 | H8: 62246.119 | I8: 63341.138 | J8: 172501.84 | K8: 157064.05 | L8: -41058.808 | M8: -16880.35
B9: 0702 | C9: Pomidory świeże lub chłodzone | D9: 110072.83 | E9: 118770.49 | F9: 76305.925 | G9: 78265.073 | H9: 438201.84 | I9: 420922.98 | J9: 218513.94 | K9: 246260.81 | L9: -328129.01 | M9: -302152.49
B10: 0703 | C10: Cebula, szalotka, czosnek, pory oraz inne warzywa | D10: 144023.3 | E10: 129088.63 | F10: 166981.05 | G10: 170182.02 | H10: 122805.76 | I10: 102974.43 | J10: 223781.42 | K10: 228146.95 | L10: 21217.548 | M10: 26114.198
B11: 0704 | C11: Kapusta, kalafiory, kalarepa, kapusta włoska, | D11: 75806.63 | E11: 78418.27 | F11: 108009.17 | G11: 103773.7 | H11: 84785.892 | I11: 91457.973 | J11: 65273.557 | K11: 85863.155 | L11: -8979.262 | M11: -13039.703
B12: 0705 | C12: Sałata (Lactuca sativa) i cykoria (Cichorium spp.), | D12: 33284.881 | E12: 32269.805 | F12: 24277.699 | G12: 26063.481 | H12: 103530.88 | I12: 97087.925 | J12: 70095.583 | K12: 73073.851 | L12: -70246.003 | M12: -64818.12
B13: 0706 | C13: Marchew, rzepa, buraki sałatkowe, salsefia, selery, | D13: 40089.523 | E13: 42404.232 | F13: 71299.741 | G13: 64597.357 | H13: 75423.489 | I13: 78545.05 | J13: 93809.949 | K13: 96386.332 | L13: -35333.966 | M13: -36140.818
B14: 0707 | C14: Ogórki i korniszony świeże | D14: 27283.599 | E14: 25426.211 | F14: 22368.221 | G14: 19346.303 | H14: 117106.48 | I14: 121899.39 | J14: 85553.008 | K14: 106985.88 | L14: -89822.88 | M14: -96473.177
B15: 0708 | C15: Warzywa strączkowe, nawet łuskane, świeże | D15: 13762.097 | E15: 15052.011 | F15: 17153.951 | G15: 27324.965 | H15: 3607.071 | I15: 4006.423 | J15: 3138.702 | K15: 4157.331 | L15: 10155.026 | M15: 11045.588
B16: 0709 | C16: Inne warzywa świeże lub chłodzone | D16: 637871.81 | E16: 681523.48 | F16: 325221.66 | G16: 323321.09 | H16: 337218.19 | I16: 345498.76 | J16: 164025.84 | K16: 168142.9 | L16: 300653.62 | M16: 336024.72
B17: 0710 | C17: Warzywa niegotowane lub gotowane na parze, zamrożone | D17: 440139.74 | E17: 432572.37 | F17: 409561.59 | G17: 407308.91 | H17: 73019.806 | I17: 78589.331 | J17: 66524.441 | K17: 68252.737 | L17: 367119.93 | M17: 353983.04
B18: 0711 | C18: Warzywa zakonserwowane tymczasowo | D18: 18856.876 | E18: 16368.888 | F18: 10612.935 | G18: 8776.655 | H18: 26571.359 | I18: 36676.991 | J18: 16658.867 | K18: 18377.683 | L18: -7714.483 | M18: -20308.103
B19: 0712 | C19: Warzywa suszone, całe, cięte w kawałki | D19: 102755.16 | E19: 110353.24 | F19: 35094.956 | G19: 45331.324 | H19: 64033.727 | I19: 71873.124 | J19: 19368.85 | K19: 22262.13 | L19: 38721.438 | M19: 38480.121
... B31: 0810 | C31: Pozostałe owoce, świeże | D31: 246879.83 | E31: 292567.88 | F31: 73675.815 | G31: 70540.003 | H31: 341711.7 | I31: 423150.1 | J31: 104818.11 | K31: 109894.76 | L31: -94831.874 | M31: -130582.22

Sheet HANDEL ZAGRANICZNY_I_XII_2025
D1: EKSPORT/WYWÓZ | H1: IMPORT/PRZYWÓZ | L1: SALDO
B2: CN | C2: Nazwa towaru | D2: Wartość [tys. EUR] | F2: Wolumen [tony] | H2: Wartość [tys. EUR] | J2: Wolumen [tony] | L2: Wartość [tys. EUR]
D3: I-XII 2024r. | E3: I-XII 2025r.* | F3: I-XII 2024r. | G3: I-XII 2025r.* | H3: I-XII 2024r. | I3: I-XII 2025r.* | J3: I-XII 2024r. | K3: I-XII 2025r.* | L3: I-XII 2024r. | M3: I-XII 2025r.*
B4: 0701 | C4: Ziemniaki, świeże lub chłodzone | D4: 46460.788 | E4: 47534.142 | F4: 119743.26 | G4: 160663.39 | H4: 63341.138 | I4: 68038.956 | J4: 157064.05 | K4: 179710.18 | L4: -16880.35 | M4: -20504.814
B5: 0702 | C5: Pomidory świeże lub chłodzone | D5: 118770.49 | E5: 127718.81 | F5: 78265.073 | G5: 80423.129 | H5: 420922.98 | I5: 440881.68 | J5: 246260.81 | K5: 237223.77 | L5: -302152.49 | M5: -313162.87
B6: 0703 | C6: Cebula, szalotka, czosnek, pory oraz inne warzywa | D6: 129088.63 | E6: 114533.35 | F6: 170182.02 | G6: 161761.06 | H6: 102974.43 | I6: 90718.876 | J6: 228146.95 | K6: 178305.02 | L6: 26114.198 | M6: 23814.477
B7: 0704 | C7: Kapusta, kalafiory, kalarepa, kapusta włoska, | D7: 78418.27 | E7: 72408.866 | F7: 103773.7 | G7: 93572.299 | H7: 91457.973 | I7: 96192.435 | J7: 85863.155 | K7: 87124.957 | L7: -13039.703 | M7: -23783.569
B8: 0705 | C8: Sałata (Lactuca sativa) i cykoria (Cichorium spp.), | D8: 32269.805 | E8: 32275.545 | F8: 26063.481 | G8: 24667.471 | H8: 97087.925 | I8: 103169.86 | J8: 73073.851 | K8: 79840.871 | L8: -64818.12 | M8: -70894.314
B9: 0706 | C9: Marchew, rzepa, buraki sałatkowe, salsefia, selery, | D9: 42404.232 | E9: 40859.998 | F9: 64597.357 | G9: 83701.753 | H9: 78545.05 | I9: 77346.817 | J9: 96386.332 | K9: 108823.43 | L9: -36140.818 | M9: -36486.819
B10: 0707 | C10: Ogórki i korniszony świeże | D10: 25426.211 | E10: 28415.476 | F10: 19346.303 | G10: 20608.521 | H10: 121899.39 | I10: 141998.66 | J10: 106985.88 | K10: 109228.17 | L10: -96473.177 | M10: -113583.19
B11: 0708 | C11: Warzywa strączkowe, nawet łuskane, świeże | D11: 15052.011 | E11: 13872.72 | F11: 27324.965 | G11: 32373.875 | H11: 4006.423 | I11: 4059.883 | J11: 4157.331 | K11: 3804.698 | L11: 11045.588 | M11: 9812.837
B12: 0709 | C12: Inne warzywa świeże lub chłodzone | D12: 681523.48 | E12: 670939.82 | F12: 323321.09 | G12: 310841.7 | H12: 345498.76 | I12: 384711.16 | J12: 168142.9 | K12: 182179.82 | L12: 336024.72 | M12: 286228.66
B13: 0710 | C13: Warzywa niegotowane lub gotowane na parze, zamrożone | D13: 432572.37 | E13: 415272.98 | F13: 407308.91 | G13: 396677.51 | H13: 78589.331 | I13: 92194.668 | J13: 68252.737 | K13: 78001.767 | L13: 353983.04 | M13: 323078.31
B14: 0711 | C14: Warzywa zakonserwowane tymczasowo | D14: 16368.888 | E14: 16323.561 | F14: 8776.655 | G14: 8581.733 | H14: 36676.991 | I14: 42908.572 | J14: 18377.683 | K14: 23606.869 | L14: -20308.103 | M14: -26585.011
B15: 0712 | C15: Warzywa suszone, całe, cięte w kawałki | D15: 110353.24 | E15: 110838.96 | F15: 45331.324 | G15: 33558.361 | H15: 71873.124 | I15: 66246.777 | J15: 22262.13 | K15: 21623.151 | L15: 38480.121 | M15: 44592.179
... B27: 0810 | C27: Pozostałe owoce, świeże | D27: 292567.88 | E27: 281130.08 | F27: 70540.003 | G27: 65970.394 | H27: 423150.1 | I27: 516564.96 | J27: 109894.76 | K27: 124926.08 | L27: -130582.22 | M27: -235434.88

Sheet EXP KRAJE I-XII 2025
B2: HANDEL ZAGRANICZNY I-XI 2025 - DANE WSTĘPNE
B4: Źródło danych: Ministerstwo Finansów | Q4: =[3]POMOC!B5 -> Notowania 12 - 18.01.2026 / Tydzień 3
B5: UWAGA! DANE W TRAKCIE WERYFIKACJI - MOGĄ BYĆ OBARCZONE ISTOTNYMI BŁĘDAMI
B6: Eksport jabłek (CN 080810) wg. ważniejszych krajów | J6: Eksport pomidorów (CN 070200) wg. ważniejszych krajów
B7: według ważniejszych krajów | K7: według ważniejszych krajów
B8: I-XII 2024r. | F8: I-XII 2025r.* | K8: I-XII 2024r. | O8: I-XII 2025r.*
B9: Kraj | C9: Wartość [tys. EUR] | D9: Wolumen [tony] | F9: Kraj | G9: Wartość [tys. EUR] | H9: Wolumen [tony] | K9: Kraj | L9: Wartość [tys. EUR] | M9: Wolumen [tony] | O9: Kraj | P9: Wartość [tys. EUR] | Q9: Wolumen [tony]
B10: OGÓŁEM | C10: 477007.25 | D10: 806264.69 | F10: OGÓŁEM | G10: 486212.41 | H10: 700508.14 | K10: OGÓŁEM | L10: 118770.49 | M10: 78265.073 | O10: OGÓŁEM | P10: 127718.81 | Q10: 80423.129
B11: Niemcy | C11: 57867.333 | D11: 111789.82 | F11: Egipt | G11: 44556.36 | H11: 62719.407 | K11: Niemcy | L11: 37684.674 | M11: 19389.458 | O11: Niemcy | P11: 35678.282 | Q11: 16870.822
B12: Rumunia | C12: 33670.529 | D12: 56733.489 | F12: Rumunia | G12: 43974.121 | H12: 57414.521 | K12: Holandia | L12: 23794.028 | M12: 12230.875 | O12: Holandia | P12: 32468.342 | Q12: 14711.92
B13: Egipt | C13: 32613.758 | D13: 49925.33 | F13: Niemcy | G13: 41697.462 | H13: 76603.03 | K13: Ukraina | L13: 13105.591 | M13: 11893.771 | O13: Ukraina | P13: 15446.839 | Q13: 12982.969
B14: Holandia | C14: 30039.133 | D14: 64552.435 | F14: Republika Czeska | G14: 28312.106 | H14: 37366.124 | K14: Wielka Brytania | L14: 6070.129 | M14: 3500.478 | O14: Wielka Brytania | P14: 6774.162 | Q14: 4065.17
B15: India | C15: 27433.208 | D15: 36502.19 | F15: India | G15: 25530.056 | H15: 32109.57 | K15: Grecja | L15: 6009.306 | M15: 4814.146 | O15: Litwa | P15: 5193.759 | Q15: 4564.059
B16: Republika Czeska | C16: 24858.528 | D16: 39726.658 | F16: Białoruś | G16: 22781.442 | H16: 35680.952 | K16: Republika Czeska | L16: 4631.464 | M16: 3523.272 | O16: Szwecja | P16: 4131.334 | Q16: 2514.554
B17: Kazachstan | C17: 22469.752 | D17: 49837.466 | F17: Holandia | G17: 22191.287 | H17: 39796.766 | K17: Litwa | L17: 4525.671 | M17: 3643.441 | O17: Republika Czeska | P17: 3901.053 | Q17: 2934.066
B18: Szwecja | C18: 19970.989 | D18: 27948.481 | F18: Węgry | G18: 21094.25 | H18: 30551.64 | K18: Bułgaria | L18: 3824.25 | M18: 3975.658 | O18: Bułgaria | P18: 3577.967 | Q18: 3864.885
B19: Wielka Brytania | C19: 19033.955 | D19: 26116.881 | F19: Szwecja | G19: 19925.551 | H19: 23047.835 | K19: Włochy | L19: 3360.329 | M19: 2980.075 | O19: Białoruś | P19: 3047.725 | Q19: 2782.257
B20: Francja | C20: 18373.113 | D20: 36300.871 | F20: Kazachstan | G20: 19620.358 | H20: 40302.204 | K20: Łotwa | L20: 2815.527 | M20: 2347.647 | O20: Grecja | P20: 3027.187 | Q20: 2595.056
B21: Hiszpania | C21: 16763.658 | D21: 24837.097 | F21: Litwa | G21: 16914.04 | H21: 23227.383 | K21: Francja | L21: 2226.902 | M21: 2002.429 | O21: Hiszpania | P21: 2674.943 | Q21: 2614.798
... B26: Litwa | C26: 9688.003 | D26: 17808.343 | F26: Jordania | G26: 10017.868 | H26: 13195.878 | K26: Rumunia | L26: 692.409 | M26: 677.679 | O26: Chorwacja | P26: 583.031 | Q26: 626.885

Sheet IMP KRAJE I-XII 2025
B2: HANDEL ZAGRANICZNY I-XI 2025 - DANE WSTĘPNE
B4: Źródło danych: Ministerstwo Finansów | Q4: =[3]POMOC!B5 -> Notowania 12 - 18.01.2026 / Tydzień 3
B5: UWAGA! DANE W TRAKCIE WERYFIKACJI - MOGĄ BYĆ OBARCZONE ISTOTNYMI BŁĘDAMI
B6: Import pomarańczy (CN 080510) wg. ważniejszych krajów | J6: Import winogron (CN 080610) wg. ważniejszych krajów
B7: według ważniejszych krajów | K7: według ważniejszych krajów
B8: I-XII 2024r. | F8: I-XII 2025r.* | K8: I-XII 2024r. | O8: I-XII 2025r.*
B9: Kraj | C9: Wartość [tys. EUR] | D9: Wolumen [tony] | F9: Kraj | G9: Wartość [tys. EUR] | H9: Wolumen [tony] | K9: Kraj | L9: Wartość [tys. EUR] | M9: Wolumen [tony] | O9: Kraj | P9: Wartość [tys. EUR] | Q9: Wolumen [tony]
B10: OGÓŁEM | C10: 132678.96 | D10: 153645.18 | F10: OGÓŁEM | G10: 141542.86 | H10: 155386.55 | K10: OGÓŁEM | L10: 253467.64 | M10: 123915.93 | O10: OGÓŁEM | P10: 266661.98 | Q10: 137711.73
B11: Hiszpania | C11: 46973.179 | D11: 52170.665 | F11: Hiszpania | G11: 54614.552 | H11: 57751.299 | K11: Włochy | L11: 76020.069 | M11: 45258.874 | O11: Włochy | P11: 82454.215 | Q11: 51058.577
B12: Niemcy | C12: 23778.266 | D12: 22662.082 | F12: Niemcy | G12: 23017.112 | H12: 22119.654 | K12: Niemcy | L12: 42346.738 | M12: 15822.594 | O12: Niemcy | P12: 46541.621 | Q12: 17915.067
B13: Grecja | C13: 21630.095 | D13: 26988.807 | F13: Egipt | G13: 17778.799 | H13: 24100.734 | K13: Peru | L13: 18599.061 | M13: 5691.825 | O13: Peru | P13: 22021.268 | Q13: 8795.527
B14: Egipt | C14: 13826.024 | D14: 24299.338 | F14: Republika Południowej Afryki | G14: 17467.278 | H14: 18664.663 | K14: Holandia | L14: 17711.005 | M14: 6652.908 | O14: India | P14: 18847.363 | Q14: 9151.269
B15: Republika Południowej Afryki | C15: 12712.954 | D15: 13855.719 | F15: Grecja | G15: 16961.194 | H15: 20440.511 | K15: Hiszpania | L15: 16147.945 | M15: 6826.342 | O15: Chile | P15: 15608.446 | Q15: 6896.697
B16: Włochy | C16: 3488.998 | D16: 3240.985 | F16: Zimbabwe | G16: 3750.019 | H16: 4852.788 | K16: Republika Południowej Afryki | L16: 15593.338 | M16: 6052.69 | O16: Mołdowa | P16: 14457.088 | Q16: 11491.432
B17: Holandia | C17: 3455.966 | D17: 2934.207 | F17: Włochy | G17: 2630.714 | H17: 2404.308 | K17: India | L17: 14674.232 | M17: 8216.408 | O17: Holandia | P17: 13849.502 | Q17: 4693.092
B18: Portugalia | C18: 2190.646 | D18: 2104.521 | F18: Portugalia | G18: 1836.693 | H18: 1746.701 | K18: Mołdowa | L18: 14261.16 | M18: 9425.039 | O18: Republika Południowej Afryki | P18: 13252.279 | Q18: 5406.039
B19: Zimbabwe | C19: 2128.474 | D19: 2578.098 | F19: Holandia | G19: 1303.63 | H19: 1378.27 | K19: Turcja | L19: 10629.273 | M19: 6491.362 | O19: Hiszpania | P19: 12216.576 | Q19: 5913.352
B20: Turcja | C20: 1403.846 | D20: 1714.432 | F20: Turcja | G20: 664.744 | H20: 798.411 | K20: Chile | L20: 8849.538 | M20: 3758.045 | O20: Grecja | P20: 9231.052 | Q20: 6222.532
B21: Urugwaj | C21: 300.514 | D21: 432.887 | F21: Iran | G21: 567.664 | H21: 103.6 | K21: Grecja | L21: 6001.072 | M21: 3838.416 | O21: Turcja | P21: 5212.929 | Q21: 3568.377
... B26: Izrael | C26: 70.875 | D26: 64.897 | F26: Cypr | G26: 65.137 | H26: 92.82 | K26: Macedonia | L26: 1183.496 | M26: 1012.34 | O26: Łotwa | P26: 1671.836 | Q26: 750.866

Sheet Sł_Pol-Ang
B2: DICTIONARY
B5: WARZYWA | C5: VEGETABLES | D5: OWOCE | E5: FRUITS
B6: Buraki czerwone | C6: Red beets | D6: Arbuzy | E6: Watermelons
B7: Cebula biała | C7: Onions dry | D7: Banany | E7: Bananas
B8: Czosnek | C8: Garlic | D8: Brzoskwinie | E8: Peaches
B9: Kalafiory | C9: Cauliflowers | D9: Cytryny | E9: Lemons
B10: Kapusta biała | C10: Cabbage- white | D10: Grapefruity | E10: Grapefruit
B11: Marchew | C11: Carrots | D11: Gruszki | E11: Pears
B12: Ogórki długie | C12: Cucumbers | D12: Jabłka | E12: Apples
B13: Ogórki krótkie | C13: Gherkins | D13: Kiwi | E13: Kiwifruit
B14: Ogórki gruntowe | C14: Cucumbers field | D14: Mandarynki | E14: Tangerine
B15: Papryka czerwona | C15: Peppers - red | D15: Nektaryny | E15: Nectarines
B16: Papryka żółta | C16: Peppers - yellow | D16: Pomarańcze | E16: Oranges
... B25: Ziemniaki | C25: Potatoes | D25: Pieczarki | E25: Champignons

Sheet POMOC
B2: POMOC
P4: =B5 -> Notowania 09.03 - 18.03.2026 / Tydzień 10
B5: Notowania 09.03 - 18.03.2026 / Tydzień 10
B6: NR 11/2026

Sheet Moduł1

Sheet Moduł2

Sheet Moduł3

Sheet Moduł4

Sheet Moduł5

Sheet Moduł6
