Workbook
Name \a: #N/A
Name \s: #REF!
Name \s: #REF!
Name \s: #REF!
Name \s: #REF!
Name \s: #REF!
Name \s: #REF!
Name \s: #REF!
Name \s: #REF!
Name _17_11_2011: #REF!
Name _17_11_2011: #REF!
Name _17_11_2011: #REF!
Name _17_11_2011: #REF!
Name _17_11_2011: #REF!
Name _17_11_2011: #REF!
Name _17_11_2011: #REF!
Name _17_11_2011: #REF!
Name _7_11_2011: #REF!
Name _7_11_2011: #REF!
Name _7_11_2011: #REF!
Name _7_11_2011: #REF!
Name _7_11_2011: #REF!
Name _7_11_2011: #REF!
Name _7_11_2011: #REF!
Name _7_11_2011: #REF!
Name _A: #REF!
Name _A: #REF!
Name _A: #REF!
Name _A: #REF!
Name _A: #REF!
Name _A: #REF!
Name _A: #REF!
Name a: #REF!
Name a: #REF!
Name a: #REF!
Name a: #REF!
Name a: #REF!
Name a: #REF!
Name a: #REF!
Name aa: OFFSET(#REF!,0,0,COUNTA(#REF!),27)
Name aa: OFFSET(#REF!,0,0,COUNTA(#REF!),27)
Name aa: OFFSET(#REF!,0,0,COUNTA(#REF!),27)
Name aa: OFFSET(#REF!,0,0,COUNTA(#REF!),27)
Name aa: OFFSET(#REF!,0,0,COUNTA(#REF!),27)
Name aa: #REF!
Name aa: OFFSET(#REF!,0,0,COUNTA(#REF!),27)
Name aa: OFFSET(#REF!,0,0,COUNTA(#REF!),27)
Name aa: #REF!
Name aaa: #REF!
Name aaa: #REF!
Name aaa: #REF!
Name aaa: #REF!
Name aaa: #REF!
Name aaa: #REF!
Name aaaa: #REF!
Name aaaa: #REF!
Name aaaa: #REF!
Name aaaa: #REF!
Name aaaa: #REF!
Name aaaa: #REF!

Sheet INFO
B5: ZINTEGROWANY SYSTEM ROLNICZEJ INFORMACJI RYNKOWEJ
B10: Rynek
B11: owoców i warzyw
B14: NR 33/2026
M16: 24 sierpnia 2026 r.
D19: zsrir.minrol.gov.pl
A22: Informacje dot. cen hurtowych dostarczone są przez przedstawicieli niżej wymienionych rynków hurtowych.
A23: Warszawski Rolno-Spożywczy Rynek Hurtowy S.A. – Bronisze – www.bronisze.com.pl; Giełda - Białystok Podlaskie Centrum Rolno Towarowe S.A. - https://www.podlaskiecentrum.pl/; Lubelski Rynek Hurtowy S.A. – Lublin – www.elizowka.pl, Wielkopolska Gildia Rolno-Ogrodnicza S.A. – Poznań – www.wgro.com.pl; Podkarpackie Centrum Hurtowe Agrohurt S.A. – Rzeszów – www.mgrt.rzeszow.pl; Zachodniopomorskie Centrum Hurtowe Rolhurt- www.rolhurt.pl, Mewat Bydgoszcz - www.targowisko.mewat.pl, Rolno-spożywczy rynek hurtowy we Wrocławiu - http://www.targpiast.com.pl/, Łódzki Rynek Hurtowy ZJAZDOWA S.A. https://zjazdowa.com.pl/., Radomska Giełda Rolna - https://rsrh-radom.pl/, Targowisko Miejskie Sandomierz - http://targowiskasandomierz.pl/, Kompleks Handlowy RYBITWY - https://khrybitwy.pl/.

Sheet SPIS
B2: SPIS TREŚCI
C6: ZMIANY CEN HURTOWYCH
C7: CENY HURTOWE WARZYW
C8: CENY HURTOWE OWOCÓW
C9: CENY OWOCÓW ORGANIZACJI PRODUCENTÓW
C10: CENY OWOCÓW DO PRZETWORSTWA
C11: CENY WARZYW DO PRZETWORSTWA
C12: CENY DETALICZNE OWOCÓW
C13: CENY DETALICZNE WARZYW
C14: WYKRESY - OWOCE DETAL
C15: WYKRESY - WARZYWA DETAL
C16: IERGZ - CENY WARZYW
C17: IRGZ- CENY W ZAKŁADACH PRZETWÓRCZYCH I SPÓLDZIELNIACH
... C20: HANDEL ZAGRANICZNY

Sheet ZMIANY HURT
B2: ZMIANY ŚREDNICH CEN HURTOWYCH DLA WYBRANEGO ASORTYMENTU OWOCÓW I WARZYW
O4: =POMOC!B5 -> Notowania 17 - 23.08.2026 / Tydzień 33
D5: Cena zł/jedn | H5: Zmiany ceny (%)
B6: Produkt | C6: Jedn. | D6: 46254 | F6: 46247 | H6: w stosunku do poprzedniego notowania*) | J6: 2 tyg. | L6: 3 tyg. | N6: 4 tyg.
D7: Min | E7: Max | F7: Min | G7: Max | H7: Min | I7: Max | J7: Min | K7: Max | L7: Min | M7: Max | N7: Min | O7: Max
B8: 1 | C8: 2 | D8: 3 | E8: 4 | F8: 5 | G8: 6 | H8: 7 | I8: 8 | J8: 9 | K8: 10 | L8: 11 | M8: 12 | N8: 13 | O8: 14
B9: Warzywa krajowe
B10: Boczniaki | C10: kg | D10: 21.166667 | E10: 27 | F10: 21.166667 | G10: 27 | H10: 2.6366251 | I10: -2.9528865 | J10: -2.074214e-14 | K10: -2.9528865 | L10: -6.3702624 | M10: -10.459184 | N10: -8.111588 | O10: -3.3057851
B11: Buraki ćwikłowe | C11: kg | D11: 1.0166667 | E11: 1.31 | F11: 0.86666667 | G11: 1.2666667 | H11: 17.307692 | I11: 3.4210526 | J11: 12.962963 | K11: -4.1463415 | L11: 9.9099099 | M11: -2.962963 | N11: 12.962963 | O11: -4.1463415
B12: Buraki młode | C12: kg | D12: 3 | E12: 3.2 | F12: 3 | G12: 3.2 | H12: 0 | I12: 0 | J12: 36.363636 | K12: 3.2258065 | L12: 20 | M12: 3.2258065 | N12: 0 | O12: 0
B13: Cebula biała | C13: kg | D13: 1.1825 | E13: 1.605 | F13: 1.6825 | G13: 2.335 | H13: -29.717682 | I13: -31.263383 | J13: -29.717682 | K13: -30.141458 | L13: -29.402985 | M13: -30.217391 | N13: -34.668508 | O13: -27.811094
B14: Cebula młoda | C14: kg | D14: 4.1666667 | E14: 4.8333333 | F14: 4.3333333 | G14: 5 | H14: -3.8461538 | I14: -3.3333333 | J14: 31.578947 | K14: -3.3333333 | L14: -10.714286 | M14: -19.444444 | N14: 4.1666667 | O14: -3.3333333
B15: Kalafiory | C15: szt. | D15: 4.626 | E15: 6.814 | F15: 4.7 | G15: 6.6 | H15: -1.5744681 | I15: 3.2424242 | J15: 12.829268 | K15: 15.491525 | L15: -0.87142857 | M15: -0.28292683 | N15: 8.8470588 | O15: 0.94814815
B16: Kapusta biała | C16: kg | D16: 0.9 | E16: 1.1 | F16: 1.0666667 | G16: 1.2666667 | H16: -15.625 | I16: -13.157895 | J16: -21.73913 | K16: -21.428571 | L16: -21.73913 | M16: -21.428571 | N16: -21.73913 | O16: -21.428571
B17: Kapusta młoda | C17: szt. | D17: 2.666 | E17: 3.25 | F17: 2.766 | G17: 3.7 | H17: -3.615329 | I17: -12.162162 | J17: -6.9783671 | K17: -14.473684 | L17: -9.4736842 | M17: -13.983238 | N17: -4.529991 | O17: -14.304548
B18: Marchew | C18: kg | D18: 1.1666667 | E18: 1.7333333 | F18: 1.1666667 | G18: 1.7333333 | H18: 0 | I18: 0 | J18: -7.8947368 | K18: -13.333333 | L18: -23.497268 | M18: -19.379845 | N18: -30 | O18: -27.777778
B19: Marchew młoda | C19: kg | D19: 2 | E19: 2.375 | F19: 2.5 | G19: 2.75 | H19: -20 | I19: -13.636364 | J19: -20 | K19: -13.636364 | L19: -27.272727 | M19: -30.147059 | N19: -20 | O19: -15.178571
B20: Ogórki gruntowe | C20: kg | D20: 2.6 | E20: 4.7333333 | F20: 2.6666667 | G20: 5 | H20: -2.5 | I20: -5.3333333 | J20: 5.4054054 | K20: 20.338983 | L20: -42.222222 | M20: -27.179487 | N20: -35 | O20: -13.939394
B21: Ogórki szklarniowe | C21: kg | D21: 3.1 | E21: 4.5 | F21: 2.8 | G21: 4.05 | H21: 10.714286 | I21: 11.111111 | J21: -24.390244 | K21: -19.642857 | L21: -42.325581 | M21: -34.146341 | N21: -43.636364 | O21: -40
... B36: Ziemniaki młode | C36: kg | D36: 1.4 | E36: 1.68 | F36: 1.1766667 | G36: 1.4233333 | H36: 18.98017 | I36: 18.032787 | J36: 18.98017 | K36: 18.032787 | L36: -10.828025 | M36: -8.4468665 | N36: 30.841121 | O36: 12
B37: Owoce krajowe
B38: Borówki amerykańskie | C38: kg | D38: 19.2 | E38: 24 | F38: 16.4 | G38: 21.466 | H38: 17.073171 | I38: 11.804714 | J38: 43.283582 | K38: 25 | L38: 22.553191 | M38: 8.2706767 | N38: 20 | O38: -4
B39: Brzoskwinie | C39: kg | D39: 5.1 | E39: 7.88 | F39: 6.06 | G39: 8.4 | H39: -15.841584 | I39: -6.1904762 | J39: -15.841584 | K39: -3.902439 | L39: -27.142857 | M39: -10.454545 | N39: -19.473684 | O39: -9.0769231
B40: Gruszki | C40: kg | D40: 5 | E40: 5.75 | F40: 5 | G40: 5.75 | H40: 0 | I40: 0 | J40: 0 | K40: 0 | L40: 11.111111 | M40: 2.2222222 | N40: 11.111111 | O40: -8
B41: Agrest | C41: kg | D41: 26 | E41: 28 | F41: 12.5 | G41: 15 | H41: 108 | I41: 86.666667 | J41: 73.333333 | K41: 52.727273 | L41: 131.11111 | M41: 72.307692 | N41: 131.11111 | O41: 77.777778
B42: Czereśnie | C42: kg | D42: 11.666667 | E42: 17.583333 | F42: 12.5 | G42: 19.833333 | H42: -6.6666667 | I42: -11.344538 | J42: 14.379085 | K42: -8.4201389 | L42: 6.0606061 | M42: -11.344538 | N42: -0.70921986 | O42: -12.083333
B43: Maliny | C43: kg | D43: 33.2 | E43: 44 | F43: 36 | G43: 46.2 | H43: -7.7777778 | I43: -4.7619048 | J43: 3.75 | K43: 2.0881671 | L43: 0.60606061 | M43: 5.6 | N43: 16.491228 | O43: 13.548387
B44: Morele | C44: kg | D44: 5.8 | E44: 8.6 | F44: 6.4 | G44: 9.5 | H44: -9.375 | I44: -9.4736842 | J44: -6.4516129 | K44: -9.4736842 | L44: -7.4468085 | M44: -10.26087 | N44: -25.16129 | O44: -14
B45: Nektarynki | C45: kg | D45: 6.5 | E45: 6.5 | F45: 7 | G45: 7 | H45: -7.1428571 | I45: -7.1428571 | J45: -7.1428571 | K45: -7.1428571 | L45: -18.75 | M45: -18.75 | N45: 8.3333333 | O45: 8.3333333
B46: Śliwki | C46: kg | D46: 3.6 | E46: 5.8 | F46: 4.1 | G46: 6.7 | H46: -12.195122 | I46: -13.432836 | J46: -7.6923077 | K46: -9.375 | L46: -24.869565 | M46: -30.4 | N46: -44.615385 | O46: -31.764706
B47: Truskawki | C47: kg | D47: 17.4 | E47: 21 | F47: 14.8 | G47: 19.3 | H47: 17.567568 | I47: 8.8082902 | J47: 13.72549 | K47: -7.4889868 | L47: 14.725275 | M47: -10.320285 | N47: 22.105263 | O47: -7.1823204
B48: Porzeczki czarne | C48: kg | D48: 15 | E48: 17.5 | F48: 17.333333 | G48: 19 | H48: -13.461538 | I48: -7.8947368 | J48: -15.730337 | K48: -15.865385 | L48: -21.052632 | M48: -24.460432 | N48: -17.808219 | O48: -23.913043
B49: Porzeczki czerwone | C49: kg | D49: 12.5 | E49: 15.75 | F49: 13.2 | G49: 15.8 | H49: -5.3030303 | I49: -0.3164557 | J49: -5.3030303 | K49: 5 | L49: -1.3157895 | M49: 3.8461538 | N49: -9.0909091 | O49: -8.6956522
B50: Wiśnie | C50: kg | D50: 8.394 | E50: 10.13 | F50: 8.2 | G50: 10.532 | H50: 2.3658537 | I50: -3.8169389 | J50: 5.7978321 | K50: -1.3247613 | L50: -5.3237085 | M50: -11.140351 | N50: 0.7199424 | O50: -14.630035
B51: Jabłka:
B52: Antonówki | C52: kg | D52: 3.425 | E52: 3.925 | F52: 3.425 | G52: 4.255 | H52: 0 | I52: -7.7555817 | J52: -20.533643 | K52: -18.399168
B53: Celesta | C53: kg | D53: 3.08 | E53: 3.08 | F53: 3.08 | G53: 3.08 | H53: 0 | I53: 0 | J53: 0 | K53: 0
B54: Early Geneva | C54: kg | D54: 3.08 | E54: 3.08 | F54: 3.08 | G54: 3.08 | H54: 0 | I54: 0 | J54: 1.986755 | K54: -33.692142 | L54: -12.5 | M54: -39.100346 | N54: -26.198083 | O54: -36.275862
B55: Gala | C55: kg | D55: 2 | E55: 3 | F55: 2 | G55: 3 | H55: 0 | I55: 0 | J55: -20 | K55: -14.285714 | L55: -28.315412 | M55: -8.8145897 | N55: -28.315412 | O55: -8.8145897
B56: Golden | C56: kg | D56: 2 | E56: 3 | F56: 2 | G56: 3 | H56: 0 | I56: 0 | J56: -38.461538 | K56: -22.580645 | L56: -38.461538 | M56: -22.580645 | N56: -37.36952 | O56: -16.897507
...

Sheet HURT WARZ
B2: ŚREDNIE CENY WARZYW NA RYNKACH HURTOWYCH
N4: =POMOC!B5 -> Notowania 17 - 23.08.2026 / Tydzień 33
E5: Bronisze | G5: Kalisz | I5: Lublin | K5: Łódź | M5: Poznań
B6: Data notowania | E6: 46254 | G6: 46252 | I6: 46252 | K6: 46254 | M6: 46254
B7: Warzywa | E7: Min | F7: Max | G7: Min | H7: Max | I7: Min | J7: Max | K7: Min | L7: Max | M7: Min | N7: Max
B8: KRAJOWE
B9: Buraki ćwikłowe | E9: 0.8 | F9: 1.2 | G9: 1.25 | H9: 1.13 | K9: 1 | L9: 1.6
B10: Cebula biała | D10: kg | E10: 1.2 | F10: 1.75 | G10: 1 | H10: 1 | I10: 1.33 | J10: 1.67 | K10: 1.2 | L10: 2
B11: Cebula młoda | D11: kg | E11: 3.5 | F11: 5 | I11: 5 | J11: 5.5 | M11: 4 | N11: 4
B12: Kalafiory | D12: szt. | E12: 6 | F12: 9 | G12: 1.33 | H12: 1.17 | I12: 5.8 | J12: 6.9 | K12: 3 | L12: 9 | M12: 7 | N12: 8
B13: Kapusta biała | D13: kg | E13: 0.7 | F13: 0.9 | G13: 1 | H13: 1 | K13: 1 | L13: 1.4
B14: Kapusta młoda | D14: szt. | E14: 2.5 | F14: 3 | G14: 1.5 | H14: 1.25 | I14: 4 | J14: 4 | K14: 2 | L14: 4 | M14: 3.33 | N14: 4
B15: Marchew | D15: kg | E15: 1 | F15: 1.5 | G15: 1.2 | H15: 1.5 | K15: 1.3 | L15: 2.2
B16: Ogórki gruntowe | D16: kg | E16: 1 | F16: 6 | G16: 2 | H16: 3 | M16: 4.8 | N16: 5.2
B17: Ogórki szklarniowe | D17: kg | E17: 3.5 | F17: 5 | G17: 2 | H17: 2.5 | I17: 3 | J17: 4 | K17: 3 | L17: 6 | M17: 4 | N17: 5
B18: Papryka czerwona | D18: kg | E18: 6 | F18: 9 | G18: 6 | H18: 7 | I18: 4 | J18: 6.5 | K18: 6 | L18: 9 | M18: 8.6 | N18: 9
B19: Papryka zielona | D19: kg | E19: 4 | F19: 5 | G19: 4 | H19: 5 | K19: 5 | L19: 7 | M19: 5.6 | N19: 6.4
B20: Papryka żółta | D20: kg | E20: 6 | F20: 9 | G20: 7 | H20: 7 | K20: 9 | L20: 12 | M20: 8.6 | N20: 9
B21: Pietruszka | D21: kg | E21: 3.5 | F21: 5 | G21: 3 | H21: 3 | K21: 4 | L21: 6 | M21: 5 | N21: 6
B22: Pomidory | D22: kg | E22: 4.5 | F22: 6 | G22: 5 | H22: 5.83 | I22: 5 | J22: 5.8 | K22: 4 | L22: 5.83 | M22: 4.5 | N22: 5.67
B23: Pomidory gruntowe | D23: kg | E23: 2.25 | F23: 4
B24: Pomidory malinowe | D24: kg | E24: 3.66 | F24: 6.65 | G24: 3.67 | H24: 4.33 | I24: 5 | J24: 5.15 | K24: 4.17 | L24: 5.83 | M24: 4.5 | N24: 5.67
B25: Pory | D25: szt. | G25: 1 | H25: 2 | I25: 2.5 | J25: 3 | K25: 1.5 | L25: 2.5
B26: Pory młode | D26: szt. | E26: 2.25 | F26: 3 | K26: 2 | L26: 3 | M26: 2.3 | N26: 2.5
B27: Rzodkiewka | D27: pęczek | E27: 2 | F27: 2.75 | G27: 1.5 | H27: 1.5 | I27: 2.3 | J27: 2.4 | K27: 1.5 | L27: 2.5 | M27: 2 | N27: 2
B28: Sałata | D28: szt. | E28: 2.25 | F28: 4 | G28: 2.08 | H28: 2.08 | I28: 3.18 | J28: 3.34 | K28: 2.5 | L28: 3.5 | M28: 3 | N28: 3.33
B29: Selery | D29: kg | E29: 1.4 | F29: 1.6 | G29: 2 | H29: 3 | I29: 3 | J29: 4 | K29: 2 | L29: 4 | M29: 3.6 | N29: 4
B30: Ziemniaki | D30: kg | E30: 0.66 | F30: 1.1 | I30: 1.34 | J30: 1.34 | K30: 0.53 | L30: 1.07
B31: Ziemniaki młode | D31: kg | G31: 0.53 | H31: 0.8 | I31: 1.67 | J31: 1.84 | M31: 2 | N31: 2.4
B32: Boczniaki | D32: kg | E32: 13.5 | F32: 20 | I32: 20 | J32: 26 | M32: 30 | N32: 35
B33: Pieczarki | D33: kg | E33: 9 | F33: 12 | G33: 10 | H33: 10 | I33: 7 | J33: 9 | K33: 6.67 | L33: 11.67 | M33: 11 | N33: 13
B34: Selery młode | D34: kg | M34: 5 | N34: 6
D35: szt. | E35: 2 | F35: 3
B36: Ziemniaki | D36: kg | E36: 0.66 | F36: 1.1 | I36: 1.34 | J36: 1.34 | K36: 0.53 | L36: 1.07
B37: Ziemniaki młode | D37: kg | G37: 0.53 | H37: 0.67 | I37: 1.67 | J37: 2 | M37: 1.33 | N37: 1.6

Sheet HURT OWOC
B2: ŚREDNIE CENY OWOCÓW NA RYNKACH HURTOWYCH
N4: =POMOC!B5 -> Notowania 17 - 23.08.2026 / Tydzień 33
B5: Miejscowość | E5: Bronisze | G5: Kalisz | I5: Lublin | K5: Łódź | M5: Poznań
B6: Data notowania | E6: 46254 | G6: 46252 | I6: 46252 | K6: 46254 | M6: 46254
B7: Owoce | D7: Jedn. | E7: Min | F7: Max | G7: Min | H7: Max | I7: Min | J7: Max | K7: Min | L7: Max | M7: Min | N7: Max
B8: KRAJOWE
B9: Borówki amerykańskie | E9: 20 | F9: 30 | G9: 20 | H9: 24 | I9: 16 | J9: 18 | K9: 20 | L9: 23 | M9: 20 | N9: 25
B10: Brzoskwinie | E10: 5 | F10: 8 | G10: 4 | H10: 6 | I10: 5.5 | J10: 6.6 | K10: 5 | L10: 8 | M10: 6 | N10: 10.8
B11: Czereśnie | E11: 10 | F11: 19 | G11: 15 | H11: 15 | I11: 13 | J11: 17.5 | K11: 10 | L11: 18 | M11: 12 | N11: 17
B12: Gruszki | E12: 5 | F12: 6.5 | G12: 5 | H12: 5
B13: Jabłka
C14: Antonówki | D14: kg | E14: 3 | F14: 4 | G14: 3.85 | H14: 3.85
C15: Celesta | D15: kg | G15: 3.08 | H15: 3.08
C16: Early Geneva | D16: kg | G16: 3.08 | H16: 3.08
C17: Gala | D17: kg | E17: 2 | F17: 3
C18: Golden | D18: kg | E18: 2 | F18: 3
C19: Jonagold | D19: kg | E19: 2 | F19: 3
C20: Jonagored | D20: kg | G20: 3.08 | H20: 3.08
C21: Ligol | D21: kg | E21: 2 | F21: 3 | G21: 3.08 | H21: 3.08
C22: Lobo | D22: kg | I22: 4 | J22: 4.17
C23: Papierówki | D23: kg | G23: 3.85 | H23: 3.85 | K23: 2.67 | L23: 4.67
C24: Piros | D24: kg | E24: 3 | F24: 4.25 | G24: 3.08 | H24: 3.08 | I24: 3.3 | J24: 3.98 | K24: 2.67 | L24: 4.33 | M24: 2 | N24: 5.33
C25: Szampion | D25: kg | E25: 2 | F25: 3.5 | I25: 5.33 | J25: 5.33 | K25: 1.67 | L25: 3.33
C26: Szara Reneta | D26: kg | E26: 2 | F26: 3 | K26: 2 | L26: 4
C27: Paula-Red | D27: kg | E27: 3 | F27: 4 | G27: 3.08 | H27: 3.08 | M27: 2 | N27: 5.33
B28: Maliny | D28: kg | E28: 28 | F28: 40 | G28: 24 | H28: 40 | I28: 36 | J28: 38 | K28: 32 | L28: 50 | M28: 46 | N28: 52
B29: Morele | D29: kg | E29: 5 | F29: 9 | G29: 4 | H29: 8 | I29: 5 | J29: 6.5 | K29: 5 | L29: 8.5 | M29: 10 | N29: 11
B30: Nektarynki | D30: kg | G30: 5 | H30: 5 | M30: 8 | N30: 8
B31: Porzeczki czarne | D31: kg | G31: 15 | H31: 15 | K31: 15 | L31: 20
B32: Porzeczki czerwone | D32: kg | E32: 10 | F32: 15 | G32: 10 | H32: 10 | K32: 10 | L32: 14 | M32: 20 | N32: 24
B33: Śliwki | D33: kg | E33: 3 | F33: 5 | G33: 3 | H33: 4 | I33: 5 | J33: 5 | K33: 3 | L33: 9 | M33: 4 | N33: 6
B34: Truskawki | D34: kg | E34: 17 | F34: 25 | G34: 15 | H34: 20 | I34: 15 | J34: 18.5 | K34: 16 | L34: 17.5 | M34: 24 | N34: 24
B35: Wiśnie | D35: kg | E35: 9 | F35: 12 | G35: 8 | H35: 8 | I35: 8.3 | J35: 8.32 | K35: 6 | L35: 10 | M35: 10.67 | N35: 12.33
B36: IMPORTOWANE
B37: Ananasy | D37: szt. | E37: 5 | F37: 9 | G37: 5 | H37: 15 | I37: 11 | J37: 11 | K37: 5 | L37: 17
B38: Arbuzy | D38: kg | E38: 2 | F38: 4.5 | G38: 2 | H38: 4.5 | I38: 3 | J38: 3.6 | K38: 1.8 | L38: 4 | M38: 4.5 | N38: 5
B39: Banany | D39: kg | E39: 4.2 | F39: 6.15 | G39: 4.44 | H39: 4.44 | I39: 4.72 | J39: 5.61 | K39: 3.33 | L39: 6.11 | M39: 4.72 | N39: 6.94
B40: Brzoskwinie | D40: kg | E40: 6 | F40: 8 | K40: 7 | L40: 9
B41: Cytryny | D41: kg | E41: 5 | F41: 7 | G41: 5 | H41: 7 | I41: 7.22 | J41: 8.61 | K41: 8 | L41: 10 | M41: 8 | N41: 9
B42: Grejpfruty | D42: kg | E42: 5 | F42: 26 | G42: 5 | H42: 7 | I42: 7 | J42: 8 | K42: 7 | L42: 9 | M42: 7.14 | N42: 7.86
...

Sheet ADRESY RYNKÓW HURTOWYCH 
A2: Adresy rynków hurtowych z których MINROL pobiera informacje do Biuletynu Informacyjnego ;
A3: 1. www.bronisze.com.pl
A4: 2. https://podlaskiecentrum.pl/
A5: 3. https://gieldakaliska.pl/
A6: 4. https://www.elizowka.pl/
A7: 5. https://www.targpiast.com.pl/pl
A8: 6. https://www.zjazdowa.com.pl/pl/serwis-cenowy/
A9: 7. https://wgro.com.pl/notowania-cenowe-maly-hurt/
A10: 8. https://khrybitwy.pl/
A11: 9. https://www.agrohurtsa.pl/

Sheet OWOCE ORGANIZACJE PROD.
B2: ŚREDNIE CENY ZAKUPU JABŁEK I GRUSZEK PŁACONE PRZEZ ORGANIZACJE PRODUCENTÓW - najważniejsze odmiany
B3: (zł/100 kg)
N4: =POMOC!B5 -> Notowania 17 - 23.08.2026 / Tydzień 33
B5: TOWAR | C5: 16.08.2026 | E5: 09.08.2026 | F5: 45886 | G5: Zmiana % w stosunku do poprzedniego okresu | H5: Zmiana % w stosunku do okresu sprzed roku
B6: Jabłka (razem) | C6: Jabłka (razem) | D6: nld | E6: nld | F6: nld | G6: - | H6: -
B7: Boskoop | C7: Boskoop | D7: --- | E7: --- | F7: --- | G7: - | H7: -
B8: Gala | C8: Gala | D8: nld | E8: nld | F8: nld | G8: - | H8: -
B9: Gloster | C9: Gloster | D9: --- | E9: --- | F9: --- | G9: - | H9: -
B10: Golden delicious | C10: Golden delicious | D10: nld | E10: nld | F10: nld | G10: - | H10: -
B11: Idared | C11: Idared | D11: nld | E11: nld | F11: nld | G11: - | H11: -
B12: Jonagold/Jonagored | C12: Jonagold/Jonagored | D12: nld | E12: nld | F12: nld | G12: - | H12: -
B13: Ligol | C13: Ligol | D13: nld | E13: nld | F13: nld | G13: - | H13: -
B14: Szampion | C14: Szampion | D14: nld | E14: nld | F14: nld | G14: - | H14: -
B15: Gruszki (razem) | C15: Gruszki (razem) | D15: --- | E15: --- | F15: --- | G15: - | H15: -
B17: ŚREDNIE CENY SPRZEDAŻY JABŁEK I GRUSZEK PŁACONE PRZEZ ORGANIZACJE PRODUCENTÓW - główne odmiany
B18: (zł/100 kg)
B20: TOWAR | C20: 16.08.2026 | E20: 09.08.2026 | F20: 45886 | G20: Zmiana % w stosunku do poprzedniego okresu | H20: Zmiana % w stosunku do okresu sprzed roku
B21: Jabłka (razem) | C21: Jabłka (razem) | D21: nld | E21: nld | F21: nld | G21: - | H21: -
B22: Boskoop | C22: Boskoop | D22: --- | E22: --- | F22: --- | G22: - | H22: -
B23: Gala | C23: Gala | D23: nld | E23: nld | F23: nld | G23: - | H23: -
B24: Gloster | C24: Gloster | D24: --- | E24: --- | F24: --- | G24: - | H24: -
B25: Golden delicious | C25: Golden delicious | D25: nld | E25: nld | F25: nld | G25: - | H25: -
B26: Idared | C26: Idared | D26: nld | E26: nld | F26: nld | G26: - | H26: -
B27: Jonagold/Jonagored | C27: Jonagold/Jonagored | D27: nld | E27: nld | F27: nld | G27: - | H27: -
B28: Ligol | C28: Ligol | D28: nld | E28: nld | F28: nld | G28: - | H28: -
B29: Szampion | C29: Szampion | D29: nld | E29: nld | F29: nld | G29: - | H29: -
B30: Gruszki (razem) | C30: Gruszki (razem) | D30: --- | E30: --- | F30: --- | G30: - | H30: -
B32: Odmiany, dla których zbierane są dane:
B33: Boskoop, Cortland, Elstar, Gala, Gloster, Golden delicious, Idared, Jonagold/Jonagored, Ligol, Lobo, Red delicious, Shampion

Sheet OWOCE PRZETWÓRSTWO
B2: ŚREDNIE CENY ZAKUPU OWOCÓW PŁACONE PRZEZ PODMIOTY ZAJMUJĄCE SIĘ PRZETWÓRSTWEM
B3: (zł/100 kg)
L4: =POMOC!B5 -> Notowania 17 - 23.08.2026 / Tydzień 33
B5: Towar | C5: Przeznaczenie | D5: 16.08.2026 | E5: 09.08.2026 | F5: 17.08.2025 | G5: Zmiana ceny (%)
G6: tygodniowa | H6: roczna
B7: Jabłka | C7: ogółem | D7: 70.643757 | E7: 69.444519 | F7: 84.439853 | G7: 1.7268999 | H7: -16.338371
C8: na sok zagęszczony | D8: 70.495278 | E8: 69.439312 | F8: 83.219875 | G8: 1.5207033 | H8: -15.290334
B9: Maliny | C9: ogółem | D9: 1826.1201 | E9: 1817.4983 | F9: 934.12331 | G9: 0.47438188 | H9: 95.490266
C10: na mrożonki | D10: 1858.5519 | E10: 1694.0843 | F10: nld | G10: 9.708346 | H10: -
B11: Wiśnie | C11: ogółem | D11: 354.6862 | E11: 355.52831 | F11: 394.92636 | G11: -0.23686084 | H11: -10.189282
C12: na sok zagęszczony | D12: 329.03773 | E12: 318.37975 | F12: 350.74117 | G12: 3.3475685 | H12: -6.1878794
C13: na mrożonki | D13: 513.41365 | E13: 482.14342 | F13: nld | G13: 6.4856693 | H13: -
B14: Aronia | C14: ogółem | D14: 400.74592 | E14: nld | F14: nld | G14: - | H14: -
C15: na sok zagęszczony | D15: 409.3872 | E15: --- | F15: --- | G15: - | H15: -

Sheet WARZYWA PRZETWÓRSTWO 
B2: ŚREDNIE CENY ZAKUPU WARZYW płacone przez podmioty zajmujące się przetwórstwem
B3: (zł/100 kg)
B5: Towar | C5: 16.08.2026 | D5: 09.08.2026 | E5: 17.08.2025 | F5: Zmiana ceny (%)
F6: tygodniowa | G6: roczna
B7: Cebula biała obierana | C7: 111.84045 | D7: 126.69425 | E7: nld | F7: -11.724131 | G7: -
B8: Kapusta biała | C8: --- | D8: 90.335371 | E8: nld | F8: - | G8: -
B9: Ogórki / ogółem | C9: 297.46395 | D9: 293.98012 | E9: 370.33679 | F9: 1.1850545 | G9: -19.677451
B10: Ogórki / 6-9 cm | C10: 329.54629 | D10: 312.33138 | E10: nld | F10: 5.5117435 | G10: -
B11: Ogórki / 9-12 cm | C11: 139.54278 | D11: 139.659 | E11: 205.76149 | F11: -0.083218726 | G11: -32.182266
B12: Ogórki / powyżej 12 cm | C12: nld | D12: 74.670554 | E12: nld | F12: - | G12: -

Sheet ZAKUP OWOCE DETAL - LUZ
B2: ŚREDNIE CENY ZAKUPU OWOCÓW PŁACONE PRZEZ PODMIOTY HANDLU DETALICZNEGO - luz
B3: (zł/100 kg)
B5: OWOCE krajowe - luzem
B6: TOWAR | C6: 16.08.2026 | D6: 09.08.2026 | E6: 17.08.2025 | F6: Zmiana ceny (%)
F7: tygodniowa | G7: roczna
B8: Jabłka (razem) | C8: 297.54843 | D8: 314.40845 | E8: 490.11419 | F8: -5.3624564 | G8: -39.289979
B9: Gala | C9: 377.03061 | D9: 367.09928 | E9: nld | F9: 2.7053524 | G9: -
B10: Golden delicious | C10: 353.50395 | D10: 348.90936 | E10: 510.36595 | F10: 1.3168441 | G10: -30.735202
B11: Idared | C11: 343.32005 | D11: 343.74975 | E11: 477.38649 | F11: -0.12500325 | G11: -28.083418
B12: Jonagold/Jonagored | C12: 275.82317 | D12: 286.26126 | E12: 491.29946 | F12: -3.6463515 | G12: -43.858441
B13: Ligol | C13: 334.66603 | D13: 312.05518 | E13: 506.15278 | F13: 7.2457845 | G13: -33.880433
B14: Cortland | C14: --- | D14: --- | E14: --- | F14: - | G14: -
B15: Boskoop | C15: --- | D15: --- | E15: --- | F15: - | G15: -
B16: Granny Smith | C16: --- | D16: --- | E16: --- | F16: - | G16: -
B17: Elstar | C17: --- | D17: --- | E17: --- | F17: - | G17: -
B18: Lobo | C18: --- | D18: --- | E18: --- | F18: - | G18: -
B19: Red Delicious | C19: --- | D19: --- | E19: --- | F19: - | G19: -
B20: Szampion | C20: 309.50568 | D20: 322.61499 | E20: 497.11176 | F20: -4.0634546 | G20: -37.739215
B22: OWOCE z importu - luzem
B23: TOWAR | C23: 16.08.2026 | D23: 09.08.2026 | E23: 17.08.2025 | F23: Zmiana ceny (%)
F24: tygodniowa | G24: roczna
B25: Jabłka-Granny Smith | C25: nld | D25: nld | E25: --- | F25: - | G25: -
B26: Pomarańcze (razem) | C26: 508.08634 | D26: 463.5049 | E26: 524.55594 | F26: 9.6183306 | G26: -3.1397233
B27: Pomarańcze nieokreślone | C27: 519.38688 | D27: 452.48427 | E27: 535.55278 | F27: 14.785622 | G27: -3.0185452
B28: Navel | C28: nld | D28: nld | E28: nld | F28: - | G28: -
B29: Salustiana Novelinas | C29: nld | D29: nld | E29: nld | F29: - | G29: -
B30: Tarroco | C30: --- | D30: --- | E30: --- | F30: - | G30: -
B31: Lanelate | C31: nld | D31: nld | E31: nld | F31: - | G31: -
B32: Navelate | C32: --- | D32: --- | E32: --- | F32: - | G32: -
B33: Valencia Late | C33: nld | D33: nld | E33: nld | F33: - | G33: -
B34: Brzoskwinie (razem) | C34: 640.54356 | D34: 622.06133 | E34: 824.66524 | F34: 2.9711266 | G34: -22.326839
B35: Brzoskwinie biały miąższ | C35: 860.85159 | D35: 720.21216 | E35: nld | F35: 19.527499 | G35: -
B36: Brzoskwinie zółty miąższ | C36: 663.28118 | D36: 649.73999 | E36: 817.67447 | F36: 2.0840936 | G36: -18.882
B37: Nektaryny (razem) | C37: 576.24763 | D37: 577.85231 | E37: 880.5271 | F37: -0.2776979 | G37: -34.556514
B38: Nektaryny biały miąższ | C38: --- | D38: --- | E38: --- | F38: - | G38: -
B39: Nektaryny żółty miąższ | C39: 584.7012 | D39: 632.89744 | E39: 875.33971 | F39: -7.615174 | G39: -33.20294

Sheet ZAKUP WARZ DETAL - LUZ
B2: ŚREDNIE CENY ZAKUPU WARZYW PŁACONE PRZEZ PODMIOTY HANDLU DETALICZNEGO - luz
B3: (zł/100 kg)
B5: WARZYWA krajowe - luzem
B6: TOWAR | C6: 16.08.2026 | D6: 09.08.2026 | E6: 17.08.2025 | F6: Zmiana ceny (%)
F7: tygodniowa | G7: roczna
B8: Cebula biała | C8: 216.65981 | D8: 225.18606 | E8: --- | F8: -3.7863134 | G8: -
B9: Marchew | C9: 186.13748 | D9: 200.14427 | E9: 175.12025 | F9: -6.9983471 | G9: 6.291237
B10: Ogórki szklarniowe | C10: 377.41715 | D10: 469.9854 | E10: --- | F10: -19.695984 | G10: -
B11: Papryka czerwona | C11: 734.07444 | D11: 760.81495 | E11: --- | F11: -3.5147193 | G11: -
B12: Pomidory okrągłe | C12: 522.05044 | D12: 482.0113 | E12: 450.31465 | F12: 8.3066796 | G12: 15.930147
B13: Pomidory na gałązkach | C13: 502.60144 | D13: 386.04347 | E13: 412.00885 | F13: 30.192965 | G13: 21.988019
B14: Pomidory typu "cherry" | C14: 1012.7967 | D14: 898.30737 | E14: nld | F14: 12.745003 | G14: -
B15: Ziemniaki | C15: 106.93315 | D15: 106.35408 | E15: 116.57972 | F15: 0.54447266 | G15: -8.2746571
B17: WARZYWA z importu - luzem
B18: TOWAR | C18: 16.08.2026 | D18: 09.08.2026 | E18: 17.08.2025 | F18: Zmiana ceny (%)
F19: tygodniowa | G19: roczna
B20: Cebula biała | C20: nld | D20: nld | E20: --- | F20: - | G20: -
B21: Marchew | C21: nld | D21: nld | E21: nld | F21: - | G21: -
B22: Ogórki szklarniowe | C22: --- | D22: --- | E22: --- | F22: - | G22: -
B23: Papryka czerwona | C23: 596.87487 | D23: 863.31168 | E23: --- | F23: -30.86218 | G23: -
B24: Pomidory okrągłe | C24: nld | D24: 928.42675 | E24: nld | F24: - | G24: -
B25: Pomidory na gałązkach | C25: 624.95987 | D25: 558.65982 | E25: nld | F25: 11.867695 | G25: -
B26: Pomidory typu "cherry" | C26: nld | D26: nld | E26: 1530.4797 | F26: - | G26: -
B27: Ziemniaki | C27: nld | D27: nld | E27: nld | F27: - | G27: -

Sheet ZAKUP WARZ DETAL - DO 2 KG
B2: ŚREDNIE CENY ZAKUPU WARZYW PŁACONE PRZEZ PODMIOTY HANDLU DETALICZNEGO - opakowania do 2 kg
B3: (zł/100 kg)
B5: WARZYWA krajowe - opakowania do 2 kg
B6: TOWAR | C6: 16.08.2026 | D6: 09.08.2026 | E6: 17.08.2025 | F6: Zmiana ceny (%)
F7: tygodniowa | G7: roczna
B8: Cebula biała | C8: 211.91179 | D8: 222.0173 | E8: --- | F8: -4.5516747 | G8: -
B9: Marchew | C9: 334.75458 | D9: 447.37231 | E9: 324.93244 | F9: -25.173155 | G9: 3.022827
B10: Ogórki szklarniowe | C10: --- | D10: --- | E10: --- | F10: - | G10: -
B11: Papryka czerwona | C11: 1610.3219 | D11: 1447.4194 | E11: --- | F11: 11.254691 | G11: -
B12: Pomidory okrągłe | C12: 760.55892 | D12: 652.34403 | E12: 655.37098 | F12: 16.588623 | G12: 16.050137
B13: Pomidory na gałązkach | C13: 1147.9993 | D13: 1082.4145 | E13: 1113.8653 | F13: 6.0591227 | G13: 3.0644633
B14: Pomidory typu "cherry" | C14: 1684.4921 | D14: 1561.0234 | E14: 1520.7757 | F14: 7.9094727 | G14: 10.765323
B15: Ziemniaki | C15: 177.41482 | D15: 179.25301 | E15: 206.23267 | F15: -1.0254686 | G15: -13.973463
B17: WARZYWA z importu - do 2 kg
B18: TOWAR | C18: 16.08.2026 | D18: 09.08.2026 | E18: 17.08.2025 | F18: Zmiana ceny (%)
F19: tygodniowa | G19: roczna
B20: Cebula biała | C20: 855.46291 | D20: 901.46139 | E20: --- | F20: -5.1026563 | G20: -
B21: Marchew | C21: nld | D21: nld | E21: nld | F21: - | G21: -
B22: Ogórki szklarniowe | C22: nld | D22: nld | E22: --- | F22: - | G22: -
B23: Papryka czerwona | C23: 594.88805 | D23: 1537.4649 | E23: --- | F23: -61.307211 | G23: -
B24: Pomidory okrągłe | C24: nld | D24: nld | E24: nld | F24: - | G24: -
B25: Pomidory na gałązkach | C25: nld | D25: nld | E25: nld | F25: - | G25: -
B26: Pomidory typu "cherry" | C26: 680.4369 | D26: 1336.9851 | E26: 1276.4329 | F26: -49.106619 | G26: -46.692311
B27: Ziemniaki | C27: --- | D27: --- | E27: --- | F27: - | G27: -

Sheet DETAL OWOCE WYKRES 
B2: Średnie ceny zakupu jabłek (luzem) płacone przez podmioty handlu detalicznego
M4: =POMOC!B5 -> Notowania 17 - 23.08.2026 / Tydzień 33

Sheet DETAL WARZ WYKRES
B2: Średnie ceny zakupu warzyw (luzem) płacone przez podmioty handlu detalicznego
M4: =POMOC!B5 -> Notowania 17 - 23.08.2026 / Tydzień 33
B60: 12.07.2026 | C60: 05.07.2026
A61: Marchew | B61: 2.48 | C61: 2.56
A62: Pomidory okrągłe | B62: 4.207 | C62: 3.86
A63: Ziemniaki | B63: 1.259 | C63: 1.43

Sheet IERGZ_warzywa
B2: Ogrodniczy Informator Cenowy
B3: Instytut Ekonomiki Rolnictwa i Gospodarki Żywnościowej Państwowy Instytut Badawczy
B4: 00-950 Warszawa, ul.Świętokrzyska 20, P.O. Box 984
B5: tel. (22) 505 44 32, e-mail: Tomasz.Smolenski@ierigz.waw.pl
B7: Ceny skupu netto warzyw i owoców w spółdzielniach ogrodniczych zbierane 17 VIII 2026 r.
B8: Województwo | C8: Buraki ćwikłowe | D8: Cebula | E8: Kaputa wczesna/a | F8: Kapusta włoska | G8: Kapusta pekińska | H8: Fasola szparagowa | I8: Kiszona kapusta | J8: Ogórki kiszone | K8: Sałata masłowa | L8: Kalafiory/a | M8: Brokuły/a | N8: Kalarepa/a | O8: Cukinia
B9: kujawsko-pomorskie | C9: 0,47-0,55 | D9: 0,61-0,68 | E9: 1,20-1,30 | F9: 2,15-2,35 | G9: 1,89-2,35 | H9: 6,55-7,00 | J9: 6,98-7,66 | K9: 1,40-1,55 | L9: 2,55-3,10 | N9: 1,25-1,45 | O9: 1,10-1,25
B10: lubelskie | C10: 0,45-0,51 | D10: 0,62-0,67 | E10: 1,15-1,25 | F10: 2,27-2,45 | I10: 6,35-7,35 | L10: 2,79-2,99 | M10: 2,45-2,60
B11: lubelskie | C11: 0,52-0,60 | D11: 0,58-0,68 | G11: 2,10-2,45 | H11: 7,25-7,68 | J11: 6,89-7,55
B12: łódzkie | C12: 0,44-0,53 | D12: 0,46-0,53 | F12: 2,35-2,50 | I12: 6,80-7,35 | L12: 2,87-3,20 | M12: 2,25-2,35 | N12: 1,35-1,58 | O12: 1,33-1,56
B13: łódzkie | C13: 0,42-0,46 | D13: 0,51-0,65 | G13: 1,85-2,52 | H13: 6,60-6,98 | I13: 6,45-6,85 | J13: 7,68-7,95 | K13: 1,45-1,52 | L13: 2,56-2,84
B14: małopol. | C14: 0,48-0,54 | D14: 0,54-0,66 | E14: 1,25-1,35 | F14: 2,15-2,45 | I14: 6,25-6,78 | J14: 6,98-7,36 | L14: 2,75-2,85 | N14: 1,26-1,65 | O14: 1,27-1,45
B15: małopol. | C15: 0,41-0,46 | D15: 0,55-0,63 | I15: 6,35-6,45 | J15: 6,80-7,44 | K15: 1,46-1,55 | M15: 2,30-2,45
B16: małopol. | C16: 0,46-0,49 | D16: 0,53-0,57 | H16: 6,50-7,00 | I16: 6,44-7,95
B17: małopol. | C17: 0,45-0,51 | D17: 0,55-0,69 | E17: 1,10-1,13 | F17: 2,40-2,60 | G17: 1,95-2,36 | J17: 6,87-7,54 | K17: 1,43-1,56 | L17: 2,66-2,94 | N17: 1,10-1,55 | O17: 1,30-1,58
B18: mazowiec. | C18: 0,43-0,53 | D18: 0,52-0,58 | F18: 2,00-2,25 | G18: 1,80-2,33 | H18: 5,89-6,80 | I18: 6,78-7,35 | L18: 3,15-3,45 | M18: 2,27-2,46
B19: podkarp. | C19: 0,44-0,47 | D19: 0,51-0,57 | E19: 1,15-1,25 | I19: 6,55-7,45 | J19: 6,66-7,54
B20: podkarp. | C20: 0,44-0,48 | D20: 0,46-0,52 | H20: 6,38-6,90 | J20: 6,56-7,13 | L20: 2,86-3,66
B21: Cena średnia | C21: 0,41-0,60 | D21: 0,46-0,69 | E21: 1,10-1,35 | F21: 2,00-2,60 | G21: 1,80-2,52 | H21: 5,89-7,68 | I21: 6,25-7,95 | J21: 6,56-7,95 | K21: 1,40-1,56 | L21: 2,55-3,66 | M21: 2,25-2,60 | N21: 1,10-1,65 | O21: 1,10-1,58
B22: tydzień temu | C22: 0,40-0,56 | D22: 0,46-0,69 | E22: 1,10-1,28 | F22: 1,98-2,55 | G22: 1,75-2,45 | H22: 6,33-9,55 | I22: 5,45-7,89 | J22: 6,56-7,95 | K22: 1,40-1,56 | L22: 2,45-3,74 | M22: 2,38-2,78 | N22: 1,00-1,52 | O22: 0,99-1,55
B23: rok temu | C23: 0,69-0,77 | D23: 0,64-0,89 | E23: 1,16-1,42 | F23: 2,45-2,89 | G23: 1,95-2,68 | H23: 6,45-7,89 | I23: 6,35-8,33 | J23: 6,89-8,55 | K23: 1,56-1,80 | L23: 2,78-3,87 | M23: 2,45-2,90 | N23: 1,25-1,78 | O23: 1,15-1,78
B25: Województwo | C25: Marchew (myta) | D25: Pieczarki | E25: Pietruszka | F25: Pory | G25: Czosnek/a | H25: Rzodkiewka/b | I25: Selery | J25: Pomidory | K25: Ogórki | L25: Sałata masłowa
B26: kujawsko-pomorskie | C26: 1,78-1,96 | D26: 6,34-7,90 | E26: 1,85-2,34 | F26: 2,55-2,87 | G26: 1,20-1,50 | H26: 1,89-2,15 | I26: 0,72-0,89 | J26: 1,45-1,68 | K26: 1,65-1,97 | L26: 0,88-0,96
B27: lubelskie | C27: 1,97-2,26 | D27: 6,35-7,68 | E27: 1,97-2,65 | F27: 2,77-2,99 | G27: 1,12-1,40 | I27: 0,71-0,86 | J27: 1,59-1,87 | K27: 1,87-1,90 | L27: 0,75-0,93
B28: małopol. | C28: 1,95-2,45 | D28: 6,66-7,85 | E28: 2,35-2,88 | F28: 2,45-2,88 | H28: 1,88-2,56 | I28: 0,65-0,72 | K28: 1,64-2,10
B29: małopol. | C29: 1,87-1,94 | D29: 6,34-6,87 | E29: 2,45-2,56 | F29: 2,56-2,97 | G29: 1,37-1,55 | I29: 0,68-0,73 | J29: 1,96-2,35 | K29: 1,97-2,35 | L29: 0,80-0,93
B30: mazowiec. | C30: 1,95-2,35 | D30: 6,99-7,65 | E30: 2,38-2,79 | F30: 2,54-2,88 | G30: 1,14-1,38 | H30: 2,20-2,66 | I30: 0,79-0,88 | J30: 2,17-2,45 | K30: 2,45-2,74
B31: mazowiec. | C31: 2,15-2,68 | D31: 6,66-7,55 | E31: 2,45-2,97 | F31: 2,66-2,85 | G31: 1,25-1,54 | H31: 2,15-2,45 | I31: 0,86-0,94 | L31: 0,75-0,92
B32: podkarp. | C32: 2,10-2,38 | D32: 6,44-7,69 | E32: 2,55-2,76 | F32: 2,44-2,78 | J32: 2,38-2,60 | K32: 2,45-2,87
B33: podkarp. | C33: 1,96-2,67 | D33: 6,31-7,96 | E33: 2,17-2,99 | F33: 2,35-2,88 | G33: 1,24-1,57 | H33: 2,27-2,65 | I33: 0,68-0,97
B34: Cena średnia | C34: 1,78-2,68 | D34: 6,31-7,96 | E34: 1,85-2,99 | F34: 2,35-2,99 | G34: 1,12-1,57 | H34: 1,88-2,66 | I34: 0,65-0,97 | J34: 1,45-2,60 | K34: 1,64-2,87 | L34: 0,75-0,96
B35: tydzień temu | C35: 1,55-2,56 | D35: 4,25-7,66 | E35: 1,77-2,89 | F35: 2,18-2,98 | G35: 1,07-1,45 | H35: 1,75-2,55 | I35: 0,65-0,98 | J35: 1,45-2,55 | K35: 1,69-2,68 | L35: 0,66-1,35
B36: rok temu | C36: 1,95-2,97 | D36: 6,54-8,99 | E36: 2,78-3,15 | F36: 2,87-3,35 | G36: 1,35-1,65 | H36: 1,70-2,69 | I36: 0,78-1,12 | J36: 1,87-2,78 | K36: 1,85-2,98 | L36: 0,96-1,35
B37: a/sztuka,b/peczek

Sheet IERGZ_owoce
B2: Ogrodniczy Informator Cenowy
B3: Instytut Ekonomiki Rolnictwa i Gospodarki Żywnościowej Państwowy Instytut Badawczy
B5: Ceny skupu netto owoców w spółdzielniach ogrodniczych zbierane 17 VIII 2026 r.
B6: Województwo | C6: Jabłka deserowe | D6: Jabłka przemysłowe | E6: Gruszki | F6: Czereśnie | G6: Wiśnie | H6: Maliny | I6: Borówki wysokie
B7: kujawsko-pomorskie | C7: 1,25-1,54
B8: lubelskie | C8: 1,25-1,55 | D8: 0,55-0,60 | E8: 3,56-3,89 | F8: 8,98-9,88 | I8: 6,78-7,66
B9: łódzkie | C9: 1,15-1,35 | E9: 3,77-4,15 | G9: 6,89-7,99 | H9: 21,45-25,66 | I9: 5,45-6,78
B10: łódzkie | C10: 1,25-1,63 | D10: 0,55-0,68 | E10: 3,87-4,98 | F10: 7,65-8,66
B11: łódzkie | H11: 23,66-24,66 | I11: 6,35-7,69
B12: małopolskie | C12: 1,47-1,66 | E12: 3,65-4,74 | F12: 7,45-8,66
B13: małopolskie | C13: 1,45-1,65 | G13: 7,68-8,99 | H13: 20,75-24,55 | I13: 8,66-9,60
B14: małopolskie | C14: 1,20-1,75 | D14: 0,63-0,68 | E14: 3,65-4,69 | F14: 9,15-10,78 | G14: 6,58-7,84
B15: małopolskie
B16: małopolskie | D16: 0,55-0,68 | F16: 8,97-9,65 | I16: 9,33-11,30
B17: mazowiec. | C17: 1,35-1,54 | E17: 3,78-4,90 | G17: 6,35-8,66 | H17: 20,45-26,89
B18: podkarp. | C18: 1,35-1,45 | D18: 0,55-0,70
B19: podkarp. | E19: 3,65-4,76
B20: Cena średnia | C20: 1,15-1,75 | D20: 0,55-0,70 | E20: 3,56-4,98 | F20: 7,45-10,78 | G20: 6,35-8,99 | H20: 20,45-26,89 | I20: 5,45-11,30
B21: tydzień temu | C21: 1,10-1,78 | D21: 0,50-0,78 | E21: 3,50-4,99 | F21: 7,35-10,25 | G21: 5,60-7,84 | H21: 19,25-27,88 | I21: 6,75-9,66
B22: rok temu | C22: 1,25-2,15 | D22: 0,60-0,79 | E22: 3,88-5,10 | F22: 7,98-12,56 | G22: 7,66-9,25 | H22: 16,88-23,55 | I22: 12,56-14,56
B23: s/"suchy" przemysł, */jabłka w kal. 65+ i do średniej nie wliczana jest odmiana Antonówka

Sheet Zaklady 
B2: Ogrodniczy Informator Cenowy
B3: Instytut Ekonomiki Rolnictwa i Gospodarki Żywnościowej Państwowy Instytut Badawczy
B4: Zakład Ekonomiki Gospodarstw Rolnych i Ogrodniczych
B7: Ceny skupu netto w zakładach przetwórczych i chłodniach zbierane 17 VIII 2026 r. (zł/kg)
K8: Jabłka | O8: Fasola szparagowa | P8: Cebula | Q8: Truskawki | R8: Rabarbar | S8: Jabłka | Z8: Malina | AA8: Jabłka | AB8: Jeżyny | AC8: Cuukinia
K9: przemysłowe | P9: obrana | Q9: z szyp[ułką | S9: przemyslowe | Z9: do mrożenia | AA9: przemyslowe | AC9: na kostkę
B10: kujawsko-pomor.
B11: kujawsko-pomor. | P11: 1,15-1,20lz | AC11: 0,60-0,68lz
B12: kujawsko-pomor. | P12: 1,20lz-1,25lz | R12: 2,50lz-2,50lz
B13: kujawsko-pomor. | P13: 1,25lz-1,35lz | R13: 2,50lz-3,00lz
B14: lubelskie | K14: 0,32-0,36lz | O14: 1,15lz-1,25lz | S14: 0,60lz-0,60lz | AA14: 0,60lz-0,60lz
B15: lubelskie | R15: 3,50lz | AC15: 0,65lz
B16: lubelskie | Q16: 3,45lz-3,89lz | S16: 0,50-0,60lz-0,90lz-1,20lz | Z16: 16,50lz/II-17,00lz/I | AA16: 0,55lz-0,65lz | AB16: 6,50lz-7,00lz
B17: lubelskie | O17: 1,15lz-1,25lz | S17: 0,65lz-0,75lz
B18: lubelskie | Z18: 16,00lz/II-16,50lz-17,00lz/I | AC18: 0,60-0,65lz
B19: lubuskie | Q19: 3,56lz-4,00lz | R19: 2,50lz-3,50lz
B20: łódzkie | O20: 1,30lz/k | S20: 0,50lz-0,60lz | AA20: 0,50lz-0,70lz
B21: łódzkie | Q21: 3,45lz-3,75lz
B22: małopolskie | K22: 0,31-0,35lz | AB22: 6,00lz-7,00lz
B23: mazowieckie | S23: 0,65lz-0,90lz-1,15lz-1,20lz
B24: mazowieckie | K24: 0,32-0,35lz | Q24: 3,58lz-3,80lz | AB24: 5,50-6,00lz-7,00lz
B25: podkarpackie
B26: podkarpackie
B27: podlaskie | K27: 0,36lz
B28: podlaskie
B29: śląskie
B30: świętokrzyskie | Q30: 3,68lz-3,85lz
B31: wielkopolskie | P31: 1,35lz
B32: wielkopolskie
B33: zachodnio-pomor.
B35: średnio | K35: 0,32-0,36lz | O35: 1,10lz-1,25lz-1,30lz/k | P35: 1,15-1,20lz-1,35lz | Q35: 3,45lz-4,00lz | R35: 2,50lz-3,50lz | S35: 0,50lz-0,65lz/na sok-0,90lz-1,20lz/do obierania | Z35: 16,00lz-16,50lz/II--17,00lz/I | AA35: 0,50lz-0,70lz | AB35: 5,50lz-6,00lz-7,00lz | AC35: 0,60-0,65lz-0,68lz
B37: tydzień temu | K37: 0,32-0,36lz | O37: 1,10lz-1,25lz | P37: 1,15-1,20-1,30lz | Q37: 3,50-3,50lz-4,50lz | R37: 2,50lz-3,50lz | S37: 0,50lz-0,65lz/na sok-0,90lz-1,20lz/do obierania | Z37: 17,00lz-17,50lz/II--17,50lz-18,00lz/I | AA37: 0,50lz-0,65lz | AB37: 5,50lz-6,00lz-7,50lz | AC37: 0,60-0,68lz-0,70lz
B39: rok temu | K39: 0,27-0,33lz | O39: 1,00-1,10/k | P39: 1,40-1,50lz | Q39: 5,75-6,00lz-6,50lz | R39: 5,00-6,50lz | S39: 1,00lz-1,25lz 1,30;-1,40lz-1,60lz/do obierania | Z39: 8,00lz/II-9,25lz/I-10,25lz/extra | AA39: 1,00lz-1,25lz 1,30;-1,40lz-1,60lz/do obierania | AB39: 5,00-5,50lz-6,00lz | AC39: 0,65-0,70
B72: lz/ cena loco zakład, k/kontraktacja,kl.I/klasa I, kl.II/klasa II,extra/klasa ekstra,m/"mokry" przemysł,s/ "suchy" przemysł,W/Węgierka

Sheet ow_KRIR
C1: Tygodniowy Serwis Cenowy
B2: 31 tydzień | C2: dla producentów owoców i warzyw
B3: 27.07-02.08.2026 r | C3: Krajowa Rada Izb Rolniczych
C4: Parzniew ul. Przyszłości 5, 05-804 Pruszków
C5: tel. 881-939-421, www.krir.pl, sekretariat@krir.pl
B6: Serwis znajduje się obecnie w fazie rozwoju i dotyczy wybranych produktów w niektórych województwach.
B7: BEZ AKTUALIZACJI
B8: Województwo/Towar | C8: Mazowieckie | F8: Świętokrzyskie | I8: Wielkopolskie
C9: 27.07 - 02.08.2026r. cena w zł/kg (szt*) | D9: 20.07 - 26.07.2026r. cena w zł/kg (szt*) | E9: tygodniowa zmiana ceny w % | F9: 27.07 - 02.08.2026r. cena w zł/kg (szt*) | G9: 20.07 - 26.07.2026r. cena w zł/kg (szt*) | H9: tygodniowa zmiana ceny w % | I9: 27.07 - 02.08.2026r. cena w zł/kg (szt*) | J9: 20.07 - 26.07.2026r. cena w zł/kg (szt*) | K9: tygodniowa zmiana ceny w %
B10: Jabłka (op.5-20 kg) Golden delicious (70/80mm) | C10: 2.29 | D10: 2 | E10: =((C10-D10)/D10)*100 -> 14.5 | H10: -- | I10: -- | J10: -- | K10: --
B11: Jabłka (op.5-20 kg) Jonagold+Jonagored (70/80mm) | C11: -- | D11: -- | E11: -- | H11: -- | I11: -- | J11: -- | K11: --
B12: Jabłka (op.5-20 kg) Idared (70/80mm) | C12: 2 | D12: 2 | E12: =((C12-D12)/D12)*100 -> 0 | H12: -- | I12: -- | J12: -- | K12: --
B13: Jabłka (op.5-20 kg) Shampion (70/80mm) | C13: 2.19 | D13: 2 | E13: =((C13-D13)/D13)*100 -> 9.5 | F13: 1.7 | H13: -- | I13: -- | J13: -- | K13: --
B14: Jabłka (op.5-20 kg) Boskoop (70/80mm) | C14: -- | D14: -- | E14: -- | F14: 2 | H14: -- | I14: -- | J14: -- | K14: --
B15: Jabłka (op.5-20 kg) Gala (65/70mm) | C15: -- | D15: -- | E15: -- | H15: -- | I15: -- | J15: -- | K15: --
B16: Gruszki (op.5-20 kg) Lukasówka (65/70 mm) | C16: 4.5 | D16: 4.5 | E16: =((C16-D16)/D16)*100 -> 0 | F16: 2.5 | H16: -- | I16: -- | J16: -- | K16: --
B17: Cebula żółta 40-80 mm; op.5-25 kg | C17: -- | D17: -- | E17: -- | H17: -- | I17: -- | J17: -- | K17: --
B18: Cebula biała 40-80 mm op.5-25 kg | C18: 1.42 | D18: 1.3 | E18: =((C18-D18)/D18)*100 -> 9.2307692 | H18: -- | I18: -- | J18: 1.7 | K18: --
B19: Marchew wszystkie odmiany pakowane luzem | C19: 1.84 | D19: 2.02 | E19: =((C19-D19)/D19)*100 -> -8.9108911 | H19: -- | I19: -- | J19: 1.5 | K19: --
B20: Pietruszka korzeń op. 10 kg | C20: -- | D20: -- | E20: -- | H20: -- | I20: 4 | J20: 4 | K20: --
B21: Pomidory, typ okrągły; op. 5-6-kg | C21: 4.5 | D21: 4.1 | E21: =((C21-D21)/D21)*100 -> 9.7560976 | G21: 5.3 | H21: -- | I21: 4.0182364 | J21: 3.9248353 | K21: =((I21-J21)/J21)*100 -> 2.3797461
B22: Ogórki, typ gładkie; op. 5-6 kg | C22: 2.5 | D22: 7.4 | E22: =((C22-D22)/D22)*100 -> -66.216216 | F22: 2.5 | G22: 5 | H22: =((F22-G22)/G22)*100 -> -50 | I22: -- | J22: 5.0699432 | K22: --
B23: Seler | C23: -- | D23: -- | E23: -- | H23: -- | I23: -- | J23: 4.0001531 | K23: --
B24: Sałata masłowa za główkę | C24: -- | D24: -- | E24: -- | H24: -- | K24: --
B25: Szparagi biało/fioletowe >16mm | C25: -- | D25: -- | E25: -- | H25: -- | K25: --
B26: Burak ćwikłowy op. 10-15 kg | C26: -- | D26: -- | E26: -- | H26: -- | I26: -- | J26: 1.3 | K26: --
B27: Kalafiory 12-20 cm | C27: -- | D27: -- | E27: -- | F27: 4 | G27: 3.5 | H27: =((F27-G27)/G27)*100 -> 14.285714 | I27: 4 | J27: 4 | K27: =((I27-J27)/J27)*100 -> 0
B28: Kapusta biała zł/kg | C28: -- | D28: -- | E28: -- | H28: -- | I28: -- | J28: 1 | K28: --
B29: Rzodkiewka za pęczek 1 szt | C29: -- | D29: -- | E29: -- | H29: -- | K29: --
B30: Ziemniaki (op. 15 kg) | C30: 1.68 | D30: 1.7 | E30: =((C30-D30)/D30)*100 -> -1.1764706 | F30: 0.7 | H30: -- | K30: --
B31: Pieczarki 30-65 mm | C31: -- | D31: -- | E31: -- | F31: 11.35 | H31: -- | I31: 9.59 | J31: 9.6109301 | K31: =((I31-J31)/J31)*100 -> -0.21777358

Sheet HANDEL ZAGRANICZNY_I_XII_2025
D6: EKSPORT/WYWÓZ | H6: IMPORT/PRZYWÓZ | L6: SALDO
B7: CN | C7: Nazwa towaru | D7: Wartość [tys. EUR] | F7: Wolumen [tony] | H7: Wartość [tys. EUR] | J7: Wolumen [tony] | L7: Wartość [tys. EUR]
D8: I-XII 2024r. | E8: I-XII 2025r.* | F8: I-XII 2024r. | G8: I-XII 2025r.* | H8: I-XII 2024r. | I8: I-XII 2025r.* | J8: I-XII 2024r. | K8: I-XII 2025r.* | L8: I-XII 2024r. | M8: I-XII 2025r.*
B9: 0701 | C9: Ziemniaki, świeże lub chłodzone | D9: 46460.788 | E9: 47534.142 | F9: 119743.26 | G9: 160663.39 | H9: 63341.138 | I9: 68038.956 | J9: 157064.05 | K9: 179710.18 | L9: -16880.35 | M9: -20504.814
B10: 0702 | C10: Pomidory świeże lub chłodzone | D10: 118770.49 | E10: 127718.81 | F10: 78265.073 | G10: 80423.129 | H10: 420922.98 | I10: 440881.68 | J10: 246260.81 | K10: 237223.77 | L10: -302152.49 | M10: -313162.87
B11: 0703 | C11: Cebula, szalotka, czosnek, pory oraz inne warzywa | D11: 129088.63 | E11: 114533.35 | F11: 170182.02 | G11: 161761.06 | H11: 102974.43 | I11: 90718.876 | J11: 228146.95 | K11: 178305.02 | L11: 26114.198 | M11: 23814.477
B12: 0704 | C12: Kapusta, kalafiory, kalarepa, kapusta włoska, | D12: 78418.27 | E12: 72408.866 | F12: 103773.7 | G12: 93572.299 | H12: 91457.973 | I12: 96192.435 | J12: 85863.155 | K12: 87124.957 | L12: -13039.703 | M12: -23783.569
B13: 0705 | C13: Sałata (Lactuca sativa) i cykoria (Cichorium spp.), | D13: 32269.805 | E13: 32275.545 | F13: 26063.481 | G13: 24667.471 | H13: 97087.925 | I13: 103169.86 | J13: 73073.851 | K13: 79840.871 | L13: -64818.12 | M13: -70894.314
B14: 0706 | C14: Marchew, rzepa, buraki sałatkowe, salsefia, selery, | D14: 42404.232 | E14: 40859.998 | F14: 64597.357 | G14: 83701.753 | H14: 78545.05 | I14: 77346.817 | J14: 96386.332 | K14: 108823.43 | L14: -36140.818 | M14: -36486.819
B15: 0707 | C15: Ogórki i korniszony świeże | D15: 25426.211 | E15: 28415.476 | F15: 19346.303 | G15: 20608.521 | H15: 121899.39 | I15: 141998.66 | J15: 106985.88 | K15: 109228.17 | L15: -96473.177 | M15: -113583.19
B16: 0708 | C16: Warzywa strączkowe, nawet łuskane, świeże | D16: 15052.011 | E16: 13872.72 | F16: 27324.965 | G16: 32373.875 | H16: 4006.423 | I16: 4059.883 | J16: 4157.331 | K16: 3804.698 | L16: 11045.588 | M16: 9812.837
B17: 0709 | C17: Inne warzywa świeże lub chłodzone | D17: 681523.48 | E17: 670939.82 | F17: 323321.09 | G17: 310841.7 | H17: 345498.76 | I17: 384711.16 | J17: 168142.9 | K17: 182179.82 | L17: 336024.72 | M17: 286228.66
B18: 0710 | C18: Warzywa niegotowane lub gotowane na parze, zamrożone | D18: 432572.37 | E18: 415272.98 | F18: 407308.91 | G18: 396677.51 | H18: 78589.331 | I18: 92194.668 | J18: 68252.737 | K18: 78001.767 | L18: 353983.04 | M18: 323078.31
B19: 0711 | C19: Warzywa zakonserwowane tymczasowo | D19: 16368.888 | E19: 16323.561 | F19: 8776.655 | G19: 8581.733 | H19: 36676.991 | I19: 42908.572 | J19: 18377.683 | K19: 23606.869 | L19: -20308.103 | M19: -26585.011
B20: 0712 | C20: Warzywa suszone, całe, cięte w kawałki | D20: 110353.24 | E20: 110838.96 | F20: 45331.324 | G20: 33558.361 | H20: 71873.124 | I20: 66246.777 | J20: 22262.13 | K20: 21623.151 | L20: 38480.121 | M20: 44592.179
... B32: 0810 | C32: Pozostałe owoce, świeże | D32: 292567.88 | E32: 281130.08 | F32: 70540.003 | G32: 65970.394 | H32: 423150.1 | I32: 516564.96 | J32: 109894.76 | K32: 124926.08 | L32: -130582.22 | M32: -235434.88

Sheet HANDEL ZAGRANICZNY_I _V_2026
D5: EKSPORT/WYWÓZ | H5: IMPORT/PRZYWÓZ | L5: SALDO
B6: CN | C6: Nazwa towaru | D6: Wartość [tys. EUR] | F6: Wolumen [tony] | H6: Wartość [tys. EUR] | J6: Wolumen [tony] | L6: Wartość [tys. EUR]
D7: I-V 2025r.* | E7: I-V 2026r.* | F7: I-V 2025r.* | G7: I-V 2026r.* | H7: I-V 2025r.* | I7: I-V 2026r.* | J7: I-V 2025r.* | K7: I-V 2026r.* | L7: I-V 2025r.* | M7: I-V 2026r.*
B8: 0701 | C8: Ziemniaki, świeże lub chłodzone | D8: 29466.344 | E8: 10021.329 | F8: 87310.648 | G8: 41806.624 | H8: 52155.928 | I8: 25657.319 | J8: 125244.39 | K8: 62393.499 | L8: -22689.584 | M8: -15635.99
B9: 0702 | C9: Pomidory świeże lub chłodzone | D9: 54172.437 | E9: 54434.862 | F9: 25256.618 | G9: 25876.714 | H9: 248174.37 | I9: 286410.96 | J9: 127578.55 | K9: 119409.11 | L9: -194001.93 | M9: -231976.1
B10: 0703 | C10: Cebula, szalotka, czosnek, pory oraz inne warzywa | D10: 50280.282 | E10: 46711.958 | F10: 70977.051 | G10: 75666.96 | H10: 50831.952 | I10: 34821.055 | J10: 96648.628 | K10: 74014.677 | L10: -551.67 | M10: 11890.903
B11: 0704 | C11: Kapusta, kalafiory, kalarepa, kapusta włoska, | D11: 33380.098 | E11: 21127.97 | F11: 42994.561 | G11: 29323.576 | H11: 75518.599 | I11: 73257.069 | J11: 68832.151 | K11: 62068.067 | L11: -42138.501 | M11: -52129.099
B12: 0705 | C12: Sałata (Lactuca sativa) i cykoria (Cichorium spp.), | D12: 13908.677 | E12: 12227.786 | F12: 8838.279 | G12: 7876.627 | H12: 68645.638 | I12: 60731.346 | J12: 53788.028 | K12: 44396.278 | L12: -54736.961 | M12: -48503.56
B13: 0706 | C13: Marchew, rzepa, buraki sałatkowe, salsefia, selery, | D13: 22850.568 | E13: 16217.269 | F13: 49658.085 | G13: 35406.46 | H13: 52633.419 | I13: 41688.325 | J13: 77106.396 | K13: 42914.338 | L13: -29782.851 | M13: -25471.056
B14: 0707 | C14: Ogórki i korniszony świeże | D14: 11616.221 | E14: 11421.747 | F14: 7252.822 | G14: 7041.688 | H14: 66825.16 | I14: 76101.921 | J14: 42173.86 | K14: 41664.05 | L14: -55208.939 | M14: -64680.174
B15: 0708 | C15: Warzywa strączkowe, nawet łuskane, świeże | D15: 5071.517 | E15: 3963.699 | F15: 9769.131 | G15: 7596.174 | H15: 2507.939 | I15: 3828.318 | J15: 1726.969 | K15: 2751.749 | L15: 2563.578 | M15: 135.381
B16: 0709 | C16: Inne warzywa świeże lub chłodzone | D16: 271963.47 | E16: 264597.08 | F16: 122570.93 | G16: 115484.46 | H16: 237680.3 | I16: 246464.8 | J16: 110127.7 | K16: 100536.74 | L16: 34283.179 | M16: 18132.274
B17: 0710 | C17: Warzywa niegotowane lub gotowane na parze, zamrożone | D17: 175573.64 | E17: 170227.42 | F17: 164911.17 | G17: 172530.9 | H17: 42305.149 | I17: 43031.463 | J17: 36803.703 | K17: 36465.187 | L17: 133268.49 | M17: 127195.96
B18: 0711 | C18: Warzywa zakonserwowane tymczasowo | D18: 6931.896 | E18: 7128.884 | F18: 3570.839 | G18: 3797.982 | H18: 17518.291 | I18: 19763.294 | J18: 9277.459 | K18: 11709.96 | L18: -10586.395 | M18: -12634.41
B19: 0712 | C19: Warzywa suszone, całe, cięte w kawałki | D19: 51641.147 | E19: 45242.191 | F19: 15187.341 | G19: 11961.38 | H19: 29855.102 | I19: 29608.797 | J19: 9316.748 | K19: 9850.814 | L19: 21786.045 | M19: 15633.394
... B31: 0810 | C31: Pozostałe owoce, świeże | D31: 45365.05 | E31: 43965.759 | F31: 18339.172 | G31: 18428.91 | H31: 287691.73 | I31: 336765.61 | J31: 70564.741 | K31: 84406.978 | L31: -242326.68 | M31: -292799.85

Sheet EXP KRAJE I-V 2026
B2: HANDEL ZAGRANICZNY - DANE WSTĘPNE
B4: Źródło danych: Ministerstwo Finansów | Q4: =POMOC!B5 -> Notowania 17 - 23.08.2026 / Tydzień 33
B5: UWAGA! DANE W TRAKCIE WERYFIKACJI - MOGĄ BYĆ OBARCZONE ISTOTNYMI BŁĘDAMI
B6: Eksport jabłek (CN 080810) wg. ważniejszych krajów | K6: Eksport pomidorów (CN 070200) wg. ważniejszych krajów
B7: według ważniejszych krajów | K7: według ważniejszych krajów
B8: I-V 2025r.* | F8: I-V 2026r.* | K8: I-V 2025r.* | O8: I-V 2026r.*
B9: Kraj | C9: Wartość [tys. EUR] | D9: Wolumen [tony] | F9: Kraj | G9: Wartość [tys. EUR] | H9: Wolumen [tony] | K9: Kraj | L9: Wartość [tys. EUR] | M9: Wolumen [tony] | O9: Kraj | P9: Wartość [tys. EUR] | Q9: Wolumen [tony]
B10: OGÓŁEM | C10: 244814.33 | D10: 359199.88 | F10: OGÓŁEM | G10: 246472.02 | H10: 400356.33 | K10: OGÓŁEM | L10: 54172.437 | M10: 25256.618 | O10: OGÓŁEM | P10: 54434.862 | Q10: 25876.714
B11: Niemcy | C11: 22710.475 | D11: 35731.932 | F11: Egipt | G11: 24534.341 | H11: 36870.121 | K11: Niemcy | L11: 22455.432 | M11: 8579.858 | O11: Holandia | P11: 23026.353 | Q11: 7477.029
B12: Rumunia | C12: 21198.708 | D12: 29473.751 | F12: Rumunia | G12: 20259.227 | H12: 33694.686 | K12: Holandia | L12: 16175.863 | M12: 6677.998 | O12: Ukraina | P12: 16990.289 | Q12: 11645.287
B13: Republika Czeska | C13: 17082.681 | D13: 23115.742 | F13: Kazachstan | G13: 18900.554 | H13: 41931.272 | K13: Ukraina | L13: 5901.582 | M13: 4531.773 | O13: Niemcy | P13: 6296.322 | Q13: 2851.083
B14: Egipt | C14: 16762.43 | D14: 22478.775 | F14: Białoruś | G14: 17311.911 | H14: 32159.682 | K14: Wielka Brytania | L14: 2300.452 | M14: 920.195 | O14: Wielka Brytania | P14: 1965.7 | Q14: 760.14
B15: Kazachstan | C15: 14577.316 | D15: 29840.358 | F15: India | G15: 15046.658 | H15: 20511.928 | K15: Szwecja | L15: 1647.107 | M15: 780.869 | O15: Bułgaria | P15: 1552.041 | Q15: 814.673
B16: Holandia | C16: 13697.71 | D16: 26257.68 | F16: Węgry | G16: 11888.821 | H16: 18782.37 | K16: Republika Czeska | L16: 1433.075 | M16: 633.132 | O16: Szwecja | P16: 1121.56 | Q16: 505.639
B17: Białoruś | C17: 12224.97 | D17: 20680.627 | F17: Litwa | G17: 10986.784 | H17: 18366.369 | K17: Białoruś | L17: 915.885 | M17: 641.433 | O17: Białoruś | P17: 983.291 | Q17: 648.023
B18: Węgry | C18: 10360.475 | D18: 15105.159 | F18: Republika Czeska | G18: 9394.785 | H18: 14922.528 | K18: Bułgaria | L18: 706.462 | M18: 549.864 | O18: Republika Czeska | P18: 797.47 | Q18: 406.893
B19: Szwecja | C19: 10026.055 | D19: 12470.226 | F19: Szwecja | G19: 8658.207 | H19: 12002.964 | K19: Litwa | L19: 441.945 | M19: 292.3 | O19: Łotwa | P19: 422.919 | Q19: 166.565
B20: India | C20: 8389.594 | D20: 10963.288 | F20: Niemcy | G20: 8424.746 | H20: 14314.494 | K20: Węgry | L20: 422.235 | M20: 238.173 | O20: Litwa | P20: 386.957 | Q20: 183.061
B21: Wielka Brytania | C21: 7887.829 | D21: 9654.103 | F21: Hiszpania | G21: 7223.279 | H21: 9940.49 | K21: Łotwa | L21: 394.682 | M21: 214 | O21: Słowacja | P21: 182.154 | Q21: 76.211
... B26: Łotwa | C26: 4968.695 | D26: 7223.491 | F26: Wielka Brytania | G26: 5232.062 | H26: 6291.852 | K26: Słowacja | L26: 120.969 | M26: 70.298 | O26: Węgry | P26: 66.605 | Q26: 26.455
B30: Eksport grzybów agaricus (CN 70095100) wg. ważniejszych krajów | K30: Eksport cebuli i szalotki (CN 070310) wg. ważniejszych krajów
B31: według ważniejszych krajów | K31: według ważniejszych krajów
B32: I-IV 2025r.* | F32: I-IV 2026r.* | K32: I-IV 2025r.* | O32: I-IV 2026r.*
B33: Kraj | C33: Wartość [tys. EUR] | D33: Wolumen [tony] | F33: Kraj | G33: Wartość [tys. EUR] | H33: Wolumen [tony] | K33: Kraj | L33: Wartość [tys. EUR] | M33: Wolumen [tony] | O33: Kraj | P33: Wartość [tys. EUR] | Q33: Wolumen [tony]
B34: OGÓŁEM | C34: 196843.82 | D34: 85744.637 | F34: OGÓŁEM | G34: 190546.14 | H34: 81680.519 | K34: OGÓŁEM | L34: 39674.431 | M34: 59395.803 | O34: OGÓŁEM | P34: 38777.673 | Q34: 64072.976
B35: Niemcy | C35: 55409.377 | D35: 22660.764 | F35: Niemcy | G35: 56375.955 | H35: 21953.82 | K35: Holandia | L35: 11007.226 | M35: 16551.743 | O35: Holandia | P35: 11233.004 | Q35: 18783.72
B36: Wielka Brytania | C36: 37422.31 | D36: 15979.846 | F36: Wielka Brytania | G36: 34072.243 | H36: 14894.218 | K36: Wielka Brytania | L36: 9075.19 | M36: 10477.814 | O36: Wielka Brytania | P36: 7221.698 | Q36: 8793.715
B37: Francja | C37: 29016.448 | D37: 11777.669 | F37: Francja | G37: 30864.553 | H37: 12027.222 | K37: Niemcy | L37: 4200.232 | M37: 6423.265 | O37: Niemcy | P37: 4467.267 | Q37: 7158.792
B38: Włochy | C38: 11825.855 | D38: 7948.714 | F38: Grecja | G38: 10043.785 | H38: 4873.164 | K38: Francja | L38: 3466.81 | M38: 5244.423 | O38: Francja | P38: 4315.418 | Q38: 5977.797
B39: Grecja | C39: 10952.092 | D39: 5031.481 | F39: Szwecja | G39: 8546.398 | H39: 3080.195 | K39: Ukraina | L39: 2475.336 | M39: 2171.948 | O39: Belgia | P39: 3713.198 | Q39: 7929.002
B40: Szwecja | C40: 7614.626 | D40: 2748.295 | F40: Włochy | G40: 8439 | H40: 5865.809 | K40: Belgia | L40: 2461.102 | M40: 5303.44 | O40: Ukraina | P40: 1623.882 | Q40: 1578.372
B41: Dania | C41: 5839.683 | D41: 1920.819 | F41: Dania | G41: 5695.022 | H41: 1852.196 | K41: Włochy | L41: 1439.875 | M41: 1763.513 | O41: Włochy | P41: 1255.505 | Q41: 1719.218
B42: Austria | C42: 5033.714 | D42: 1896.141 | F42: Bułgaria | G42: 5445.693 | H42: 3318.401 | K42: Republika Czeska | L42: 1218.371 | M42: 2718.237 | O42: Rumunia | P42: 842.52 | Q42: 2420.761
B43: Rumunia | C43: 5003.524 | D43: 2430.614 | F43: Holandia | G43: 3744.104 | H43: 1623.548 | K43: Rumunia | L43: 967.318 | M43: 2410.951 | O43: Hiszpania | P43: 769.774 | Q43: 1845.742
B44: Bułgaria | C44: 4904.753 | D44: 2595.652 | F44: Norwegia | G44: 3696.212 | H44: 1347.834 | K44: Słowacja | L44: 944.59 | M44: 1892.105 | O44: Słowacja | P44: 677.458 | Q44: 1696.502
B45: Holandia | C45: 4141.148 | D45: 1770.236 | F45: Belgia | G45: 3640.057 | H45: 1477.654 | K45: Szwecja | L45: 420.166 | M45: 272.095 | O45: Republika Czeska | P45: 582.208 | Q45: 1421.71
... B50: Węgry | C50: 1973 | D50: 1051.314 | F50: Słowacja | G50: 1825.163 | H50: 1063.528 | K50: Łotwa | L50: 179.85 | M50: 397.628 | O50: Mołdowa | P50: 149.121 | Q50: 152

Sheet IMP KRAJE I-V 2025
B2: HANDEL ZAGRANICZNY I-XI 2025 - DANE WSTĘPNE
B4: Źródło danych: Ministerstwo Finansów | Q4: =POMOC!B5 -> Notowania 17 - 23.08.2026 / Tydzień 33
B5: UWAGA! DANE W TRAKCIE WERYFIKACJI - MOGĄ BYĆ OBARCZONE ISTOTNYMI BŁĘDAMI
B6: Import bananów (CN 0803) wg. ważniejszych krajów | J6: Import pomidorów (CN 0702) wg. ważniejszych krajów
B7: według ważniejszych krajów | K7: według ważniejszych krajów
B8: I-V 2025r.* | F8: I-V 2026r.* | K8: I-V 2025r.* | O8: I-V 2026r.*
B9: Kraj | C9: Wartość [tys. EUR] | D9: Wolumen [tony] | F9: Kraj | G9: Wartość [tys. EUR] | H9: Wolumen [tony] | K9: Kraj | L9: Wartość [tys. EUR] | M9: Wolumen [tony] | O9: Kraj | P9: Wartość [tys. EUR] | Q9: Wolumen [tony]
B10: OGÓŁEM | C10: 164883.21 | D10: 219630.02 | F10: OGÓŁEM | G10: 169823.25 | H10: 234434.21 | K10: OGÓŁEM | L10: 248174.37 | M10: 127578.55 | O10: OGÓŁEM | P10: 286410.96 | Q10: 119409.11
B11: Ekwador | C11: 83760.821 | D11: 114217.32 | F11: Ekwador | G11: 83455.948 | H11: 116762.21 | K11: Holandia | L11: 88759.458 | M11: 50031.509 | O11: Holandia | P11: 94309.686 | Q11: 43562.05
B12: Kolumbia | C12: 38096.739 | D12: 44499.123 | F12: Kolumbia | G12: 39808.359 | H12: 52501.457 | K12: Hiszpania | L12: 45508.524 | M12: 23982.588 | O12: Hiszpania | P12: 83083.126 | Q12: 33904.12
B13: Gwatemala | C13: 20034.98 | D13: 28951.234 | F13: Gwatemala | G13: 25835.592 | H13: 38537.482 | K13: Niemcy | L13: 38086.946 | M13: 13804.135 | O13: Niemcy | P13: 43327.51 | Q13: 12894.128
B14: Kostaryka | C14: 16306.224 | D14: 22237.717 | F14: Kostaryka | G14: 13835.891 | H14: 18262.398 | K14: Maroko | L14: 33719.784 | M14: 16365.65 | O14: Maroko | P14: 26292.415 | Q14: 12040.58
B15: Panama | C15: 3592.329 | D15: 5514.272 | F15: Kamerun | G15: 2739.554 | H15: 3456.197 | K15: Turcja | L15: 21134.359 | M15: 15432.983 | O15: Turcja | P15: 17088.877 | Q15: 9826.157
B16: Dominikana | C16: 568.594 | D16: 1086.005 | F16: Panama | G16: 1375.489 | H16: 2164.817 | K16: Francja | L16: 6733.255 | M16: 2633.562 | O16: Włochy | P16: 10345.895 | Q16: 3024.44
B17: Hiszpania | C17: 512.02 | D17: 512.892 | F17: Hiszpania | G17: 494.489 | H17: 493.992 | K17: Włochy | L17: 5663.31 | M17: 1872.925 | O17: Belgia | P17: 5390.064 | Q17: 1273.07
B18: Włochy | C18: 404.457 | D18: 19.354 | F18: Włochy | G18: 434.398 | H18: 19.631 | K18: Belgia | L18: 2726.016 | M18: 589.585 | O18: Tunezja | P18: 2227.788 | Q18: 691.301
B19: Wybrzeże Kości Słoniowej | C19: 397.057 | D19: 605.047 | F19: Wybrzeże Kości Słoniowej | G19: 313.309 | H19: 391.196 | K19: Portugalia | L19: 1533.306 | M19: 695.755 | O19: Azerbejdżan | P19: 1165.803 | Q19: 804
B20: Francja | C20: 369.528 | D20: 979.893 | F20: Nikaragua | G20: 259.683 | H20: 366.013 | K20: Senegal | L20: 1368.462 | M20: 476.988 | O20: Macedonia | P20: 526.431 | Q20: 239.544
B21: Kamerun | C21: 266.598 | D21: 318.889 | F21: Francja | G21: 251.434 | H21: 192.188 | K21: Tunezja | L21: 1184.082 | M21: 685.056 | O21: Francja | P21: 514.9 | Q21: 191.073
... B25: Nikaragua | C25: 59.286 | D25: 172.642 | F25: Niemcy | G25: 101.201 | H25: 46.181 | K25: Węgry | L25: 125.531 | M25: 90.547 | O25: Egipt | P25: 257.366 | Q25: 88.425
B31: Import papryki czerwonej (CN 07096010) wg. ważniejszych krajów
B32: według ważniejszych krajów
B33: I-IV 2025r.* | F33: I-IV 2026r.*
B34: Kraj | C34: Wartość [tys. EUR] | D34: Wolumen [tony] | F34: Kraj | G34: Wartość [tys. EUR] | H34: Wolumen [tony]
B35: OGÓŁEM | C35: 98636.298 | D35: 40444.928 | F35: OGÓŁEM | G35: 100958.62 | H35: 37592.525
B36: Hiszpania | C36: 43451.57 | D36: 17525.422 | F36: Hiszpania | G36: 44300.478 | H36: 16201.947
B37: Niemcy | C37: 19235.48 | D37: 6165.693 | F37: Niemcy | G37: 21544.015 | H37: 6677.193
B38: Holandia | C38: 17042.7 | D38: 9076.773 | F38: Turcja | G38: 12885.179 | H38: 4688.726
B39: Turcja | C39: 10362.827 | D39: 4164.529 | F39: Holandia | G39: 9274.526 | H39: 4433.287
B40: Izrael | C40: 5810.946 | D40: 2193.865 | F40: Izrael | G40: 7089.863 | H40: 2761.914
B41: Maroko | C41: 1427.436 | D41: 656.511 | F41: Jordania | G41: 2172.823 | H41: 897.987
B42: Belgia | C42: 276.581 | D42: 134.053 | F42: Bułgaria | G42: 1291.802 | H42: 460.001
B43: Słowenia | C43: 194.882 | D43: 115.925 | F43: Maroko | G43: 1056.595 | H43: 765.643
B44: Iran | C44: 169.364 | D44: 115.59 | F44: Egipt | G44: 384.94 | H44: 185.02
B45: Szwecja | C45: 169.336 | D45: 64.511 | F45: Belgia | G45: 322.49 | H45: 129.034
B46: Grecja | C46: 120.818 | D46: 47.945 | F46: Iran | G46: 199.765 | H46: 219.09
... B51: Jordania | C51: 42.418 | D51: 20.59 | F51: Włochy | G51: 32.357 | H51: 14.353

Sheet EXP-IMP KRAJE
B2: HANDEL ZAGRANICZNY ARTYKUŁAMI Z RYNKU OWOCÓW
B3: W OKRESIE I - IV 2026 - DANE WSTĘPNE
B4: Źródło danych: Ministerstwo Finansów
B5: UWAGA! DANE W TRAKCIE WERYFIKACJI - MOGĄ BYĆ OBARCZONE ISTOTNYMI BŁĘDAMI
B7: Eksport jabłek z Polski (CN 080810)
B8: I-V 2025r.* | G8: I-V 2026r.*
B9: Kraj | C9: Wartość [tys. EUR] | D9: Wolumen [tony] | E9: Wolumen (t) | G9: Kraj | H9: Wartość [tys. EUR] | I9: Wolumen [tony] | J9: Wolumen (t)
B10: OGÓŁEM | C10: 244814.33 | D10: 359199.88 | E10: 121510.12 | G10: OGÓŁEM | H10: 246472.02 | I10: 400356.33 | J10: 120336.79
B11: Niemcy | C11: 22710.475 | D11: 35731.932 | E11: 10668.68 | G11: Egipt | H11: 24534.341 | I11: 36870.121 | J11: 11543.733
B12: Rumunia | C12: 21198.708 | D12: 29473.751 | E12: 11481.727 | G12: Rumunia | H12: 20259.227 | I12: 33694.686 | J12: 11611.22
B13: Republika Czeska | C13: 17082.681 | D13: 23115.742 | E13: 7050.959 | G13: Kazachstan | H13: 18900.554 | I13: 41931.272 | J13: 6158.882
B14: Egipt | C14: 16762.43 | D14: 22478.775 | E14: 6809.036 | G14: Białoruś | H14: 17311.911 | I14: 32159.682 | J14: 6963.219
B15: Kazachstan | C15: 14577.316 | D15: 29840.358 | E15: 6046.84 | G15: India | H15: 15046.658 | I15: 20511.928 | J15: 4852.63
